Workbook

Sheet Hipótesis
B3: Principales Hipótesis
E4: =+E7*E8 -> 62500
E5: Valor | F5: Unidad | H5: Comentarios
B6: Tecnología | E6: Eólica
B7: Potencia | E7: 50 | F7: MW | H7: --
B8: Coste de Inversión | E8: =+IF(E6="PV",650,1250) -> 1250 | F8: €/KW | H8: Calendario 10% año PEM-1, 80% año PEM, 10% año PEM +1
C9: Prima | E9: =+IF(E6="PV",20,150) -> 150 | F9: =+F8 -> €/KW
B10: Hora Anuales Equivalentes | E10: =+IF(E6="PV",1650,2350) -> 2350 | F10: Horas
C11: Coste medio ventas | E11: 1 | F11: €/MWh
B12: Costes Operativos | E12: =+IF(E6="PV",30,50) -> 50 | F12: €/KW
B13: Vida útil | E13: 30 | F13: años
B14: Valor Terminal | E14: =IF(E13=25,10%,5%) -> 0.05
B15: Puesta en Marcha | E15: 46023 | F15: -- | H15: --
B16: Ingresos | E16: Mercado
C17: Senda de mercado activa | E17: Base
B18: Tarifa/PPA | E18: =+IF(E6="PV",37,48) -> 48 | F18: €/MWh | H18: Valor 2026 Escalado (si aplica indexación)
C19: Años | E19: 12
C20: Actualización Tarifa/PPA | E20: 0 | F20: %
B21: Inflación | E21: 2 | F21: % | H21: --
B22: Tasa Impositiva | E22: 25 | F22: % | H22: --
B23: Apalancamiento inicial | E23: 70 | F23: % | H23: --
B24: Vida deuda | E24: 12 | F24: años | H24: --
B25: Tipo interés | E25: 3 | F25: % | H25: --
B26: WACC | E26: =+J35 -> 0.06375 | F26: %
B27: TIR | C27: TIR de proyecto | E27: =IFERROR(+FC!C43,"n/a") -> 0.089742009 | F27: % | I27: Cálculo del WACC
B28: Margen de creación de valor | E28: =+E27-E26 -> 0.025992009 | F28: % | I28: Kd | J28: =+IF(E16="mercado",5%,3.5%) -> 0.05
B29: VAN (k.€) | C29: VAN (k.€) | E29: =+FC!C45 -> 19471.614 | I29: Ke | J29: =+IF(E16="mercado",9%,7%) -> 0.09
B30: VAN / Capex | C30: VAN (k.€) | E30: =+E29/((E8+E9)*E7) -> 0.27816591 | I30: Impuestos | J30: 0.25
B31: LCOE | E31: =+FC!C94 -> 68.479603 | F31: €/MWh | I31: D/(D+E) | J31: 0.5
I32: E/(D+E) | J32: 0.5
I33: WCD | J33: =+(J31*J28*(1-J30)) -> 0.01875
I34: WCE | J34: =+J32*J29 -> 0.045
I35: WACC | J35: =+J33+J34 -> 0.06375

Sheet FC
E1: 45 | F1: 45.9 | G1: 46.818 | H1: 47.75436 | I1: 48.709447 | J1: 49.683636 | K1: 50.180473 | L1: 50.180473 | M1: 50.180473 | N1: 50.180473 | O1: 50.180473 | P1: 50.180473 | Q1: 50.180473 | R1: 49.176863 | S1: 48.193326 | T1: 47.229459 | U1: 46.28487 | V1: 45.359173 | W1: 44.451989 | X1: 43.562949 | Y1: 42.69169 | Z1: 42.69169 | AA1: 42.69169 | AB1: 42.69169 | AC1: 42.69169
B2: =+Hipótesis!E16 -> Mercado | E2: 1 | F2: =+E2+1 -> 2 | G2: =+F2+1 -> 3 | H2: =+G2+1 -> 4 | I2: =+H2+1 -> 5 | J2: =+I2+1 -> 6 | K2: =+J2+1 -> 7 | L2: =+K2+1 -> 8 | M2: =+L2+1 -> 9 | ... AH2: =+AG2+1 -> 30
B3: Concepto | C3: Unidades | D3: =+YEAR(Hipótesis!E15)-1 -> 2025 | E3: =+D3+1 -> 2026 | F3: =+E3+1 -> 2027 | G3: =+F3+1 -> 2028 | H3: =+G3+1 -> 2029 | I3: =+H3+1 -> 2030 | J3: =+I3+1 -> 2031 | K3: =+J3+1 -> 2032 | L3: =+K3+1 -> 2033 | ... AJ3: =+AI3+1 -> 2057
B4: % año | E4: =+IF(E3>=YEAR(Hipótesis!$E$15)+Hipótesis!$E$13,0,IF(E3>=YEAR(Hipótesis!$E$15),1,0)) -> 1 | F4: =+IF(F3>=YEAR(Hipótesis!$E$15)+Hipótesis!$E$13,0,IF(F3>=YEAR(Hipótesis!$E$15),1,0)) -> 1 | G4: =+IF(G3>=YEAR(Hipótesis!$E$15)+Hipótesis!$E$13,0,IF(G3>=YEAR(Hipótesis!$E$15),1,0)) -> 1 | H4: =+IF(H3>=YEAR(Hipótesis!$E$15)+Hipótesis!$E$13,0,IF(H3>=YEAR(Hipótesis!$E$15),1,0)) -> 1 | I4: =+IF(I3>=YEAR(Hipótesis!$E$15)+Hipótesis!$E$13,0,IF(I3>=YEAR(Hipótesis!$E$15),1,0)) -> 1 | J4: =+IF(J3>=YEAR(Hipótesis!$E$15)+Hipótesis!$E$13,0,IF(J3>=YEAR(Hipótesis!$E$15),1,0)) -> 1 | K4: =+IF(K3>=YEAR(Hipótesis!$E$15)+Hipótesis!$E$13,0,IF(K3>=YEAR(Hipótesis!$E$15),1,0)) -> 1 | L4: =+IF(L3>=YEAR(Hipótesis!$E$15)+Hipótesis!$E$13,0,IF(L3>=YEAR(Hipótesis!$E$15),1,0)) -> 1 | ... AJ4: =+IF(AJ3>=YEAR(Hipótesis!$E$15)+Hipótesis!$E$13,0,IF(AJ3>=YEAR(Hipótesis!$E$15),1,0)) -> 0
B5: Ingresos a Mercado | C5: €/MWh | E5: =+(IF(Hipótesis!$E$17="Base",VLOOKUP(FC!E$3,'Senda de precios mercado'!$A$5:$D$60,3,0),IF(Hipótesis!$E$17="Pesimista",VLOOKUP(FC!E$3,'Senda de precios mercado'!$A$5:$D$60,2,0),VLOOKUP(E$3,'Senda de precios mercado'!$A$5:$D$60,4,0))))*E$4 -> 65 | F5: =+(IF(Hipótesis!$E$17="Base",VLOOKUP(FC!F$3,'Senda de precios mercado'!$A$5:$D$60,3,0),IF(Hipótesis!$E$17="Pesimista",VLOOKUP(FC!F$3,'Senda de precios mercado'!$A$5:$D$60,2,0),VLOOKUP(F$3,'Senda de precios mercado'!$A$5:$D$60,4,0))))*F$4 -> 65 | G5: =+(IF(Hipótesis!$E$17="Base",VLOOKUP(FC!G$3,'Senda de precios mercado'!$A$5:$D$60,3,0),IF(Hipótesis!$E$17="Pesimista",VLOOKUP(FC!G$3,'Senda de precios mercado'!$A$5:$D$60,2,0),VLOOKUP(G$3,'Senda de precios mercado'!$A$5:$D$60,4,0))))*G$4 -> 65 | H5: =+(IF(Hipótesis!$E$17="Base",VLOOKUP(FC!H$3,'Senda de precios mercado'!$A$5:$D$60,3,0),IF(Hipótesis!$E$17="Pesimista",VLOOKUP(FC!H$3,'Senda de precios mercado'!$A$5:$D$60,2,0),VLOOKUP(H$3,'Senda de precios mercado'!$A$5:$D$60,4,0))))*H$4 -> 66.3 | I5: =+(IF(Hipótesis!$E$17="Base",VLOOKUP(FC!I$3,'Senda de precios mercado'!$A$5:$D$60,3,0),IF(Hipótesis!$E$17="Pesimista",VLOOKUP(FC!I$3,'Senda de precios mercado'!$A$5:$D$60,2,0),VLOOKUP(I$3,'Senda de precios mercado'!$A$5:$D$60,4,0))))*I$4 -> 67.626 | J5: =+(IF(Hipótesis!$E$17="Base",VLOOKUP(FC!J$3,'Senda de precios mercado'!$A$5:$D$60,3,0),IF(Hipótesis!$E$17="Pesimista",VLOOKUP(FC!J$3,'Senda de precios mercado'!$A$5:$D$60,2,0),VLOOKUP(J$3,'Senda de precios mercado'!$A$5:$D$60,4,0))))*J$4 -> 68.97852 | K5: =+(IF(Hipótesis!$E$17="Base",VLOOKUP(FC!K$3,'Senda de precios mercado'!$A$5:$D$60,3,0),IF(Hipótesis!$E$17="Pesimista",VLOOKUP(FC!K$3,'Senda de precios mercado'!$A$5:$D$60,2,0),VLOOKUP(K$3,'Senda de precios mercado'!$A$5:$D$60,4,0))))*K$4 -> 70.35809 | L5: =+(IF(Hipótesis!$E$17="Base",VLOOKUP(FC!L$3,'Senda de precios mercado'!$A$5:$D$60,3,0),IF(Hipótesis!$E$17="Pesimista",VLOOKUP(FC!L$3,'Senda de precios mercado'!$A$5:$D$60,2,0),VLOOKUP(L$3,'Senda de precios mercado'!$A$5:$D$60,4,0))))*L$4 -> 75.353515 | ... AJ5: =+(IF(Hipótesis!$E$17="Base",VLOOKUP(FC!AJ$3,'Senda de precios mercado'!$A$5:$D$60,3,0),IF(Hipótesis!$E$17="Pesimista",VLOOKUP(FC!AJ$3,'Senda de precios mercado'!$A$5:$D$60,2,0),VLOOKUP(AJ$3,'Senda de precios mercado'!$A$5:$D$60,4,0))))*AJ$4 -> 0
B6: Ingresos tarifa | C6: €/MWh | E6: =+IF(YEAR(Hipótesis!$E$15)+Hipótesis!$E$19<FC!E3+1,FC!E5,Hipótesis!$E$18*E4) -> 48 | F6: =+IF(YEAR(Hipótesis!$E$15)+Hipótesis!$E$19<FC!F3+1,FC!F5,E6*F4*(1+Hipótesis!$E$20/100)) -> 48 | G6: =+IF(YEAR(Hipótesis!$E$15)+Hipótesis!$E$19<FC!G3+1,FC!G5,F6*G4*(1+Hipótesis!$E$20/100)) -> 48 | H6: =+IF(YEAR(Hipótesis!$E$15)+Hipótesis!$E$19<FC!H3+1,FC!H5,G6*H4*(1+Hipótesis!$E$20/100)) -> 48 | I6: =+IF(YEAR(Hipótesis!$E$15)+Hipótesis!$E$19<FC!I3+1,FC!I5,H6*I4*(1+Hipótesis!$E$20/100)) -> 48 | J6: =+IF(YEAR(Hipótesis!$E$15)+Hipótesis!$E$19<FC!J3+1,FC!J5,I6*J4*(1+Hipótesis!$E$20/100)) -> 48 | K6: =+IF(YEAR(Hipótesis!$E$15)+Hipótesis!$E$19<FC!K3+1,FC!K5,J6*K4*(1+Hipótesis!$E$20/100)) -> 48 | L6: =+IF(YEAR(Hipótesis!$E$15)+Hipótesis!$E$19<FC!L3+1,FC!L5,K6*L4*(1+Hipótesis!$E$20/100)) -> 48 | M6: =+IF(YEAR(Hipótesis!$E$15)+Hipótesis!$E$19<FC!M3+1,FC!M5,L6*M4*(1+Hipótesis!$E$20/100)) -> 48 | ... AH6: =+IF(YEAR(Hipótesis!$E$15)+Hipótesis!$E$19<FC!AH3+1,FC!AH5,AG6*AH4*(1+Hipótesis!$E$20/100)) -> 116.495 | AI6: =+AH6*(1+Hipótesis!$E$21%)*AI4 -> 0 | AJ6: =+AI6*(1+Hipótesis!$E$21%)*AJ4 -> 0
B7: Senda Precios ACTIVA | C7: €/MWh | E7: =+IF(Hipótesis!$E$16="Mercado",FC!E5,FC!E6) -> 65 | F7: =+IF(Hipótesis!$E$16="Mercado",FC!F5,FC!F6) -> 65 | G7: =+IF(Hipótesis!$E$16="Mercado",FC!G5,FC!G6) -> 65 | H7: =+IF(Hipótesis!$E$16="Mercado",FC!H5,FC!H6) -> 66.3 | I7: =+IF(Hipótesis!$E$16="Mercado",FC!I5,FC!I6) -> 67.626 | J7: =+IF(Hipótesis!$E$16="Mercado",FC!J5,FC!J6) -> 68.97852 | K7: =+IF(Hipótesis!$E$16="Mercado",FC!K5,FC!K6) -> 70.35809 | L7: =+IF(Hipótesis!$E$16="Mercado",FC!L5,FC!L6) -> 75.353515 | ... AJ7: =+IF(Hipótesis!$E$16="Mercado",FC!AJ5,FC!AJ6) -> 0
B8: Costes Operativos | C8: €/KW | E8: =Hipótesis!E12 -> 50 | F8: =E8*(1+Hipótesis!$E$21%)*F4 -> 51 | G8: =F8*(1+Hipótesis!$E$21%)*G4 -> 52.02 | H8: =G8*(1+Hipótesis!$E$21%)*H4 -> 53.0604 | I8: =H8*(1+Hipótesis!$E$21%)*I4 -> 54.121608 | J8: =I8*(1+Hipótesis!$E$21%)*J4 -> 55.20404 | K8: =J8*(1+Hipótesis!$E$21%)*K4 -> 56.308121 | L8: =K8*(1+Hipótesis!$E$21%)*L4 -> 57.434283 | M8: =L8*(1+Hipótesis!$E$21%)*M4 -> 58.582969 | ... AJ8: =AI8*(1+Hipótesis!$E$21%)*AJ4 -> 0
B9: Inversión | C9: €/KW | D9: =0%*Hipótesis!$E$8*Hipótesis!$E$7 -> 0 | E9: =100%*Hipótesis!$E$8*Hipótesis!$E$7 -> 62500 | F9: =0%*Hipótesis!$E$8*Hipótesis!$E$7 -> 0
B11: 1. Cuenta de Resultados
B13: Concepto | C13: Unidades | D13: =+D3 -> 2025 | E13: =+E3 -> 2026 | F13: =+F3 -> 2027 | G13: =+G3 -> 2028 | H13: =+H3 -> 2029 | I13: =+I3 -> 2030 | J13: =+J3 -> 2031 | K13: =+K3 -> 2032 | ... AJ13: =+AJ3 -> 2057
B14: Ingresos | C14: m€ | D14: =D7*Hipótesis!$E$7*Hipótesis!$E$10 -> 0 | E14: =E7*Hipótesis!$E$7*Hipótesis!$E$10/1000 -> 7637.5 | F14: =F7*Hipótesis!$E$7*Hipótesis!$E$10/1000 -> 7637.5 | G14: =G7*Hipótesis!$E$7*Hipótesis!$E$10/1000 -> 7637.5 | H14: =H7*Hipótesis!$E$7*Hipótesis!$E$10/1000 -> 7790.25 | I14: =I7*Hipótesis!$E$7*Hipótesis!$E$10/1000 -> 7946.055 | J14: =J7*Hipótesis!$E$7*Hipótesis!$E$10/1000 -> 8104.9761 | K14: =K7*Hipótesis!$E$7*Hipótesis!$E$10/1000 -> 8267.0756 | L14: =L7*Hipótesis!$E$7*Hipótesis!$E$10/1000 -> 8854.038 | ... AJ14: =AJ7*Hipótesis!$E$7*Hipótesis!$E$10/1000 -> 0
B15: CMV | C15: m€ | D15: 0 | E15: =(-Hipótesis!$E$11*Hipótesis!$E$10*Hipótesis!$E$7/1000)*E4 -> -117.5 | F15: =(-Hipótesis!$E$11*Hipótesis!$E$10*Hipótesis!$E$7/1000)*F4 -> -117.5 | G15: =(-Hipótesis!$E$11*Hipótesis!$E$10*Hipótesis!$E$7/1000)*G4 -> -117.5 | H15: =(-Hipótesis!$E$11*Hipótesis!$E$10*Hipótesis!$E$7/1000)*H4 -> -117.5 | I15: =(-Hipótesis!$E$11*Hipótesis!$E$10*Hipótesis!$E$7/1000)*I4 -> -117.5 | J15: =(-Hipótesis!$E$11*Hipótesis!$E$10*Hipótesis!$E$7/1000)*J4 -> -117.5 | K15: =(-Hipótesis!$E$11*Hipótesis!$E$10*Hipótesis!$E$7/1000)*K4 -> -117.5 | L15: =(-Hipótesis!$E$11*Hipótesis!$E$10*Hipótesis!$E$7/1000)*L4 -> -117.5 | ... AJ15: =(-Hipótesis!$E$11*Hipótesis!$E$10*Hipótesis!$E$7/1000)*AJ4 -> 0
B16: Margen Bruto | C16: m€ | D16: =D14 -> 0 | E16: =E14+E15 -> 7520 | F16: =F14 -> 7637.5 | G16: =G14 -> 7637.5 | H16: =H14 -> 7790.25 | I16: =I14 -> 7946.055 | J16: =J14 -> 8104.9761 | K16: =K14 -> 8267.0756 | L16: =L14 -> 8854.038 | M16: =M14 -> 9031.1188 | ... AJ16: =AJ14 -> 0
B17: Costes Operativos | C17: m€ | D17: =D8*Hipótesis!$E$7 -> 0 | E17: =E8*Hipótesis!$E$7*50%*E4 -> 1250 | F17: =F8*Hipótesis!$E$7*50%*F4 -> 1275 | G17: =G8*Hipótesis!$E$7*50%*G4 -> 1300.5 | H17: =H8*Hipótesis!$E$7*50%*H4 -> 1326.51 | I17: =I8*Hipótesis!$E$7*50%*I4 -> 1353.0402 | J17: =J8*Hipótesis!$E$7*50%*J4 -> 1380.101 | K17: =K8*Hipótesis!$E$7*50%*K4 -> 1407.703 | L17: =L8*Hipótesis!$E$7*50%*L4 -> 1435.8571 | ... AJ17: =AJ8*Hipótesis!$E$7*50%*AJ4 -> 0
B18: EBITDA | C18: m€ | D18: =D16-D17 -> 0 | E18: =E16-E17 -> 6270 | F18: =F16-F17 -> 6362.5 | G18: =G16-G17 -> 6337 | H18: =H16-H17 -> 6463.74 | I18: =I16-I17 -> 6593.0148 | J18: =J16-J17 -> 6724.8751 | K18: =K16-K17 -> 6859.3726 | ... AJ18: =AJ16-AJ17 -> 0
B19: Amortización | C19: m€ | D19: 0 | E19: =(Hipótesis!$E$7*Hipótesis!$E$8/Hipótesis!$E$13)*E4 -> 2083.3333 | F19: =(Hipótesis!$E$7*Hipótesis!$E$8/Hipótesis!$E$13)*F4 -> 2083.3333 | G19: =(Hipótesis!$E$7*Hipótesis!$E$8/Hipótesis!$E$13)*G4 -> 2083.3333 | H19: =(Hipótesis!$E$7*Hipótesis!$E$8/Hipótesis!$E$13)*H4 -> 2083.3333 | I19: =(Hipótesis!$E$7*Hipótesis!$E$8/Hipótesis!$E$13)*I4 -> 2083.3333 | J19: =(Hipótesis!$E$7*Hipótesis!$E$8/Hipótesis!$E$13)*J4 -> 2083.3333 | K19: =(Hipótesis!$E$7*Hipótesis!$E$8/Hipótesis!$E$13)*K4 -> 2083.3333 | L19: =(Hipótesis!$E$7*Hipótesis!$E$8/Hipótesis!$E$13)*L4 -> 2083.3333 | ... AJ19: =(Hipótesis!$E$7*Hipótesis!$E$8/Hipótesis!$E$13)*AJ4 -> 0
B20: EBIT | C20: m€ | D20: =D18-D19 -> 0 | E20: =E18-E19 -> 4186.6667 | F20: =F18-F19 -> 4279.1667 | G20: =G18-G19 -> 4253.6667 | H20: =H18-H19 -> 4380.4067 | I20: =I18-I19 -> 4509.6815 | J20: =J18-J19 -> 4641.5418 | K20: =K18-K19 -> 4776.0393 | ... AJ20: =AJ18-AJ19 -> 0
B21: Intereses | C21: m€ | D21: 0 | E21: =-E83 -> 1257.8125 | F21: =-F83 -> 1148.4375 | G21: =-G83 -> 1039.0625 | H21: =-H83 -> 929.6875 | I21: =-I83 -> 820.3125 | J21: =-J83 -> 710.9375 | K21: =-K83 -> 601.5625 | L21: =-L83 -> 492.1875 | ... AJ21: =-AJ83 -> 0
B22: EBT | C22: m€ | D22: =D20-D21 -> 0 | E22: =E20-E21 -> 2928.8542 | F22: =F20-F21 -> 3130.7292 | G22: =G20-G21 -> 3214.6042 | H22: =H20-H21 -> 3450.7192 | I22: =I20-I21 -> 3689.369 | J22: =J20-J21 -> 3930.6043 | K22: =K20-K21 -> 4174.4768 | ... AJ22: =AJ20-AJ21 -> 0
B23: Impuestos | C23: m€ | D23: =-D22*Hipótesis!$E$22% -> 0 | E23: =-E22*Hipótesis!$E$22% -> -732.21354 | F23: =-F22*Hipótesis!$E$22% -> -782.68229 | G23: =-G22*Hipótesis!$E$22% -> -803.65104 | H23: =-H22*Hipótesis!$E$22% -> -862.67979 | I23: =-I22*Hipótesis!$E$22% -> -922.34224 | J23: =-J22*Hipótesis!$E$22% -> -982.65107 | K23: =-K22*Hipótesis!$E$22% -> -1043.6192 | ... AJ23: =-AJ22*Hipótesis!$E$22% -> 0
B24: R.Neto | C24: m€ | D24: =D22+D23 -> 0 | E24: =E22+E23 -> 2196.6406 | F24: =F22+F23 -> 2348.0469 | G24: =G22+G23 -> 2410.9531 | H24: =H22+H23 -> 2588.0394 | I24: =I22+I23 -> 2767.0267 | J24: =J22+J23 -> 2947.9532 | K24: =K22+K23 -> 3130.8576 | ... AJ24: =AJ22+AJ23 -> 0
B27: 2. Flujo de Caja
B29: Concepto | C29: Unidades | D29: =+D13 -> 2025 | E29: =+E13 -> 2026 | F29: =+F13 -> 2027 | G29: =+G13 -> 2028 | H29: =+H13 -> 2029 | I29: =+I13 -> 2030 | J29: =+J13 -> 2031 | K29: =+K13 -> 2032 | ... AJ29: =+AJ13 -> 2057
B30: Ingresos | C30: m€ | D30: =D14 -> 0 | E30: =E14 -> 7637.5 | F30: =F14 -> 7637.5 | G30: =G14 -> 7637.5 | H30: =H14 -> 7790.25 | I30: =I14 -> 7946.055 | J30: =J14 -> 8104.9761 | K30: =K14 -> 8267.0756 | ... AJ30: =AJ14 -> 0
B31: CMV | C31: m€ | D31: =D15 -> 0 | E31: =E15 -> -117.5 | F31: =F15 -> -117.5 | G31: =G15 -> -117.5 | H31: =H15 -> -117.5 | I31: =I15 -> -117.5 | J31: =J15 -> -117.5 | K31: =K15 -> -117.5 | ... AJ31: =AJ15 -> 0
B32: Margen Bruto | C32: m€ | D32: =D16 -> 0 | E32: =E16 -> 7520 | F32: =F16 -> 7637.5 | G32: =G16 -> 7637.5 | H32: =H16 -> 7790.25 | I32: =I16 -> 7946.055 | J32: =J16 -> 8104.9761 | K32: =K16 -> 8267.0756 | ... AJ32: =AJ16 -> 0
B33: Costes Operativos | C33: m€ | D33: =D17 -> 0 | E33: =E17 -> 1250 | F33: =F17 -> 1275 | G33: =G17 -> 1300.5 | H33: =H17 -> 1326.51 | I33: =I17 -> 1353.0402 | J33: =J17 -> 1380.101 | K33: =K17 -> 1407.703 | ... AJ33: =AJ17 -> 0
B34: EBITDA | C34: m€ | D34: =D18 -> 0 | E34: =E18 -> 6270 | F34: =F18 -> 6362.5 | G34: =G18 -> 6337 | H34: =H18 -> 6463.74 | I34: =I18 -> 6593.0148 | J34: =J18 -> 6724.8751 | K34: =K18 -> 6859.3726 | ... AJ34: =AJ18 -> 0
B35: Impuestos | C35: m€ | D35: =D23 -> 0 | E35: =-Hipótesis!$E$22%*FC!E20 -> -1046.6667 | F35: =-Hipótesis!$E$22%*FC!F20 -> -1069.7917 | G35: =-Hipótesis!$E$22%*FC!G20 -> -1063.4167 | H35: =-Hipótesis!$E$22%*FC!H20 -> -1095.1017 | I35: =-Hipótesis!$E$22%*FC!I20 -> -1127.4204 | J35: =-Hipótesis!$E$22%*FC!J20 -> -1160.3854 | K35: =-Hipótesis!$E$22%*FC!K20 -> -1194.0098 | L35: =-Hipótesis!$E$22%*FC!L20 -> -1333.7119 | ... AJ35: =-Hipótesis!$E$22%*FC!AJ20 -> 0
B36: F. Caja Operativo | C36: m€ | E36: =E34+E35 -> 5223.3333 | F36: =F34+F35 -> 5292.7083 | G36: =G34+G35 -> 5273.5833 | H36: =H34+H35 -> 5368.6383 | I36: =I34+I35 -> 5465.5944 | J36: =J34+J35 -> 5564.4897 | K36: =K34+K35 -> 5665.3628 | L36: =L34+L35 -> 6084.469 | ... AJ36: =AJ34+AJ35 -> 0
B37: Inversión | C37: m€ | D37: =-D9 -> 0 | E37: =-E9 -> -62500 | F37: =-F9 -> 0
B38: Prima | E38: =-Hipótesis!E9*Hipótesis!E7 -> -7500
B39: Valor residual | C39: m€ | H39: =IF(H29=YEAR(Hipótesis!$E$15)+25,-$E$37*Hipótesis!$E$14*(1+2%)^Hipótesis!#REF!,0) -> 0 | I39: =IF(I29=YEAR(Hipótesis!$E$15)+25,-$E$37*Hipótesis!$E$14*(1+2%)^Hipótesis!#REF!,0) -> 0 | J39: =IF(J29=YEAR(Hipótesis!$E$15)+25,-$E$37*Hipótesis!$E$14*(1+2%)^Hipótesis!#REF!,0) -> 0 | K39: =IF(K29=YEAR(Hipótesis!$E$15)+25,-$E$37*Hipótesis!$E$14*(1+2%)^Hipótesis!#REF!,0) -> 0 | L39: =IF(L29=YEAR(Hipótesis!$E$15)+25,-$E$37*Hipótesis!$E$14*(1+2%)^Hipótesis!#REF!,0) -> 0 | M39: =IF(M29=YEAR(Hipótesis!$E$15)+25,-$E$37*Hipótesis!$E$14*(1+2%)^Hipótesis!#REF!,0) -> 0 | N39: =IF(N29=YEAR(Hipótesis!$E$15)+25,-$E$37*Hipótesis!$E$14*(1+2%)^Hipótesis!#REF!,0) -> 0 | O39: =IF(O29=YEAR(Hipótesis!$E$15)+25,-$E$37*Hipótesis!$E$14*(1+2%)^Hipótesis!#REF!,0) -> 0 | ... T39: =IF(T29=YEAR(Hipótesis!$E$15)+25,-$E$37*Hipótesis!$E$14*(1+2%)^Hipótesis!#REF!,0) -> 0 | U39: =IF(U29=YEAR(Hipótesis!$E$15)+25,-$E$37*Hipótesis!$E$14*(1+2%)^Hipótesis!A13,0) -> 0 | V39: =IF(V29=YEAR(Hipótesis!$E$15)+25,-$E$37*Hipótesis!$E$14*(1+2%)^Hipótesis!B13,0) -> 0 | W39: =IF(W29=YEAR(Hipótesis!$E$15)+25,-$E$37*Hipótesis!$E$14*(1+2%)^Hipótesis!C13,0) -> 0 | X39: =IF(X29=YEAR(Hipótesis!$E$15)+25,-$E$37*Hipótesis!$E$14*(1+2%)^Hipótesis!D13,0) -> 0 | Y39: =IF(Y29=YEAR(Hipótesis!$E$15)+25,-$E$37*Hipótesis!$E$14*(1+2%)^Hipótesis!E13,0) -> 0 | Z39: =IF(Z29=YEAR(Hipótesis!$E$15)+25,-$E$37*Hipótesis!$E$14*(1+2%)^Hipótesis!F13,0) -> 0 | AA39: =IF(AA29=YEAR(Hipótesis!$E$15)+25,-$E$37*Hipótesis!$E$14*(1+2%)^Hipótesis!G13,0) -> 0 | AB39: =IF(AB29=YEAR(Hipótesis!$E$15)+25,-$E$37*Hipótesis!$E$14*(1+2%)^Hipótesis!H13,0) -> 0 | AC39: =IF(AC29=YEAR(Hipótesis!$E$15)+25,-$E$37*Hipótesis!$E$14*(1+2%)^Hipótesis!I13,0) -> 0 | AD39: =IF(AD29=YEAR(Hipótesis!$E$15)+Hipótesis!$E$13,-$E$37*Hipótesis!$E$14*(1+2%)^Hipótesis!J13,0) -> 0 | AE39: =IF(AE29=YEAR(Hipótesis!$E$15)+Hipótesis!$E$13,-$E$37*Hipótesis!$E$14*(1+2%)^Hipótesis!K13,0) -> 0 | AF39: =IF(AF29=YEAR(Hipótesis!$E$15)+Hipótesis!$E$13,-$E$37*Hipótesis!$E$14*(1+2%)^Hipótesis!L13,0) -> 0 | AG39: =IF(AG29=YEAR(Hipótesis!$E$15)+Hipótesis!$E$13,-$E$37*Hipótesis!$E$14*(1+2%)^Hipótesis!M13,0) -> 0 | AH39: =IF(AH29=YEAR(Hipótesis!$E$15)+Hipótesis!$E$13,-$E$37*Hipótesis!$E$14*(1+2%)^Hipótesis!N13,0) -> 0 | AI39: =IF(AI29=YEAR(Hipótesis!$E$15)+Hipótesis!$E$13,-$E$37*Hipótesis!$E$14*(1+2%)^Hipótesis!O13,0) -> 3125 | AJ39: =IF(AJ29=YEAR(Hipótesis!$E$15)+25,-$E$37*Hipótesis!$E$14*(1+2%)^Hipótesis!P13,0) -> 0
B40: FCL | C40: m€ | D40: =D39+D37+D36+D38 -> 0 | E40: =E39+E37+E36+E38 -> -64776.667 | F40: =F39+F37+F36+F38 -> 5292.7083 | G40: =G39+G37+G36+G38 -> 5273.5833 | H40: =H39+H37+H36+H38 -> 5368.6383 | I40: =I39+I37+I36+I38 -> 5465.5944 | J40: =J39+J37+J36+J38 -> 5564.4897 | K40: =K39+K37+K36+K38 -> 5665.3628 | ... AJ40: =AJ39+AJ37+AJ36+AJ38 -> 0
B43: TIR | C43: =IRR(E40:AJ40) -> 0.089742009
B44: WACC | C44: =+Hipótesis!E26 -> 0.06375
B45: VAN (k.€) | C45: =+NPV(C44,E40:AJ40) -> 19471.614
B47: 3. Flujo de Caja Amortización Acelerada
B49: Concepto | C49: Unidades | D49: =+D29 -> 2025 | E49: =+E29 -> 2026 | F49: =+F29 -> 2027 | G49: =+G29 -> 2028 | H49: =+H29 -> 2029 | I49: =+I29 -> 2030 | J49: =+J29 -> 2031 | K49: =+K29 -> 2032 | ... AJ49: =+AJ29 -> 2057
...

Sheet P&L
C3: 1. Cuenta de Resultados
D5: =+FC!E3 -> 2026 | E5: =+FC!F3 -> 2027 | F5: =+FC!G3 -> 2028 | H5: =+D5 -> 2026 | I5: =+E5 -> 2027 | J5: =+F5 -> 2028
C6: Ventas | D6: =+FC!E14 -> 7637.5 | E6: =+FC!F14 -> 7637.5 | F6: =+FC!G14 -> 7637.5 | H6: =D6/$D$6 -> 1 | I6: =E6/$E$6 -> 1 | J6: =F6/$F$6 -> 1
C7: CMV | D7: =+FC!E15 -> -117.5 | E7: =+FC!F15 -> -117.5 | F7: =+FC!G15 -> -117.5 | H7: =D7/$D$6 -> -0.015384615 | I7: =E7/$E$6 -> -0.015384615 | J7: =F7/$F$6 -> -0.015384615
C8: Margen Bruto | D8: =D6+D7 -> 7520 | E8: =E6+E7 -> 7520 | F8: =F6+F7 -> 7520 | H8: =D8/$D$6 -> 0.98461538 | I8: =E8/$E$6 -> 0.98461538 | J8: =F8/$F$6 -> 0.98461538
C9: Costes Operativos | D9: =-FC!E33 -> -1250 | E9: =-FC!F33 -> -1275 | F9: =-FC!G33 -> -1300.5 | H9: =D9/$D$6 -> -0.16366612 | I9: =E9/$E$6 -> -0.16693944 | J9: =F9/$F$6 -> -0.17027823
C10: EBITDA | D10: =+D8+D9 -> 6270 | E10: =+E8+E9 -> 6245 | F10: =+F8+F9 -> 6219.5 | H10: =D10/$D$6 -> 0.82094926 | I10: =E10/$E$6 -> 0.81767594 | J10: =F10/$F$6 -> 0.81433715
C11: Amortización | D11: =-FC!E19 -> -2083.3333 | E11: =-FC!F19 -> -2083.3333 | F11: =-FC!G19 -> -2083.3333 | H11: =D11/$D$6 -> -0.27277687 | I11: =E11/$E$6 -> -0.27277687 | J11: =F11/$F$6 -> -0.27277687
C12: EBIT | D12: =+D10+D11 -> 4186.6667 | E12: =+E10+E11 -> 4161.6667 | F12: =+F10+F11 -> 4136.1667 | H12: =D12/$D$6 -> 0.54817239 | I12: =E12/$E$6 -> 0.54489907 | J12: =F12/$F$6 -> 0.54156028
C13: Gastos Financieros | D13: =-FC!E21 -> -1257.8125 | E13: =-FC!F21 -> -1148.4375 | F13: =-FC!G21 -> -1039.0625 | H13: =D13/$D$6 -> -0.16468903 | I13: =E13/$E$6 -> -0.15036825 | J13: =F13/$F$6 -> -0.13604746
C14: EBT | D14: =+D12+D13 -> 2928.8542 | E14: =+E12+E13 -> 3013.2292 | F14: =+F12+F13 -> 3097.1042 | H14: =D14/$D$6 -> 0.38348336 | I14: =E14/$E$6 -> 0.39453082 | J14: =F14/$F$6 -> 0.40551282
C15: Impuestos | D15: =+FC!E23 -> -732.21354 | E15: =+FC!F23 -> -782.68229 | F15: =+FC!G23 -> -803.65104 | H15: =D15/$D$6 -> -0.09587084 | I15: =E15/$E$6 -> -0.10247886 | J15: =F15/$F$6 -> -0.10522436
C16: Beneficio Neto | D16: =+D14+D15 -> 2196.6406 | E16: =+E14+E15 -> 2230.5469 | F16: =+F14+F15 -> 2293.4531 | H16: =D16/$D$6 -> 0.28761252 | I16: =E16/$E$6 -> 0.29205196 | J16: =F16/$F$6 -> 0.30028846

Sheet Senda de precios mercado
B2: =+Hipótesis!E6 -> Eólica
B4: Senda Pesimista | C4: Senda Base | D4: Senda optimista | F4: Evol Senda Base | G4: Apuntamiento
A5: 2026 | B5: =+C5 -> 65 | C5: =65*F5*G5 -> 65 | D5: =+C5 -> 65 | F5: 1 | G5: =+IF(B2="PV",0.5,1) -> 1
A6: =+A5+1 -> 2027 | B6: =+C6*0.8 -> 52 | C6: =+C5*F6*G6/G5 -> 65 | D6: =+C6*1.2 -> 78 | F6: 1 | G6: =+IF($B$2="PV",+G5*1.05,1) -> 1
A7: =+A6+1 -> 2028 | B7: =+C7*0.8 -> 52 | C7: =+C6*F7*G7/G6 -> 65 | D7: =+C7*1.2 -> 78 | F7: 1 | G7: =+IF($B$2="PV",+G6*1.05,1) -> 1
A8: =+A7+1 -> 2029 | B8: =+C8*0.8 -> 53.04 | C8: =+C7*F8*G8/G7 -> 66.3 | D8: =+C8*1.2 -> 79.56 | F8: =1+Hipótesis!$E$21% -> 1.02 | G8: =+IF($B$2="PV",+G7*1.05,1) -> 1
A9: =+A8+1 -> 2030 | B9: =+C9*0.8 -> 54.1008 | C9: =+C8*F9*G9/G8 -> 67.626 | D9: =+C9*1.2 -> 81.1512 | F9: =1+Hipótesis!$E$21% -> 1.02 | G9: =+IF($B$2="PV",+G8*1.05,1) -> 1
A10: =+A9+1 -> 2031 | B10: =+C10*0.8 -> 55.182816 | C10: =+C9*F10*G10/G9 -> 68.97852 | D10: =+C10*1.2 -> 82.774224 | F10: =1+Hipótesis!$E$21% -> 1.02 | G10: =+IF($B$2="PV",+G9*1.05,1) -> 1
A11: =+A10+1 -> 2032 | B11: =+C11*0.8 -> 56.286472 | C11: =+C10*F11*G11/G10 -> 70.35809 | D11: =+C11*1.2 -> 84.429708 | F11: =1+Hipótesis!$E$21% -> 1.02 | G11: =+IF($B$2="PV",+G10*1.05,1) -> 1
A12: =+A11+1 -> 2033 | B12: =+C12*0.8 -> 60.282812 | C12: =+C11*F12*G12/G11 -> 75.353515 | D12: =+C12*1.2 -> 90.424218 | F12: =1+Hipótesis!$E$21% -> 1.02 | G12: =+G11*1.05 -> 1.05
A13: =+A12+1 -> 2034 | B13: =+C13*0.8 -> 61.488468 | C13: =+C12*F13*G13/G12 -> 76.860585 | D13: =+C13*1.2 -> 92.232702 | F13: =1+Hipótesis!$E$21% -> 1.02 | G13: =+G12 -> 1.05
A14: =+A13+1 -> 2035 | B14: =+C14*0.8 -> 62.718237 | C14: =+C13*F14*G14/G13 -> 78.397797 | D14: =+C14*1.2 -> 94.077356 | F14: =1+Hipótesis!$E$21% -> 1.02 | G14: =+G13 -> 1.05
A15: =+A14+1 -> 2036 | B15: =+C15*0.8 -> 63.972602 | C15: =+C14*F15*G15/G14 -> 79.965753 | D15: =+C15*1.2 -> 95.958903 | F15: =1+Hipótesis!$E$21% -> 1.02 | G15: =+G14 -> 1.05
A16: =+A15+1 -> 2037 | B16: =+C16*0.8 -> 65.252054 | C16: =+C15*F16*G16/G15 -> 81.565068 | D16: =+C16*1.2 -> 97.878081 | F16: =1+Hipótesis!$E$21% -> 1.02 | G16: =+G15 -> 1.05
A17: =+A16+1 -> 2038 | B17: =+C17*0.8 -> 66.557095 | C17: =+C16*F17*G17/G16 -> 83.196369 | D17: =+C17*1.2 -> 99.835643 | F17: =1+Hipótesis!$E$21% -> 1.02 | G17: =+G16 -> 1.05
A18: =+A17+1 -> 2039 | B18: =+C18*0.8 -> 67.888237 | C18: =+C17*F18*G18/G17 -> 84.860297 | D18: =+C18*1.2 -> 101.83236 | F18: =1+Hipótesis!$E$21% -> 1.02 | G18: =+G17 -> 1.05
A19: =+A18+1 -> 2040 | B19: =+C19*0.8 -> 69.246002 | C19: =+C18*F19*G19/G18 -> 86.557502 | D19: =+C19*1.2 -> 103.869 | F19: =1+Hipótesis!$E$21% -> 1.02 | G19: =+G18 -> 1.05
A20: =+A19+1 -> 2041 | B20: =+C20*0.8 -> 70.630922 | C20: =+C19*F20*G20/G19 -> 88.288653 | D20: =+C20*1.2 -> 105.94638 | F20: =1+Hipótesis!$E$21% -> 1.02 | G20: =+G19 -> 1.05
A21: =+A20+1 -> 2042 | B21: =+C21*0.8 -> 72.04354 | C21: =+C20*F21*G21/G20 -> 90.054426 | D21: =+C21*1.2 -> 108.06531 | F21: =1+Hipótesis!$E$21% -> 1.02 | G21: =+G20 -> 1.05
A22: =+A21+1 -> 2043 | B22: =+C22*0.8 -> 73.484411 | C22: =+C21*F22*G22/G21 -> 91.855514 | D22: =+C22*1.2 -> 110.22662 | F22: =1+Hipótesis!$E$21% -> 1.02 | G22: =+G21 -> 1.05
A23: =+A22+1 -> 2044 | B23: =+C23*0.8 -> 74.954099 | C23: =+C22*F23*G23/G22 -> 93.692624 | D23: =+C23*1.2 -> 112.43115 | F23: =1+Hipótesis!$E$21% -> 1.02 | G23: =+G22 -> 1.05
A24: =+A23+1 -> 2045 | B24: =+C24*0.8 -> 76.453181 | C24: =+C23*F24*G24/G23 -> 95.566477 | D24: =+C24*1.2 -> 114.67977 | F24: =1+Hipótesis!$E$21% -> 1.02 | G24: =+G23 -> 1.05
... A42: =+A41+1 -> 2063 | B42: =+C42*0.8 -> 109.19397 | C42: =+C41*F42*G42/G41 -> 136.49246 | D42: =+C42*1.2 -> 163.79095 | F42: =1+Hipótesis!$E$21% -> 1.02 | G42: =+G41 -> 1.05
