Workbook
Name AL: #REF!
Name AL: #REF!
Name AL: #REF!
Name AL: #REF!
Name BE: [1]Gdm!#REF!
Name BE: [1]Gdm!#REF!
Name BE: [1]Gdm!#REF!
Name BE: [1]Gdm!#REF!
Name BE: [1]Gdm!#REF!
Name BEOP: #REF!
Name BEOP: #REF!
Name BEOP: #REF!
Name BEOP: #REF!
Name beta: #REF!
Name beta: #REF!
Name beta: #REF!
Name beta: #REF!
Name beta: #REF!
Name beta: #REF!
Name BOP: #REF!
Name BOP: #REF!
Name BOP: #REF!
Name BOP: #REF!
Name decli1: 'Ej.Lat -32'!$C$5
Name decli1: 'Ej-2a_TraySol_Mad'!$C$5
Name decli1: 'Ej-2b_Munich'!$C$5
Name decli1: 'Ej-2c_CMex'!$C$5
Name decli1: #REF!
Name Hp: #REF!
Name Hp: #REF!
Name Hp: #REF!
Name Hp: #REF!
Name Hp: #REF!
Name Hp: #REF!
Name Hp: #REF!
Name Hvp: #REF!
Name Hvp: #REF!
Name Hvp: #REF!
Name Hvp: #REF!
Name Hvp: #REF!
Name Hvp: #REF!
Name l: #REF!
Name l: #REF!
Name l: #REF!
Name l: #REF!
Name l: #REF!
Name l: #REF!
Name LAT: [1]Ghm!$C$4
Name lm: #REF!
Name lm: #REF!
Name lm: #REF!
Name lm: #REF!
Name lm: #REF!
Name lm: #REF!
Name lm: #REF!

Sheet Ej-1a_PosicSol_Madrid
A1: Lugar: | B1: Madrid | G1: Día | H1: Mes | I1: nº días/mes | J1: Día Juliano
H2: Enero | I2: 31 | J2: =IF(G2<>"",G2,"")
A3: Latitud | C3: Longitud | H3: Febrero | I3: 28 | J3: =IF(G3<>"",I2+G3,"")
A4: (º) | B4: (rad) | C4: (º) | G4: 22 | H4: Marzo | I4: 31 | J4: =IF(G4<>"",G4+I2+I3,"") -> 81
A5: =40+26/60 -> 40.433333 | B5: =RADIANS(A5) -> 0.70569479 | C5: =3+42/60 -> 3.7 | H5: Abril | I5: 30 | J5: =IF(G5<>"",G5+I2+I3+I4,"")
H6: Mayo | I6: 31 | J6: =IF(G6<>"",G6+I2+I3+I4+I5,"")
G7: 21 | H7: Junio | I7: 30 | J7: =IF(G7<>"",G7+I2+I3+I4+I5+I6,"") -> 172
H8: Julio | I8: 31 | J8: =IF(G8<>"",G8+I2+I3+I4+I5+I6+I7,"")
H9: Agosto | I9: 31 | J9: =IF(G9<>"",G9+I2+I3+I4+I5+I6+I7+I8,"")
G10: 21 | H10: Septiembre | I10: 30 | J10: =IF(G10<>"",G10+I2+I3+I4+I5+I6+I7+I8+I9,"") -> 264
G11: 24 | H11: Octubre | I11: 31 | J11: =IF(G11<>"",G11+I2+I3+I4+I5+I6+I7+I8+I9+I10,"") -> 297
H12: Noviembre | I12: 30 | J12: =IF(G12<>"",G12+I2+I3+I4+I5+I6+I7+I8+I9+I10+I11,"")
G13: 21 | H13: Diciembre | I13: 31 | J13: =IF(G13<>"",G13+I2+I3+I4+I5+I6+I7+I8+I9+I10+I11+I12,"") -> 355
A16: Día | B16: Declinación, d (º) | D16: Salida del sol, ws | G16: ET | I16: AO | J16: TO | K16: Máxima gs
A17: juliano | B17: (º) | C17: (rad) | D17: (rad) | E17: (º) | F17: (h) | G17: (min) | H17: (h) | I17: (h) | J17: (h) | K17: (rad) | L17: (º)
A18: 297 | B18: =23.45*SIN(RADIANS((360/365)*(A18+284))) -> -12.785888 | C18: =RADIANS(B18) -> -0.22315585 | D18: =-ACOS(-TAN(C18)*TAN($B$5)) -> -1.3762056 | E18: =DEGREES(D18) -> -78.850775 | F18: =E18/15 -> -5.2567184 | G18: =-7.64*SIN(RADIANS(A18-2))+9.86*SIN(RADIANS(2*(A18-80))) -> 16.402232 | H18: =G18/60 -> 0.27337053 | I18: 1 | J18: =F18+12-H18+I18+($C$5-0)/15 -> 7.7165778 | K18: =ASIN(SIN(C18)*SIN($B$5)+COS(C18)*COS($B$5)) -> 0.64194568 | L18: =DEGREES(K18) -> 36.780778
J19: =TEXT(INT(J18),"#") & " horas" -> 7 horas
J20: =TEXT((J18-INT(J18))*60,"#") & " minutos" -> 43 minutos

Sheet Ej-1b_Munich
A1: Lugar: | B1: Múnich | G1: Día | H1: Mes | I1: nº días/mes | J1: Día Juliano
G2: 24 | H2: Enero | I2: 31 | J2: =IF(G2<>"",G2,"") -> 24
A3: Latitud | C3: Longitud | H3: Febrero | I3: 28 | J3: =IF(G3<>"",I2+G3,"")
A4: (º) | B4: (rad) | C4: (º) | G4: 22 | H4: Marzo | I4: 31 | J4: =IF(G4<>"",G4+I2+I3,"") -> 81
A5: =48+8/60 -> 48.133333 | B5: =RADIANS(A5) -> 0.84008515 | C5: =11.575 -> 11.575 | H5: Abril | I5: 30 | J5: =IF(G5<>"",G5+I2+I3+I4,"")
H6: Mayo | I6: 31 | J6: =IF(G6<>"",G6+I2+I3+I4+I5,"")
G7: 21 | H7: Junio | I7: 30 | J7: =IF(G7<>"",G7+I2+I3+I4+I5+I6,"") -> 172
H8: Julio | I8: 31 | J8: =IF(G8<>"",G8+I2+I3+I4+I5+I6+I7,"")
H9: Agosto | I9: 31 | J9: =IF(G9<>"",G9+I2+I3+I4+I5+I6+I7+I8,"")
G10: 21 | H10: Septiembre | I10: 30 | J10: =IF(G10<>"",G10+I2+I3+I4+I5+I6+I7+I8+I9,"") -> 264
H11: Octubre | I11: 31
H12: Noviembre | I12: 30 | J12: =IF(G12<>"",G12+I2+I3+I4+I5+I6+I7+I8+I9+I10+I11,"")
G13: 21 | H13: Diciembre | I13: 31 | J13: =IF(G13<>"",G13+I2+I3+I4+I5+I6+I7+I8+I9+I10+I11+I12,"") -> 355
A16: Día | B16: Declinación, d (º) | D16: Salida del sol, ws | G16: ET | I16: AO | J16: TO | K16: Máxima gs
A17: juliano | B17: (º) | C17: (rad) | D17: (rad) | E17: (º) | F17: (h) | G17: (min) | H17: (h) | I17: (h) | J17: (h) | K17: (rad) | L17: (º)
A18: ='Ej-1a_PosicSol_Madrid'!A18 -> 297 | B18: =23.45*SIN(RADIANS((360/365)*(A18+284))) -> -12.785888 | C18: =RADIANS(B18) -> -0.22315585 | D18: =-ACOS(-TAN(C18)*TAN($B$5)) -> -1.3147892 | E18: =DEGREES(D18) -> -75.331869 | F18: =E18/15 -> -5.0221246 | G18: =-7.64*SIN(RADIANS(A18-2))+9.86*SIN(RADIANS(2*(A18-80))) -> 16.402232 | H18: =G18/60 -> 0.27337053 | I18: 1 | J18: =F18+12-H18+I18+($C$5-0)/15 -> 8.4761715 | K18: =ASIN(SIN(C18)*SIN($B$5)+COS(C18)*COS($B$5)) -> 0.50755533 | L18: =DEGREES(K18) -> 29.080778
J19: =TEXT(INT(J18),"#") & " horas" -> 8 horas
J20: =TEXT((J18-INT(J18))*60,"#") & " minutos" -> 29 minutos

Sheet Ej-1c_CMexico
A1: Lugar: | B1: Ciudad de México | G1: Día | H1: Mes | I1: nº días/mes | J1: Día Juliano
G2: 24 | H2: Enero | I2: 31 | J2: =IF(G2<>"",G2,"") -> 24
A3: Latitud | C3: Longitud | H3: Febrero | I3: 28 | J3: =IF(G3<>"",I2+G3,"")
A4: (º) | B4: (rad) | C4: (º) | G4: 22 | H4: Marzo | I4: 31 | J4: =IF(G4<>"",G4+I2+I3,"") -> 81
A5: =19+28/60 -> 19.466667 | B5: =RADIANS(A5) -> 0.33975743 | C5: =99+9/60 -> 99.15 | H5: Abril | I5: 30 | J5: =IF(G5<>"",G5+I2+I3+I4,"")
H6: Mayo | I6: 31 | J6: =IF(G6<>"",G6+I2+I3+I4+I5,"")
G7: 21 | H7: Junio | I7: 30 | J7: =IF(G7<>"",G7+I2+I3+I4+I5+I6,"") -> 172
H8: Julio | I8: 31 | J8: =IF(G8<>"",G8+I2+I3+I4+I5+I6+I7,"")
H9: Agosto | I9: 31 | J9: =IF(G9<>"",G9+I2+I3+I4+I5+I6+I7+I8,"")
G10: 21 | H10: Septiembre | I10: 30 | J10: =IF(G10<>"",G10+I2+I3+I4+I5+I6+I7+I8+I9,"") -> 264
H11: Octubre | I11: 31 | J11: =IF(G11<>"",G11+I2+I3+I4+I5+I6+I7+I8+I9+I10,"")
H12: Noviembre | I12: 30 | J12: =IF(G12<>"",G12+I2+I3+I4+I5+I6+I7+I8+I9+I10+I11,"")
G13: 21 | H13: Diciembre | I13: 31 | J13: =IF(G13<>"",G13+I2+I3+I4+I5+I6+I7+I8+I9+I10+I11+I12,"") -> 355
A16: Día | B16: Declinación, d (º) | D16: Salida del sol, ws | G16: ET | I16: AO | J16: TO | K16: Máxima gs
A17: juliano | B17: (º) | C17: (rad) | D17: (rad) | E17: (º) | F17: (h) | G17: (min) | H17: (h) | I17: (h) | J17: (h) | K17: (rad) | L17: (º)
A18: ='Ej-1a_PosicSol_Madrid'!A18 -> 297 | B18: =23.45*SIN(RADIANS((360/365)*(A18+284))) -> -12.785888 | C18: =RADIANS(B18) -> -0.22315585 | D18: =-ACOS(-TAN(C18)*TAN($B$5)) -> -1.4904966 | E18: =DEGREES(D18) -> -85.399162 | F18: =E18/15 -> -5.6932775 | G18: =-7.64*SIN(RADIANS(A18-2))+9.86*SIN(RADIANS(2*(A18-80))) -> 16.402232 | H18: =G18/60 -> 0.27337053 | I18: -6 | J18: =F18+12-H18+I18+($C$5-0)/15 -> 6.643352 | K18: =ASIN(SIN(C18)*SIN($B$5)+COS(C18)*COS($B$5)) -> 1.0078831 | L18: =DEGREES(K18) -> 57.747445
J19: =TEXT(INT(J18),"#") & " horas" -> 6 horas
J20: =TEXT((J18-INT(J18))*60,"#") & " minutos" -> 39 minutos

Sheet Ej-2a_TraySol_Mad
C3: S.Junio | I3: Equinocios | O3: S.Diciembre | R3: Día, dn= | S3: ='Ej-1a_PosicSol_Madrid'!A18 -> 297
C4: (rad) | F4: (º) | G4: (rad) | L4: (º) | M4: (rad) | O4: (º) | P4: (rad) | R4: Declinación (º) | S4: (rad)
A5: Declinación (º): | B5: 23.45 | C5: =RADIANS(B5) -> 0.40927971 | F5: =B5/2 -> 11.725 | G5: =RADIANS(F5) -> 0.20463985 | I5: 0 | J5: =RADIANS(I5) -> 0 | L5: =-F5 -> -11.725 | M5: =RADIANS(L5) -> -0.20463985 | O5: =-B5 -> -23.45 | P5: =RADIANS(O5) -> -0.40927971 | R5: =IF(S3<>"",23.45*SIN(RADIANS(360*(S3+284)/365)),"") -> -12.785888 | S5: =RADIANS(R5) -> -0.22315585 | W5: 1 | X5: 17 | Z5: 7 | AA5: 198
A6: Latitud (º): | B6: 40.45 | C6: =RADIANS(B6) -> 0.70598568 | W6: 2 | X6: 46 | Z6: 8 | AA6: 228
D7: SVER | J7: EQUI | P7: SINV
D8: Elevación | E8: Acimut | W8: =A10 -> -120 | X8: =A25 -> -105 | Y8: =A40 -> -90 | Z8: =A55 -> -75 | AA8: =A70 -> -60 | AB8: =A85 -> -45 | AC8: =A100 -> -30 | AD8: =A115 -> -15 | AE8: =A131 -> 0.001 | AF8: =A146 -> 15 | AG8: =A161 -> 30 | AH8: =A176 -> 45 | AI8: =A191 -> 60 | AJ8: =A206 -> 75 | AK8: =A221 -> 90 | AL8: =A236 -> 105 | AM8: =A251 -> 120
A9: w (º) | B9: w (rad) | C9: JZS (º) | D9: gS (º) | E9: yS (º) | F9: JZS (º) | G9: gS (º) | H9: yS (º) | I9: JZS (º) | J9: gS (º) | K9: yS (º) | L9: JZS (º) | M9: gS (º) | N9: yS (º) | O9: JZS (º) | P9: gS (º) | Q9: yS (º) | R9: JZS (º) | S9: gS (º) | T9: yS (º) | V9: yS | W9: w = -8 | X9: w = -7 | Y9: w = -6 | Z9: w = -5 | AA9: w = -4 | AB9: w = -3 | AC9: w = -2 | AD9: w = -1 | AE9: w = 0 | AF9: w = 1 | AG9: w = 2 | AH9: w = 3 | AI9: w = 4 | AJ9: w = 5 | AK9: w = 6 | AL9: w = 7 | AM9: w = 8
A10: -120 | B10: =RADIANS(A10) -> -2.0943951 | C10: =DEGREES(ACOS(SIN(C$5)*SIN($C$6)+COS(C$5)*COS($C$6)*COS($B10))) -> 95.214131 | D10: =90-C10 -> -5.2141306 | E10: =DEGREES(-ACOS((SIN(RADIANS(D10))*SIN($C$6)-SIN(C$5))/(COS(RADIANS(D10))*COS($C$6)))) -> -127.0795 | F10: =DEGREES(ACOS(SIN(G$5)*SIN($C$6)+COS(G$5)*COS($C$6)*COS($B10))) -> 103.92814 | G10: =90-F10 -> -13.928135 | H10: =DEGREES(-ACOS((SIN(RADIANS(G10))*SIN($C$6)-SIN(G$5))/(COS(RADIANS(G10))*COS($C$6)))) -> -119.11539 | I10: =DEGREES(ACOS(SIN(J$5)*SIN($C$6)+COS(J$5)*COS($C$6)*COS($B10))) -> 112.3638 | J10: =90-I10 -> -22.363803 | K10: =DEGREES(-ACOS((SIN(RADIANS(J10))*SIN($C$6)-SIN(J$5))/(COS(RADIANS(J10))*COS($C$6)))) -> -110.53473 | L10: =DEGREES(ACOS(SIN(M$5)*SIN($C$6)+COS(M$5)*COS($C$6)*COS($B10))) -> 120.29083 | M10: =90-L10 -> -30.290832 | N10: =DEGREES(-ACOS((SIN(RADIANS(M10))*SIN($C$6)-SIN(M$5))/(COS(RADIANS(M10))*COS($C$6)))) -> -100.87995 | O10: =DEGREES(ACOS(SIN(P$5)*SIN($C$6)+COS(P$5)*COS($C$6)*COS($B10))) -> 127.39048 | P10: =90-O10 -> -37.390476 | Q10: =DEGREES(-ACOS((SIN(RADIANS(P10))*SIN($C$6)-SIN(P$5))/(COS(RADIANS(P10))*COS($C$6)))) -> -89.622976 | R10: =DEGREES(ACOS(SIN(S$5)*SIN($C$6)+COS(S$5)*COS($C$6)*COS($B10))) -> 120.97293 | S10: =90-R10 -> -30.972926 | T10: =DEGREES(-ACOS((SIN(RADIANS(S10))*SIN($C$6)-SIN(S$5))/(COS(RADIANS(S10))*COS($C$6)))) -> -99.935621 | V10: =E10 -> -127.0795 | W10: =D10 -> -5.2141306
A11: -119 | B11: =RADIANS(A11) -> -2.0769418 | C11: =DEGREES(ACOS(SIN(C$5)*SIN($C$6)+COS(C$5)*COS($C$6)*COS($B11))) -> 94.604284 | D11: =90-C11 -> -4.6042839 | E11: =DEGREES(-ACOS((SIN(RADIANS(D11))*SIN($C$6)-SIN(C$5))/(COS(RADIANS(D11))*COS($C$6)))) -> -126.39162 | F11: =DEGREES(ACOS(SIN(G$5)*SIN($C$6)+COS(G$5)*COS($C$6)*COS($B11))) -> 103.26095 | G11: =90-F11 -> -13.260951 | H11: =DEGREES(-ACOS((SIN(RADIANS(G11))*SIN($C$6)-SIN(G$5))/(COS(RADIANS(G11))*COS($C$6)))) -> -118.37809 | I11: =DEGREES(ACOS(SIN(J$5)*SIN($C$6)+COS(J$5)*COS($C$6)*COS($B11))) -> 111.64944 | J11: =90-I11 -> -21.649443 | K11: =DEGREES(-ACOS((SIN(RADIANS(J11))*SIN($C$6)-SIN(J$5))/(COS(RADIANS(J11))*COS($C$6)))) -> -109.77995 | L11: =DEGREES(ACOS(SIN(M$5)*SIN($C$6)+COS(M$5)*COS($C$6)*COS($B11))) -> 119.54264 | M11: =90-L11 -> -29.542644 | N11: =DEGREES(-ACOS((SIN(RADIANS(M11))*SIN($C$6)-SIN(M$5))/(COS(RADIANS(M11))*COS($C$6)))) -> -100.15125 | O11: =DEGREES(ACOS(SIN(P$5)*SIN($C$6)+COS(P$5)*COS($C$6)*COS($B11))) -> 126.62956 | P11: =90-O11 -> -36.629564 | Q11: =DEGREES(-ACOS((SIN(RADIANS(P11))*SIN($C$6)-SIN(P$5))/(COS(RADIANS(P11))*COS($C$6)))) -> -88.98117 | R11: =DEGREES(ACOS(SIN(S$5)*SIN($C$6)+COS(S$5)*COS($C$6)*COS($B11))) -> 120.22256 | S11: =90-R11 -> -30.222556 | T11: =DEGREES(-ACOS((SIN(RADIANS(S11))*SIN($C$6)-SIN(S$5))/(COS(RADIANS(S11))*COS($C$6)))) -> -99.211984 | V11: =H10 -> -119.11539 | W11: =G11 -> -13.260951
A12: -118 | B12: =RADIANS(A12) -> -2.0594885 | C12: =DEGREES(ACOS(SIN(C$5)*SIN($C$6)+COS(C$5)*COS($C$6)*COS($B12))) -> 93.989038 | D12: =90-C12 -> -3.989038 | E12: =DEGREES(-ACOS((SIN(RADIANS(D12))*SIN($C$6)-SIN(C$5))/(COS(RADIANS(D12))*COS($C$6)))) -> -125.70918 | F12: =DEGREES(ACOS(SIN(G$5)*SIN($C$6)+COS(G$5)*COS($C$6)*COS($B12))) -> 102.58913 | G12: =90-F12 -> -12.589132 | H12: =DEGREES(-ACOS((SIN(RADIANS(G12))*SIN($C$6)-SIN(G$5))/(COS(RADIANS(G12))*COS($C$6)))) -> -117.64727 | I12: =DEGREES(ACOS(SIN(J$5)*SIN($C$6)+COS(J$5)*COS($C$6)*COS($B12))) -> 110.93171 | J12: =90-I12 -> -20.931706 | K12: =DEGREES(-ACOS((SIN(RADIANS(J12))*SIN($C$6)-SIN(J$5))/(COS(RADIANS(J12))*COS($C$6)))) -> -109.03263 | L12: =DEGREES(ACOS(SIN(M$5)*SIN($C$6)+COS(M$5)*COS($C$6)*COS($B12))) -> 118.79276 | M12: =90-L12 -> -28.792758 | N12: =DEGREES(-ACOS((SIN(RADIANS(M12))*SIN($C$6)-SIN(M$5))/(COS(RADIANS(M12))*COS($C$6)))) -> -99.430226 | O12: =DEGREES(ACOS(SIN(P$5)*SIN($C$6)+COS(P$5)*COS($C$6)*COS($B12))) -> 125.8688 | P12: =90-O12 -> -35.868802 | Q12: =DEGREES(-ACOS((SIN(RADIANS(P12))*SIN($C$6)-SIN(P$5))/(COS(RADIANS(P12))*COS($C$6)))) -> -88.345392 | R12: =DEGREES(ACOS(SIN(S$5)*SIN($C$6)+COS(S$5)*COS($C$6)*COS($B12))) -> 119.47065 | S12: =90-R12 -> -29.470655 | T12: =DEGREES(-ACOS((SIN(RADIANS(S12))*SIN($C$6)-SIN(S$5))/(COS(RADIANS(S12))*COS($C$6)))) -> -98.495984 | V12: =K10 -> -110.53473 | W12: =J10 -> -22.363803
A13: -117 | B13: =RADIANS(A13) -> -2.0420352 | C13: =DEGREES(ACOS(SIN(C$5)*SIN($C$6)+COS(C$5)*COS($C$6)*COS($B13))) -> 93.368523 | D13: =90-C13 -> -3.3685225 | E13: =DEGREES(-ACOS((SIN(RADIANS(D13))*SIN($C$6)-SIN(C$5))/(COS(RADIANS(D13))*COS($C$6)))) -> -125.03206 | F13: =DEGREES(ACOS(SIN(G$5)*SIN($C$6)+COS(G$5)*COS($C$6)*COS($B13))) -> 101.91283 | G13: =90-F13 -> -11.912829 | H13: =DEGREES(-ACOS((SIN(RADIANS(G13))*SIN($C$6)-SIN(G$5))/(COS(RADIANS(G13))*COS($C$6)))) -> -116.92273 | I13: =DEGREES(ACOS(SIN(J$5)*SIN($C$6)+COS(J$5)*COS($C$6)*COS($B13))) -> 110.21075 | J13: =90-I13 -> -20.210749 | K13: =DEGREES(-ACOS((SIN(RADIANS(J13))*SIN($C$6)-SIN(J$5))/(COS(RADIANS(J13))*COS($C$6)))) -> -108.29244 | L13: =DEGREES(ACOS(SIN(M$5)*SIN($C$6)+COS(M$5)*COS($C$6)*COS($B13))) -> 118.04131 | M13: =90-L13 -> -28.041311 | N13: =DEGREES(-ACOS((SIN(RADIANS(M13))*SIN($C$6)-SIN(M$5))/(COS(RADIANS(M13))*COS($C$6)))) -> -98.716499 | O13: =DEGREES(ACOS(SIN(P$5)*SIN($C$6)+COS(P$5)*COS($C$6)*COS($B13))) -> 125.10828 | P13: =90-O13 -> -35.108284 | Q13: =DEGREES(-ACOS((SIN(RADIANS(P13))*SIN($C$6)-SIN(P$5))/(COS(RADIANS(P13))*COS($C$6)))) -> -87.715247 | R13: =DEGREES(ACOS(SIN(S$5)*SIN($C$6)+COS(S$5)*COS($C$6)*COS($B13))) -> 118.71736 | S13: =90-R13 -> -28.717356 | T13: =DEGREES(-ACOS((SIN(RADIANS(S13))*SIN($C$6)-SIN(S$5))/(COS(RADIANS(S13))*COS($C$6)))) -> -97.787221 | V13: =N10 -> -100.87995 | W13: =M10 -> -30.290832
A14: -116 | B14: =RADIANS(A14) -> -2.0245819 | C14: =DEGREES(ACOS(SIN(C$5)*SIN($C$6)+COS(C$5)*COS($C$6)*COS($B14))) -> 92.742864 | D14: =90-C14 -> -2.7428644 | E14: =DEGREES(-ACOS((SIN(RADIANS(D14))*SIN($C$6)-SIN(C$5))/(COS(RADIANS(D14))*COS($C$6)))) -> -124.36014 | F14: =DEGREES(ACOS(SIN(G$5)*SIN($C$6)+COS(G$5)*COS($C$6)*COS($B14))) -> 101.23219 | G14: =90-F14 -> -11.232187 | H14: =DEGREES(-ACOS((SIN(RADIANS(G14))*SIN($C$6)-SIN(G$5))/(COS(RADIANS(G14))*COS($C$6)))) -> -116.20425 | I14: =DEGREES(ACOS(SIN(J$5)*SIN($C$6)+COS(J$5)*COS($C$6)*COS($B14))) -> 109.48672 | J14: =90-I14 -> -19.486719 | K14: =DEGREES(-ACOS((SIN(RADIANS(J14))*SIN($C$6)-SIN(J$5))/(COS(RADIANS(J14))*COS($C$6)))) -> -107.5591 | L14: =DEGREES(ACOS(SIN(M$5)*SIN($C$6)+COS(M$5)*COS($C$6)*COS($B14))) -> 117.28843 | M14: =90-L14 -> -27.288434 | N14: =DEGREES(-ACOS((SIN(RADIANS(M14))*SIN($C$6)-SIN(M$5))/(COS(RADIANS(M14))*COS($C$6)))) -> -98.009683 | O14: =DEGREES(ACOS(SIN(P$5)*SIN($C$6)+COS(P$5)*COS($C$6)*COS($B14))) -> 124.3481 | P14: =90-O14 -> -34.348097 | Q14: =DEGREES(-ACOS((SIN(RADIANS(P14))*SIN($C$6)-SIN(P$5))/(COS(RADIANS(P14))*COS($C$6)))) -> -87.090356 | R14: =DEGREES(ACOS(SIN(S$5)*SIN($C$6)+COS(S$5)*COS($C$6)*COS($B14))) -> 117.96279 | S14: =90-R14 -> -27.962787 | T14: =DEGREES(-ACOS((SIN(RADIANS(S14))*SIN($C$6)-SIN(S$5))/(COS(RADIANS(S14))*COS($C$6)))) -> -97.085308 | V14: =Q10 -> -89.622976 | W14: =P10 -> -37.390476
A15: -115 | B15: =RADIANS(A15) -> -2.0071286 | C15: =DEGREES(ACOS(SIN(C$5)*SIN($C$6)+COS(C$5)*COS($C$6)*COS($B15))) -> 92.112189 | D15: =90-C15 -> -2.1121887 | E15: =DEGREES(-ACOS((SIN(RADIANS(D15))*SIN($C$6)-SIN(C$5))/(COS(RADIANS(D15))*COS($C$6)))) -> -123.6933 | F15: =DEGREES(ACOS(SIN(G$5)*SIN($C$6)+COS(G$5)*COS($C$6)*COS($B15))) -> 100.54735 | G15: =90-F15 -> -10.547348 | H15: =DEGREES(-ACOS((SIN(RADIANS(G15))*SIN($C$6)-SIN(G$5))/(COS(RADIANS(G15))*COS($C$6)))) -> -115.49163 | I15: =DEGREES(ACOS(SIN(J$5)*SIN($C$6)+COS(J$5)*COS($C$6)*COS($B15))) -> 108.75976 | J15: =90-I15 -> -18.759765 | K15: =DEGREES(-ACOS((SIN(RADIANS(J15))*SIN($C$6)-SIN(J$5))/(COS(RADIANS(J15))*COS($C$6)))) -> -106.8323 | L15: =DEGREES(ACOS(SIN(M$5)*SIN($C$6)+COS(M$5)*COS($C$6)*COS($B15))) -> 116.53426 | M15: =90-L15 -> -26.534255 | N15: =DEGREES(-ACOS((SIN(RADIANS(M15))*SIN($C$6)-SIN(M$5))/(COS(RADIANS(M15))*COS($C$6)))) -> -97.309406 | O15: =DEGREES(ACOS(SIN(P$5)*SIN($C$6)+COS(P$5)*COS($C$6)*COS($B15))) -> 123.58833 | P15: =90-O15 -> -33.58833 | Q15: =DEGREES(-ACOS((SIN(RADIANS(P15))*SIN($C$6)-SIN(P$5))/(COS(RADIANS(P15))*COS($C$6)))) -> -86.470356 | R15: =DEGREES(ACOS(SIN(S$5)*SIN($C$6)+COS(S$5)*COS($C$6)*COS($B15))) -> 117.20707 | S15: =90-R15 -> -27.207074 | T15: =DEGREES(-ACOS((SIN(RADIANS(S15))*SIN($C$6)-SIN(S$5))/(COS(RADIANS(S15))*COS($C$6)))) -> -96.38987
A16: -114 | B16: =RADIANS(A16) -> -1.9896753 | C16: =DEGREES(ACOS(SIN(C$5)*SIN($C$6)+COS(C$5)*COS($C$6)*COS($B16))) -> 91.476618 | D16: =90-C16 -> -1.4766179 | E16: =DEGREES(-ACOS((SIN(RADIANS(D16))*SIN($C$6)-SIN(C$5))/(COS(RADIANS(D16))*COS($C$6)))) -> -123.03139 | F16: =DEGREES(ACOS(SIN(G$5)*SIN($C$6)+COS(G$5)*COS($C$6)*COS($B16))) -> 99.858452 | G16: =90-F16 -> -9.8584521 | H16: =DEGREES(-ACOS((SIN(RADIANS(G16))*SIN($C$6)-SIN(G$5))/(COS(RADIANS(G16))*COS($C$6)))) -> -114.78466 | I16: =DEGREES(ACOS(SIN(J$5)*SIN($C$6)+COS(J$5)*COS($C$6)*COS($B16))) -> 108.03003 | J16: =90-I16 -> -18.030027 | K16: =DEGREES(-ACOS((SIN(RADIANS(J16))*SIN($C$6)-SIN(J$5))/(COS(RADIANS(J16))*COS($C$6)))) -> -106.11175 | L16: =DEGREES(ACOS(SIN(M$5)*SIN($C$6)+COS(M$5)*COS($C$6)*COS($B16))) -> 115.7789 | M16: =90-L16 -> -25.778898 | N16: =DEGREES(-ACOS((SIN(RADIANS(M16))*SIN($C$6)-SIN(M$5))/(COS(RADIANS(M16))*COS($C$6)))) -> -96.61531 | O16: =DEGREES(ACOS(SIN(P$5)*SIN($C$6)+COS(P$5)*COS($C$6)*COS($B16))) -> 122.82907 | P16: =90-O16 -> -32.829067 | Q16: =DEGREES(-ACOS((SIN(RADIANS(P16))*SIN($C$6)-SIN(P$5))/(COS(RADIANS(P16))*COS($C$6)))) -> -85.8549 | R16: =DEGREES(ACOS(SIN(S$5)*SIN($C$6)+COS(S$5)*COS($C$6)*COS($B16))) -> 116.45034 | S16: =90-R16 -> -26.450337 | T16: =DEGREES(-ACOS((SIN(RADIANS(S16))*SIN($C$6)-SIN(S$5))/(COS(RADIANS(S16))*COS($C$6)))) -> -95.700543
A17: -113 | B17: =RADIANS(A17) -> -1.9722221 | C17: =DEGREES(ACOS(SIN(C$5)*SIN($C$6)+COS(C$5)*COS($C$6)*COS($B17))) -> 90.836272 | D17: =90-C17 -> -0.83627244 | E17: =DEGREES(-ACOS((SIN(RADIANS(D17))*SIN($C$6)-SIN(C$5))/(COS(RADIANS(D17))*COS($C$6)))) -> -122.3743 | F17: =DEGREES(ACOS(SIN(G$5)*SIN($C$6)+COS(G$5)*COS($C$6)*COS($B17))) -> 99.165635 | G17: =90-F17 -> -9.1656349 | H17: =DEGREES(-ACOS((SIN(RADIANS(G17))*SIN($C$6)-SIN(G$5))/(COS(RADIANS(G17))*COS($C$6)))) -> -114.08312 | I17: =DEGREES(ACOS(SIN(J$5)*SIN($C$6)+COS(J$5)*COS($C$6)*COS($B17))) -> 107.29764 | J17: =90-I17 -> -17.297644 | K17: =DEGREES(-ACOS((SIN(RADIANS(J17))*SIN($C$6)-SIN(J$5))/(COS(RADIANS(J17))*COS($C$6)))) -> -105.39716 | L17: =DEGREES(ACOS(SIN(M$5)*SIN($C$6)+COS(M$5)*COS($C$6)*COS($B17))) -> 115.02248 | M17: =90-L17 -> -25.022483 | N17: =DEGREES(-ACOS((SIN(RADIANS(M17))*SIN($C$6)-SIN(M$5))/(COS(RADIANS(M17))*COS($C$6)))) -> -95.927044 | O17: =DEGREES(ACOS(SIN(P$5)*SIN($C$6)+COS(P$5)*COS($C$6)*COS($B17))) -> 122.07039 | P17: =90-O17 -> -32.070394 | Q17: =DEGREES(-ACOS((SIN(RADIANS(P17))*SIN($C$6)-SIN(P$5))/(COS(RADIANS(P17))*COS($C$6)))) -> -85.243654 | R17: =DEGREES(ACOS(SIN(S$5)*SIN($C$6)+COS(S$5)*COS($C$6)*COS($B17))) -> 115.69269 | S17: =90-R17 -> -25.692695 | T17: =DEGREES(-ACOS((SIN(RADIANS(S17))*SIN($C$6)-SIN(S$5))/(COS(RADIANS(S17))*COS($C$6)))) -> -95.016977
A18: -112 | B18: =RADIANS(A18) -> -1.9547688 | C18: =DEGREES(ACOS(SIN(C$5)*SIN($C$6)+COS(C$5)*COS($C$6)*COS($B18))) -> 90.191271 | D18: =90-C18 -> -0.1912707 | E18: =DEGREES(-ACOS((SIN(RADIANS(D18))*SIN($C$6)-SIN(C$5))/(COS(RADIANS(D18))*COS($C$6)))) -> -121.72188 | F18: =DEGREES(ACOS(SIN(G$5)*SIN($C$6)+COS(G$5)*COS($C$6)*COS($B18))) -> 98.46903 | G18: =90-F18 -> -8.4690298 | H18: =DEGREES(-ACOS((SIN(RADIANS(G18))*SIN($C$6)-SIN(G$5))/(COS(RADIANS(G18))*COS($C$6)))) -> -113.38681 | I18: =DEGREES(ACOS(SIN(J$5)*SIN($C$6)+COS(J$5)*COS($C$6)*COS($B18))) -> 106.56275 | J18: =90-I18 -> -16.562751 | K18: =DEGREES(-ACOS((SIN(RADIANS(J18))*SIN($C$6)-SIN(J$5))/(COS(RADIANS(J18))*COS($C$6)))) -> -104.68825 | L18: =DEGREES(ACOS(SIN(M$5)*SIN($C$6)+COS(M$5)*COS($C$6)*COS($B18))) -> 114.26513 | M18: =90-L18 -> -24.265128 | N18: =DEGREES(-ACOS((SIN(RADIANS(M18))*SIN($C$6)-SIN(M$5))/(COS(RADIANS(M18))*COS($C$6)))) -> -95.24427 | O18: =DEGREES(ACOS(SIN(P$5)*SIN($C$6)+COS(P$5)*COS($C$6)*COS($B18))) -> 121.31239 | P18: =90-O18 -> -31.312391 | Q18: =DEGREES(-ACOS((SIN(RADIANS(P18))*SIN($C$6)-SIN(P$5))/(COS(RADIANS(P18))*COS($C$6)))) -> -84.636299 | R18: =DEGREES(ACOS(SIN(S$5)*SIN($C$6)+COS(S$5)*COS($C$6)*COS($B18))) -> 114.93426 | S18: =90-R18 -> -24.934261 | T18: =DEGREES(-ACOS((SIN(RADIANS(S18))*SIN($C$6)-SIN(S$5))/(COS(RADIANS(S18))*COS($C$6)))) -> -94.338829
A19: -111 | B19: =RADIANS(A19) -> -1.9373155 | C19: =DEGREES(ACOS(SIN(C$5)*SIN($C$6)+COS(C$5)*COS($C$6)*COS($B19))) -> 89.541729 | D19: =90-C19 -> 0.45827124 | E19: =DEGREES(-ACOS((SIN(RADIANS(D19))*SIN($C$6)-SIN(C$5))/(COS(RADIANS(D19))*COS($C$6)))) -> -121.07401 | F19: =DEGREES(ACOS(SIN(G$5)*SIN($C$6)+COS(G$5)*COS($C$6)*COS($B19))) -> 97.768767 | G19: =90-F19 -> -7.7687669 | H19: =DEGREES(-ACOS((SIN(RADIANS(G19))*SIN($C$6)-SIN(G$5))/(COS(RADIANS(G19))*COS($C$6)))) -> -112.69553 | I19: =DEGREES(ACOS(SIN(J$5)*SIN($C$6)+COS(J$5)*COS($C$6)*COS($B19))) -> 105.82548 | J19: =90-I19 -> -15.82548 | K19: =DEGREES(-ACOS((SIN(RADIANS(J19))*SIN($C$6)-SIN(J$5))/(COS(RADIANS(J19))*COS($C$6)))) -> -103.98473 | L19: =DEGREES(ACOS(SIN(M$5)*SIN($C$6)+COS(M$5)*COS($C$6)*COS($B19))) -> 113.50695 | M19: =90-L19 -> -23.506947 | N19: =DEGREES(-ACOS((SIN(RADIANS(M19))*SIN($C$6)-SIN(M$5))/(COS(RADIANS(M19))*COS($C$6)))) -> -94.566659 | O19: =DEGREES(ACOS(SIN(P$5)*SIN($C$6)+COS(P$5)*COS($C$6)*COS($B19))) -> 120.55514 | P19: =90-O19 -> -30.555139 | Q19: =DEGREES(-ACOS((SIN(RADIANS(P19))*SIN($C$6)-SIN(P$5))/(COS(RADIANS(P19))*COS($C$6)))) -> -84.032527 | R19: =DEGREES(ACOS(SIN(S$5)*SIN($C$6)+COS(S$5)*COS($C$6)*COS($B19))) -> 114.17515 | S19: =90-R19 -> -24.175148 | T19: =DEGREES(-ACOS((SIN(RADIANS(S19))*SIN($C$6)-SIN(S$5))/(COS(RADIANS(S19))*COS($C$6)))) -> -93.665769
A20: -110 | B20: =RADIANS(A20) -> -1.9198622 | C20: =DEGREES(ACOS(SIN(C$5)*SIN($C$6)+COS(C$5)*COS($C$6)*COS($B20))) -> 88.887761 | D20: =90-C20 -> 1.1122393 | E20: =DEGREES(-ACOS((SIN(RADIANS(D20))*SIN($C$6)-SIN(C$5))/(COS(RADIANS(D20))*COS($C$6)))) -> -120.43055 | F20: =DEGREES(ACOS(SIN(G$5)*SIN($C$6)+COS(G$5)*COS($C$6)*COS($B20))) -> 97.064974 | G20: =90-F20 -> -7.0649739 | H20: =DEGREES(-ACOS((SIN(RADIANS(G20))*SIN($C$6)-SIN(G$5))/(COS(RADIANS(G20))*COS($C$6)))) -> -112.00906 | I20: =DEGREES(ACOS(SIN(J$5)*SIN($C$6)+COS(J$5)*COS($C$6)*COS($B20))) -> 105.08596 | J20: =90-I20 -> -15.085959 | K20: =DEGREES(-ACOS((SIN(RADIANS(J20))*SIN($C$6)-SIN(J$5))/(COS(RADIANS(J20))*COS($C$6)))) -> -103.28633 | L20: =DEGREES(ACOS(SIN(M$5)*SIN($C$6)+COS(M$5)*COS($C$6)*COS($B20))) -> 112.74805 | M20: =90-L20 -> -22.748051 | N20: =DEGREES(-ACOS((SIN(RADIANS(M20))*SIN($C$6)-SIN(M$5))/(COS(RADIANS(M20))*COS($C$6)))) -> -93.893891 | O20: =DEGREES(ACOS(SIN(P$5)*SIN($C$6)+COS(P$5)*COS($C$6)*COS($B20))) -> 119.79872 | P20: =90-O20 -> -29.798719 | Q20: =DEGREES(-ACOS((SIN(RADIANS(P20))*SIN($C$6)-SIN(P$5))/(COS(RADIANS(P20))*COS($C$6)))) -> -83.432042 | R20: =DEGREES(ACOS(SIN(S$5)*SIN($C$6)+COS(S$5)*COS($C$6)*COS($B20))) -> 113.41547 | S20: =90-R20 -> -23.415466 | T20: =DEGREES(-ACOS((SIN(RADIANS(S20))*SIN($C$6)-SIN(S$5))/(COS(RADIANS(S20))*COS($C$6)))) -> -92.997474
A21: -109 | B21: =RADIANS(A21) -> -1.9024089 | C21: =DEGREES(ACOS(SIN(C$5)*SIN($C$6)+COS(C$5)*COS($C$6)*COS($B21))) -> 88.229478 | D21: =90-C21 -> 1.7705216 | E21: =DEGREES(-ACOS((SIN(RADIANS(D21))*SIN($C$6)-SIN(C$5))/(COS(RADIANS(D21))*COS($C$6)))) -> -119.79137 | F21: =DEGREES(ACOS(SIN(G$5)*SIN($C$6)+COS(G$5)*COS($C$6)*COS($B21))) -> 96.357776 | G21: =90-F21 -> -6.3577756 | H21: =DEGREES(-ACOS((SIN(RADIANS(G21))*SIN($C$6)-SIN(G$5))/(COS(RADIANS(G21))*COS($C$6)))) -> -111.32721 | I21: =DEGREES(ACOS(SIN(J$5)*SIN($C$6)+COS(J$5)*COS($C$6)*COS($B21))) -> 104.34431 | J21: =90-I21 -> -14.344313 | K21: =DEGREES(-ACOS((SIN(RADIANS(J21))*SIN($C$6)-SIN(J$5))/(COS(RADIANS(J21))*COS($C$6)))) -> -102.59279 | L21: =DEGREES(ACOS(SIN(M$5)*SIN($C$6)+COS(M$5)*COS($C$6)*COS($B21))) -> 111.98855 | M21: =90-L21 -> -21.988551 | N21: =DEGREES(-ACOS((SIN(RADIANS(M21))*SIN($C$6)-SIN(M$5))/(COS(RADIANS(M21))*COS($C$6)))) -> -93.225653 | O21: =DEGREES(ACOS(SIN(P$5)*SIN($C$6)+COS(P$5)*COS($C$6)*COS($B21))) -> 119.04321 | P21: =90-O21 -> -29.043209 | Q21: =DEGREES(-ACOS((SIN(RADIANS(P21))*SIN($C$6)-SIN(P$5))/(COS(RADIANS(P21))*COS($C$6)))) -> -82.834558 | R21: =DEGREES(ACOS(SIN(S$5)*SIN($C$6)+COS(S$5)*COS($C$6)*COS($B21))) -> 112.65532 | S21: =90-R21 -> -22.655321 | T21: =DEGREES(-ACOS((SIN(RADIANS(S21))*SIN($C$6)-SIN(S$5))/(COS(RADIANS(S21))*COS($C$6)))) -> -92.333633
A22: -108 | B22: =RADIANS(A22) -> -1.8849556 | C22: =DEGREES(ACOS(SIN(C$5)*SIN($C$6)+COS(C$5)*COS($C$6)*COS($B22))) -> 87.566992 | D22: =90-C22 -> 2.4330082 | E22: =DEGREES(-ACOS((SIN(RADIANS(D22))*SIN($C$6)-SIN(C$5))/(COS(RADIANS(D22))*COS($C$6)))) -> -119.15631 | F22: =DEGREES(ACOS(SIN(G$5)*SIN($C$6)+COS(G$5)*COS($C$6)*COS($B22))) -> 95.647294 | G22: =90-F22 -> -5.6472942 | H22: =DEGREES(-ACOS((SIN(RADIANS(G22))*SIN($C$6)-SIN(G$5))/(COS(RADIANS(G22))*COS($C$6)))) -> -110.64975 | I22: =DEGREES(ACOS(SIN(J$5)*SIN($C$6)+COS(J$5)*COS($C$6)*COS($B22))) -> 103.60067 | J22: =90-I22 -> -13.600666 | K22: =DEGREES(-ACOS((SIN(RADIANS(J22))*SIN($C$6)-SIN(J$5))/(COS(RADIANS(J22))*COS($C$6)))) -> -101.90382 | L22: =DEGREES(ACOS(SIN(M$5)*SIN($C$6)+COS(M$5)*COS($C$6)*COS($B22))) -> 111.22855 | M22: =90-L22 -> -21.228553 | N22: =DEGREES(-ACOS((SIN(RADIANS(M22))*SIN($C$6)-SIN(M$5))/(COS(RADIANS(M22))*COS($C$6)))) -> -92.561642 | O22: =DEGREES(ACOS(SIN(P$5)*SIN($C$6)+COS(P$5)*COS($C$6)*COS($B22))) -> 118.28869 | P22: =90-O22 -> -28.288687 | Q22: =DEGREES(-ACOS((SIN(RADIANS(P22))*SIN($C$6)-SIN(P$5))/(COS(RADIANS(P22))*COS($C$6)))) -> -82.239801 | R22: =DEGREES(ACOS(SIN(S$5)*SIN($C$6)+COS(S$5)*COS($C$6)*COS($B22))) -> 111.89482 | S22: =90-R22 -> -21.894818 | T22: =DEGREES(-ACOS((SIN(RADIANS(S22))*SIN($C$6)-SIN(S$5))/(COS(RADIANS(S22))*COS($C$6)))) -> -91.67394
A23: -107 | B23: =RADIANS(A23) -> -1.8675023 | C23: =DEGREES(ACOS(SIN(C$5)*SIN($C$6)+COS(C$5)*COS($C$6)*COS($B23))) -> 86.900409 | D23: =90-C23 -> 3.099591 | E23: =DEGREES(-ACOS((SIN(RADIANS(D23))*SIN($C$6)-SIN(C$5))/(COS(RADIANS(D23))*COS($C$6)))) -> -118.52526 | F23: =DEGREES(ACOS(SIN(G$5)*SIN($C$6)+COS(G$5)*COS($C$6)*COS($B23))) -> 94.93365 | G23: =90-F23 -> -4.9336497 | H23: =DEGREES(-ACOS((SIN(RADIANS(G23))*SIN($C$6)-SIN(G$5))/(COS(RADIANS(G23))*COS($C$6)))) -> -109.9765 | I23: =DEGREES(ACOS(SIN(J$5)*SIN($C$6)+COS(J$5)*COS($C$6)*COS($B23))) -> 102.85514 | J23: =90-I23 -> -12.855137 | K23: =DEGREES(-ACOS((SIN(RADIANS(J23))*SIN($C$6)-SIN(J$5))/(COS(RADIANS(J23))*COS($C$6)))) -> -101.21918 | L23: =DEGREES(ACOS(SIN(M$5)*SIN($C$6)+COS(M$5)*COS($C$6)*COS($B23))) -> 110.46816 | M23: =90-L23 -> -20.468162 | N23: =DEGREES(-ACOS((SIN(RADIANS(M23))*SIN($C$6)-SIN(M$5))/(COS(RADIANS(M23))*COS($C$6)))) -> -91.901564 | O23: =DEGREES(ACOS(SIN(P$5)*SIN($C$6)+COS(P$5)*COS($C$6)*COS($B23))) -> 117.53523 | P23: =90-O23 -> -27.535228 | Q23: =DEGREES(-ACOS((SIN(RADIANS(P23))*SIN($C$6)-SIN(P$5))/(COS(RADIANS(P23))*COS($C$6)))) -> -81.647503 | R23: =DEGREES(ACOS(SIN(S$5)*SIN($C$6)+COS(S$5)*COS($C$6)*COS($B23))) -> 111.13406 | S23: =90-R23 -> -21.13406 | T23: =DEGREES(-ACOS((SIN(RADIANS(S23))*SIN($C$6)-SIN(S$5))/(COS(RADIANS(S23))*COS($C$6)))) -> -91.018099
A24: -106 | B24: =RADIANS(A24) -> -1.850049 | C24: =DEGREES(ACOS(SIN(C$5)*SIN($C$6)+COS(C$5)*COS($C$6)*COS($B24))) -> 86.229836 | D24: =90-C24 -> 3.7701641 | E24: =DEGREES(-ACOS((SIN(RADIANS(D24))*SIN($C$6)-SIN(C$5))/(COS(RADIANS(D24))*COS($C$6)))) -> -117.89805 | F24: =DEGREES(ACOS(SIN(G$5)*SIN($C$6)+COS(G$5)*COS($C$6)*COS($B24))) -> 94.216959 | G24: =90-F24 -> -4.2169592 | H24: =DEGREES(-ACOS((SIN(RADIANS(G24))*SIN($C$6)-SIN(G$5))/(COS(RADIANS(G24))*COS($C$6)))) -> -109.30723 | I24: =DEGREES(ACOS(SIN(J$5)*SIN($C$6)+COS(J$5)*COS($C$6)*COS($B24))) -> 102.10784 | J24: =90-I24 -> -12.107844 | K24: =DEGREES(-ACOS((SIN(RADIANS(J24))*SIN($C$6)-SIN(J$5))/(COS(RADIANS(J24))*COS($C$6)))) -> -100.5386 | L24: =DEGREES(ACOS(SIN(M$5)*SIN($C$6)+COS(M$5)*COS($C$6)*COS($B24))) -> 109.70748 | M24: =90-L24 -> -19.70748 | N24: =DEGREES(-ACOS((SIN(RADIANS(M24))*SIN($C$6)-SIN(M$5))/(COS(RADIANS(M24))*COS($C$6)))) -> -91.245129 | O24: =DEGREES(ACOS(SIN(P$5)*SIN($C$6)+COS(P$5)*COS($C$6)*COS($B24))) -> 116.78291 | P24: =90-O24 -> -26.78291 | Q24: =DEGREES(-ACOS((SIN(RADIANS(P24))*SIN($C$6)-SIN(P$5))/(COS(RADIANS(P24))*COS($C$6)))) -> -81.057409 | R24: =DEGREES(ACOS(SIN(S$5)*SIN($C$6)+COS(S$5)*COS($C$6)*COS($B24))) -> 110.37315 | S24: =90-R24 -> -20.373147 | T24: =DEGREES(-ACOS((SIN(RADIANS(S24))*SIN($C$6)-SIN(S$5))/(COS(RADIANS(S24))*COS($C$6)))) -> -90.365823
A25: -105 | B25: =RADIANS(A25) -> -1.8325957 | C25: =DEGREES(ACOS(SIN(C$5)*SIN($C$6)+COS(C$5)*COS($C$6)*COS($B25))) -> 85.555377 | D25: =90-C25 -> 4.4446233 | E25: =DEGREES(-ACOS((SIN(RADIANS(D25))*SIN($C$6)-SIN(C$5))/(COS(RADIANS(D25))*COS($C$6)))) -> -117.27457 | F25: =DEGREES(ACOS(SIN(G$5)*SIN($C$6)+COS(G$5)*COS($C$6)*COS($B25))) -> 93.497338 | G25: =90-F25 -> -3.4973382 | H25: =DEGREES(-ACOS((SIN(RADIANS(G25))*SIN($C$6)-SIN(G$5))/(COS(RADIANS(G25))*COS($C$6)))) -> -108.64176 | I25: =DEGREES(ACOS(SIN(J$5)*SIN($C$6)+COS(J$5)*COS($C$6)*COS($B25))) -> 101.3589 | J25: =90-I25 -> -11.358903 | K25: =DEGREES(-ACOS((SIN(RADIANS(J25))*SIN($C$6)-SIN(J$5))/(COS(RADIANS(J25))*COS($C$6)))) -> -99.861812 | L25: =DEGREES(ACOS(SIN(M$5)*SIN($C$6)+COS(M$5)*COS($C$6)*COS($B25))) -> 108.94661 | M25: =90-L25 -> -18.94661 | N25: =DEGREES(-ACOS((SIN(RADIANS(M25))*SIN($C$6)-SIN(M$5))/(COS(RADIANS(M25))*COS($C$6)))) -> -90.592057 | O25: =DEGREES(ACOS(SIN(P$5)*SIN($C$6)+COS(P$5)*COS($C$6)*COS($B25))) -> 116.03181 | P25: =90-O25 -> -26.031808 | Q25: =DEGREES(-ACOS((SIN(RADIANS(P25))*SIN($C$6)-SIN(P$5))/(COS(RADIANS(P25))*COS($C$6)))) -> -80.469269 | R25: =DEGREES(ACOS(SIN(S$5)*SIN($C$6)+COS(S$5)*COS($C$6)*COS($B25))) -> 109.61218 | S25: =90-R25 -> -19.612179 | T25: =DEGREES(-ACOS((SIN(RADIANS(S25))*SIN($C$6)-SIN(S$5))/(COS(RADIANS(S25))*COS($C$6)))) -> -89.71683 | V25: =E25 -> -117.27457 | X25: =D25 -> 4.4446233
A26: -104 | B26: =RADIANS(A26) -> -1.8151424 | C26: =DEGREES(ACOS(SIN(C$5)*SIN($C$6)+COS(C$5)*COS($C$6)*COS($B26))) -> 84.877134 | D26: =90-C26 -> 5.1228664 | E26: =DEGREES(-ACOS((SIN(RADIANS(D26))*SIN($C$6)-SIN(C$5))/(COS(RADIANS(D26))*COS($C$6)))) -> -116.65465 | F26: =DEGREES(ACOS(SIN(G$5)*SIN($C$6)+COS(G$5)*COS($C$6)*COS($B26))) -> 92.774899 | G26: =90-F26 -> -2.7748995 | H26: =DEGREES(-ACOS((SIN(RADIANS(G26))*SIN($C$6)-SIN(G$5))/(COS(RADIANS(G26))*COS($C$6)))) -> -107.97986 | I26: =DEGREES(ACOS(SIN(J$5)*SIN($C$6)+COS(J$5)*COS($C$6)*COS($B26))) -> 100.60843 | J26: =90-I26 -> -10.608425 | K26: =DEGREES(-ACOS((SIN(RADIANS(J26))*SIN($C$6)-SIN(J$5))/(COS(RADIANS(J26))*COS($C$6)))) -> -99.188577 | L26: =DEGREES(ACOS(SIN(M$5)*SIN($C$6)+COS(M$5)*COS($C$6)*COS($B26))) -> 108.18565 | M26: =90-L26 -> -18.18565 | N26: =DEGREES(-ACOS((SIN(RADIANS(M26))*SIN($C$6)-SIN(M$5))/(COS(RADIANS(M26))*COS($C$6)))) -> -89.942071 | O26: =DEGREES(ACOS(SIN(P$5)*SIN($C$6)+COS(P$5)*COS($C$6)*COS($B26))) -> 115.282 | P26: =90-O26 -> -25.281998 | Q26: =DEGREES(-ACOS((SIN(RADIANS(P26))*SIN($C$6)-SIN(P$5))/(COS(RADIANS(P26))*COS($C$6)))) -> -79.882842 | R26: =DEGREES(ACOS(SIN(S$5)*SIN($C$6)+COS(S$5)*COS($C$6)*COS($B26))) -> 108.85125 | S26: =90-R26 -> -18.851253 | T26: =DEGREES(-ACOS((SIN(RADIANS(S26))*SIN($C$6)-SIN(S$5))/(COS(RADIANS(S26))*COS($C$6)))) -> -89.070844 | V26: =H25 -> -108.64176 | X26: =G25 -> -3.4973382
A27: -103 | B27: =RADIANS(A27) -> -1.7976891 | C27: =DEGREES(ACOS(SIN(C$5)*SIN($C$6)+COS(C$5)*COS($C$6)*COS($B27))) -> 84.195207 | D27: =90-C27 -> 5.804793 | E27: =DEGREES(-ACOS((SIN(RADIANS(D27))*SIN($C$6)-SIN(C$5))/(COS(RADIANS(D27))*COS($C$6)))) -> -116.03816 | F27: =DEGREES(ACOS(SIN(G$5)*SIN($C$6)+COS(G$5)*COS($C$6)*COS($B27))) -> 92.049754 | G27: =90-F27 -> -2.0497541 | H27: =DEGREES(-ACOS((SIN(RADIANS(G27))*SIN($C$6)-SIN(G$5))/(COS(RADIANS(G27))*COS($C$6)))) -> -107.32135 | I27: =DEGREES(ACOS(SIN(J$5)*SIN($C$6)+COS(J$5)*COS($C$6)*COS($B27))) -> 99.856524 | J27: =90-I27 -> -9.8565239 | K27: =DEGREES(-ACOS((SIN(RADIANS(J27))*SIN($C$6)-SIN(J$5))/(COS(RADIANS(J27))*COS($C$6)))) -> -98.518641 | L27: =DEGREES(ACOS(SIN(M$5)*SIN($C$6)+COS(M$5)*COS($C$6)*COS($B27))) -> 107.4247 | M27: =90-L27 -> -17.424698 | N27: =DEGREES(-ACOS((SIN(RADIANS(M27))*SIN($C$6)-SIN(M$5))/(COS(RADIANS(M27))*COS($C$6)))) -> -89.294905 | O27: =DEGREES(ACOS(SIN(P$5)*SIN($C$6)+COS(P$5)*COS($C$6)*COS($B27))) -> 114.53355 | P27: =90-O27 -> -24.533554 | Q27: =DEGREES(-ACOS((SIN(RADIANS(P27))*SIN($C$6)-SIN(P$5))/(COS(RADIANS(P27))*COS($C$6)))) -> -79.297895 | R27: =DEGREES(ACOS(SIN(S$5)*SIN($C$6)+COS(S$5)*COS($C$6)*COS($B27))) -> 108.09047 | S27: =90-R27 -> -18.090466 | T27: =DEGREES(-ACOS((SIN(RADIANS(S27))*SIN($C$6)-SIN(S$5))/(COS(RADIANS(S27))*COS($C$6)))) -> -88.427599 | V27: =K25 -> -99.861812 | X27: =J25 -> -11.358903
A28: -102 | B28: =RADIANS(A28) -> -1.7802358 | C28: =DEGREES(ACOS(SIN(C$5)*SIN($C$6)+COS(C$5)*COS($C$6)*COS($B28))) -> 83.509696 | D28: =90-C28 -> 6.4903041 | E28: =DEGREES(-ACOS((SIN(RADIANS(D28))*SIN($C$6)-SIN(C$5))/(COS(RADIANS(D28))*COS($C$6)))) -> -115.42495 | F28: =DEGREES(ACOS(SIN(G$5)*SIN($C$6)+COS(G$5)*COS($C$6)*COS($B28))) -> 91.322011 | G28: =90-F28 -> -1.322011 | H28: =DEGREES(-ACOS((SIN(RADIANS(G28))*SIN($C$6)-SIN(G$5))/(COS(RADIANS(G28))*COS($C$6)))) -> -106.66601 | I28: =DEGREES(ACOS(SIN(J$5)*SIN($C$6)+COS(J$5)*COS($C$6)*COS($B28))) -> 99.103307 | J28: =90-I28 -> -9.1033073 | K28: =DEGREES(-ACOS((SIN(RADIANS(J28))*SIN($C$6)-SIN(J$5))/(COS(RADIANS(J28))*COS($C$6)))) -> -97.851756 | L28: =DEGREES(ACOS(SIN(M$5)*SIN($C$6)+COS(M$5)*COS($C$6)*COS($B28))) -> 106.66385 | M28: =90-L28 -> -16.663852 | N28: =DEGREES(-ACOS((SIN(RADIANS(M28))*SIN($C$6)-SIN(M$5))/(COS(RADIANS(M28))*COS($C$6)))) -> -88.650294 | O28: =DEGREES(ACOS(SIN(P$5)*SIN($C$6)+COS(P$5)*COS($C$6)*COS($B28))) -> 113.78655 | P28: =90-O28 -> -23.786551 | Q28: =DEGREES(-ACOS((SIN(RADIANS(P28))*SIN($C$6)-SIN(P$5))/(COS(RADIANS(P28))*COS($C$6)))) -> -78.714201 | R28: =DEGREES(ACOS(SIN(S$5)*SIN($C$6)+COS(S$5)*COS($C$6)*COS($B28))) -> 107.32991 | S28: =90-R28 -> -17.329913 | T28: =DEGREES(-ACOS((SIN(RADIANS(S28))*SIN($C$6)-SIN(S$5))/(COS(RADIANS(S28))*COS($C$6)))) -> -87.786832 | V28: =N25 -> -90.592057 | X28: =M25 -> -18.94661
A29: -101 | B29: =RADIANS(A29) -> -1.7627825 | C29: =DEGREES(ACOS(SIN(C$5)*SIN($C$6)+COS(C$5)*COS($C$6)*COS($B29))) -> 82.820697 | D29: =90-C29 -> 7.179303 | E29: =DEGREES(-ACOS((SIN(RADIANS(D29))*SIN($C$6)-SIN(C$5))/(COS(RADIANS(D29))*COS($C$6)))) -> -114.81488 | F29: =DEGREES(ACOS(SIN(G$5)*SIN($C$6)+COS(G$5)*COS($C$6)*COS($B29))) -> 90.591777 | G29: =90-F29 -> -0.59177727 | H29: =DEGREES(-ACOS((SIN(RADIANS(G29))*SIN($C$6)-SIN(G$5))/(COS(RADIANS(G29))*COS($C$6)))) -> -106.01364 | I29: =DEGREES(ACOS(SIN(J$5)*SIN($C$6)+COS(J$5)*COS($C$6)*COS($B29))) -> 98.348883 | J29: =90-I29 -> -8.3488832 | K29: =DEGREES(-ACOS((SIN(RADIANS(J29))*SIN($C$6)-SIN(J$5))/(COS(RADIANS(J29))*COS($C$6)))) -> -97.187677 | L29: =DEGREES(ACOS(SIN(M$5)*SIN($C$6)+COS(M$5)*COS($C$6)*COS($B29))) -> 105.90321 | M29: =90-L29 -> -15.903207 | N29: =DEGREES(-ACOS((SIN(RADIANS(M29))*SIN($C$6)-SIN(M$5))/(COS(RADIANS(M29))*COS($C$6)))) -> -88.007982 | O29: =DEGREES(ACOS(SIN(P$5)*SIN($C$6)+COS(P$5)*COS($C$6)*COS($B29))) -> 113.04106 | P29: =90-O29 -> -23.041063 | Q29: =DEGREES(-ACOS((SIN(RADIANS(P29))*SIN($C$6)-SIN(P$5))/(COS(RADIANS(P29))*COS($C$6)))) -> -78.131538 | R29: =DEGREES(ACOS(SIN(S$5)*SIN($C$6)+COS(S$5)*COS($C$6)*COS($B29))) -> 106.56969 | S29: =90-R29 -> -16.569687 | T29: =DEGREES(-ACOS((SIN(RADIANS(S29))*SIN($C$6)-SIN(S$5))/(COS(RADIANS(S29))*COS($C$6)))) -> -87.148286 | V29: =Q25 -> -80.469269 | X29: =P25 -> -26.031808
A30: -100 | B30: =RADIANS(A30) -> -1.7453293 | C30: =DEGREES(ACOS(SIN(C$5)*SIN($C$6)+COS(C$5)*COS($C$6)*COS($B30))) -> 82.128306 | D30: =90-C30 -> 7.8716941 | E30: =DEGREES(-ACOS((SIN(RADIANS(D30))*SIN($C$6)-SIN(C$5))/(COS(RADIANS(D30))*COS($C$6)))) -> -114.20779 | F30: =DEGREES(ACOS(SIN(G$5)*SIN($C$6)+COS(G$5)*COS($C$6)*COS($B30))) -> 89.859158 | G30: =90-F30 -> 0.14084158 | H30: =DEGREES(-ACOS((SIN(RADIANS(G30))*SIN($C$6)-SIN(G$5))/(COS(RADIANS(G30))*COS($C$6)))) -> -105.36404 | I30: =DEGREES(ACOS(SIN(J$5)*SIN($C$6)+COS(J$5)*COS($C$6)*COS($B30))) -> 97.593358 | J30: =90-I30 -> -7.5933575 | K30: =DEGREES(-ACOS((SIN(RADIANS(J30))*SIN($C$6)-SIN(J$5))/(COS(RADIANS(J30))*COS($C$6)))) -> -96.526161 | L30: =DEGREES(ACOS(SIN(M$5)*SIN($C$6)+COS(M$5)*COS($C$6)*COS($B30))) -> 105.14286 | M30: =90-L30 -> -15.142859 | N30: =DEGREES(-ACOS((SIN(RADIANS(M30))*SIN($C$6)-SIN(M$5))/(COS(RADIANS(M30))*COS($C$6)))) -> -87.367716 | O30: =DEGREES(ACOS(SIN(P$5)*SIN($C$6)+COS(P$5)*COS($C$6)*COS($B30))) -> 112.29717 | P30: =90-O30 -> -22.297166 | Q30: =DEGREES(-ACOS((SIN(RADIANS(P30))*SIN($C$6)-SIN(P$5))/(COS(RADIANS(P30))*COS($C$6)))) -> -77.549692 | R30: =DEGREES(ACOS(SIN(S$5)*SIN($C$6)+COS(S$5)*COS($C$6)*COS($B30))) -> 105.80988 | S30: =90-R30 -> -15.809883 | T30: =DEGREES(-ACOS((SIN(RADIANS(S30))*SIN($C$6)-SIN(S$5))/(COS(RADIANS(S30))*COS($C$6)))) -> -86.511709
A31: -99 | B31: =RADIANS(A31) -> -1.727876 | C31: =DEGREES(ACOS(SIN(C$5)*SIN($C$6)+COS(C$5)*COS($C$6)*COS($B31))) -> 81.432616 | D31: =90-C31 -> 8.5673837 | E31: =DEGREES(-ACOS((SIN(RADIANS(D31))*SIN($C$6)-SIN(C$5))/(COS(RADIANS(D31))*COS($C$6)))) -> -113.60354 | F31: =DEGREES(ACOS(SIN(G$5)*SIN($C$6)+COS(G$5)*COS($C$6)*COS($B31))) -> 89.124258 | G31: =90-F31 -> 0.87574184 | H31: =DEGREES(-ACOS((SIN(RADIANS(G31))*SIN($C$6)-SIN(G$5))/(COS(RADIANS(G31))*COS($C$6)))) -> -104.71699 | I31: =DEGREES(ACOS(SIN(J$5)*SIN($C$6)+COS(J$5)*COS($C$6)*COS($B31))) -> 96.836835 | J31: =90-I31 -> -6.8368351 | K31: =DEGREES(-ACOS((SIN(RADIANS(J31))*SIN($C$6)-SIN(J$5))/(COS(RADIANS(J31))*COS($C$6)))) -> -95.866969 | L31: =DEGREES(ACOS(SIN(M$5)*SIN($C$6)+COS(M$5)*COS($C$6)*COS($B31))) -> 104.3829 | M31: =90-L31 -> -14.3829 | N31: =DEGREES(-ACOS((SIN(RADIANS(M31))*SIN($C$6)-SIN(M$5))/(COS(RADIANS(M31))*COS($C$6)))) -> -86.729248 | O31: =DEGREES(ACOS(SIN(P$5)*SIN($C$6)+COS(P$5)*COS($C$6)*COS($B31))) -> 111.55493 | P31: =90-O31 -> -21.554934 | Q31: =DEGREES(-ACOS((SIN(RADIANS(P31))*SIN($C$6)-SIN(P$5))/(COS(RADIANS(P31))*COS($C$6)))) -> -76.968454 | R31: =DEGREES(ACOS(SIN(S$5)*SIN($C$6)+COS(S$5)*COS($C$6)*COS($B31))) -> 105.05059 | S31: =90-R31 -> -15.050593 | T31: =DEGREES(-ACOS((SIN(RADIANS(S31))*SIN($C$6)-SIN(S$5))/(COS(RADIANS(S31))*COS($C$6)))) -> -85.876857
A32: -98 | B32: =RADIANS(A32) -> -1.7104227 | C32: =DEGREES(ACOS(SIN(C$5)*SIN($C$6)+COS(C$5)*COS($C$6)*COS($B32))) -> 80.733721 | D32: =90-C32 -> 9.2662795 | E32: =DEGREES(-ACOS((SIN(RADIANS(D32))*SIN($C$6)-SIN(C$5))/(COS(RADIANS(D32))*COS($C$6)))) -> -113.00198 | F32: =DEGREES(ACOS(SIN(G$5)*SIN($C$6)+COS(G$5)*COS($C$6)*COS($B32))) -> 88.387179 | G32: =90-F32 -> 1.6128213 | H32: =DEGREES(-ACOS((SIN(RADIANS(G32))*SIN($C$6)-SIN(G$5))/(COS(RADIANS(G32))*COS($C$6)))) -> -104.07231 | I32: =DEGREES(ACOS(SIN(J$5)*SIN($C$6)+COS(J$5)*COS($C$6)*COS($B32))) -> 96.079419 | J32: =90-I32 -> -6.079419 | K32: =DEGREES(-ACOS((SIN(RADIANS(J32))*SIN($C$6)-SIN(J$5))/(COS(RADIANS(J32))*COS($C$6)))) -> -95.209862 | L32: =DEGREES(ACOS(SIN(M$5)*SIN($C$6)+COS(M$5)*COS($C$6)*COS($B32))) -> 103.62342 | M32: =90-L32 -> -13.623424 | N32: =DEGREES(-ACOS((SIN(RADIANS(M32))*SIN($C$6)-SIN(M$5))/(COS(RADIANS(M32))*COS($C$6)))) -> -86.092334 | O32: =DEGREES(ACOS(SIN(P$5)*SIN($C$6)+COS(P$5)*COS($C$6)*COS($B32))) -> 110.81444 | P32: =90-O32 -> -20.814442 | Q32: =DEGREES(-ACOS((SIN(RADIANS(P32))*SIN($C$6)-SIN(P$5))/(COS(RADIANS(P32))*COS($C$6)))) -> -76.387618 | R32: =DEGREES(ACOS(SIN(S$5)*SIN($C$6)+COS(S$5)*COS($C$6)*COS($B32))) -> 104.29191 | S32: =90-R32 -> -14.291908 | T32: =DEGREES(-ACOS((SIN(RADIANS(S32))*SIN($C$6)-SIN(S$5))/(COS(RADIANS(S32))*COS($C$6)))) -> -85.243486
A33: -97 | B33: =RADIANS(A33) -> -1.6929694 | C33: =DEGREES(ACOS(SIN(C$5)*SIN($C$6)+COS(C$5)*COS($C$6)*COS($B33))) -> 80.031709 | D33: =90-C33 -> 9.9682907 | E33: =DEGREES(-ACOS((SIN(RADIANS(D33))*SIN($C$6)-SIN(C$5))/(COS(RADIANS(D33))*COS($C$6)))) -> -112.40295 | F33: =DEGREES(ACOS(SIN(G$5)*SIN($C$6)+COS(G$5)*COS($C$6)*COS($B33))) -> 87.648021 | G33: =90-F33 -> 2.3519792 | H33: =DEGREES(-ACOS((SIN(RADIANS(G33))*SIN($C$6)-SIN(G$5))/(COS(RADIANS(G33))*COS($C$6)))) -> -103.42978 | I33: =DEGREES(ACOS(SIN(J$5)*SIN($C$6)+COS(J$5)*COS($C$6)*COS($B33))) -> 95.321212 | J33: =90-I33 -> -5.3212116 | K33: =DEGREES(-ACOS((SIN(RADIANS(J33))*SIN($C$6)-SIN(J$5))/(COS(RADIANS(J33))*COS($C$6)))) -> -94.554603 | L33: =DEGREES(ACOS(SIN(M$5)*SIN($C$6)+COS(M$5)*COS($C$6)*COS($B33))) -> 102.86452 | M33: =90-L33 -> -12.864524 | N33: =DEGREES(-ACOS((SIN(RADIANS(M33))*SIN($C$6)-SIN(M$5))/(COS(RADIANS(M33))*COS($C$6)))) -> -85.456737 | O33: =DEGREES(ACOS(SIN(P$5)*SIN($C$6)+COS(P$5)*COS($C$6)*COS($B33))) -> 110.07577 | P33: =90-O33 -> -20.075766 | Q33: =DEGREES(-ACOS((SIN(RADIANS(P33))*SIN($C$6)-SIN(P$5))/(COS(RADIANS(P33))*COS($C$6)))) -> -75.806987 | R33: =DEGREES(ACOS(SIN(S$5)*SIN($C$6)+COS(S$5)*COS($C$6)*COS($B33))) -> 103.53392 | S33: =90-R33 -> -13.53392 | T33: =DEGREES(-ACOS((SIN(RADIANS(S33))*SIN($C$6)-SIN(S$5))/(COS(RADIANS(S33))*COS($C$6)))) -> -84.611359
A34: -96 | B34: =RADIANS(A34) -> -1.6755161 | C34: =DEGREES(ACOS(SIN(C$5)*SIN($C$6)+COS(C$5)*COS($C$6)*COS($B34))) -> 79.326672 | D34: =90-C34 -> 10.673328 | E34: =DEGREES(-ACOS((SIN(RADIANS(D34))*SIN($C$6)-SIN(C$5))/(COS(RADIANS(D34))*COS($C$6)))) -> -111.8063 | F34: =DEGREES(ACOS(SIN(G$5)*SIN($C$6)+COS(G$5)*COS($C$6)*COS($B34))) -> 86.906884 | G34: =90-F34 -> 3.0931161 | H34: =DEGREES(-ACOS((SIN(RADIANS(G34))*SIN($C$6)-SIN(G$5))/(COS(RADIANS(G34))*COS($C$6)))) -> -102.78919 | I34: =DEGREES(ACOS(SIN(J$5)*SIN($C$6)+COS(J$5)*COS($C$6)*COS($B34))) -> 94.562314 | J34: =90-I34 -> -4.5623139 | K34: =DEGREES(-ACOS((SIN(RADIANS(J34))*SIN($C$6)-SIN(J$5))/(COS(RADIANS(J34))*COS($C$6)))) -> -93.900959 | L34: =DEGREES(ACOS(SIN(M$5)*SIN($C$6)+COS(M$5)*COS($C$6)*COS($B34))) -> 102.10629 | M34: =90-L34 -> -12.106292 | N34: =DEGREES(-ACOS((SIN(RADIANS(M34))*SIN($C$6)-SIN(M$5))/(COS(RADIANS(M34))*COS($C$6)))) -> -84.822221 | O34: =DEGREES(ACOS(SIN(P$5)*SIN($C$6)+COS(P$5)*COS($C$6)*COS($B34))) -> 109.33898 | P34: =90-O34 -> -19.33898 | Q34: =DEGREES(-ACOS((SIN(RADIANS(P34))*SIN($C$6)-SIN(P$5))/(COS(RADIANS(P34))*COS($C$6)))) -> -75.226366 | R34: =DEGREES(ACOS(SIN(S$5)*SIN($C$6)+COS(S$5)*COS($C$6)*COS($B34))) -> 102.77672 | S34: =90-R34 -> -12.77672 | T34: =DEGREES(-ACOS((SIN(RADIANS(S34))*SIN($C$6)-SIN(S$5))/(COS(RADIANS(S34))*COS($C$6)))) -> -83.980244
A35: -95 | B35: =RADIANS(A35) -> -1.6580628 | C35: =DEGREES(ACOS(SIN(C$5)*SIN($C$6)+COS(C$5)*COS($C$6)*COS($B35))) -> 78.618696 | D35: =90-C35 -> 11.381304 | E35: =DEGREES(-ACOS((SIN(RADIANS(D35))*SIN($C$6)-SIN(C$5))/(COS(RADIANS(D35))*COS($C$6)))) -> -111.21188 | F35: =DEGREES(ACOS(SIN(G$5)*SIN($C$6)+COS(G$5)*COS($C$6)*COS($B35))) -> 86.163866 | G35: =90-F35 -> 3.8361338 | H35: =DEGREES(-ACOS((SIN(RADIANS(G35))*SIN($C$6)-SIN(G$5))/(COS(RADIANS(G35))*COS($C$6)))) -> -102.15035 | I35: =DEGREES(ACOS(SIN(J$5)*SIN($C$6)+COS(J$5)*COS($C$6)*COS($B35))) -> 93.802826 | J35: =90-I35 -> -3.8028261 | K35: =DEGREES(-ACOS((SIN(RADIANS(J35))*SIN($C$6)-SIN(J$5))/(COS(RADIANS(J35))*COS($C$6)))) -> -93.248695 | L35: =DEGREES(ACOS(SIN(M$5)*SIN($C$6)+COS(M$5)*COS($C$6)*COS($B35))) -> 101.34882 | M35: =90-L35 -> -11.34882 | N35: =DEGREES(-ACOS((SIN(RADIANS(M35))*SIN($C$6)-SIN(M$5))/(COS(RADIANS(M35))*COS($C$6)))) -> -84.188553 | O35: =DEGREES(ACOS(SIN(P$5)*SIN($C$6)+COS(P$5)*COS($C$6)*COS($B35))) -> 108.60416 | P35: =90-O35 -> -18.604161 | Q35: =DEGREES(-ACOS((SIN(RADIANS(P35))*SIN($C$6)-SIN(P$5))/(COS(RADIANS(P35))*COS($C$6)))) -> -74.645562 | R35: =DEGREES(ACOS(SIN(S$5)*SIN($C$6)+COS(S$5)*COS($C$6)*COS($B35))) -> 102.0204 | S35: =90-R35 -> -12.020398 | T35: =DEGREES(-ACOS((SIN(RADIANS(S35))*SIN($C$6)-SIN(S$5))/(COS(RADIANS(S35))*COS($C$6)))) -> -83.349909
A36: -94 | B36: =RADIANS(A36) -> -1.6406095 | C36: =DEGREES(ACOS(SIN(C$5)*SIN($C$6)+COS(C$5)*COS($C$6)*COS($B36))) -> 77.907869 | D36: =90-C36 -> 12.092131 | E36: =DEGREES(-ACOS((SIN(RADIANS(D36))*SIN($C$6)-SIN(C$5))/(COS(RADIANS(D36))*COS($C$6)))) -> -110.61953 | F36: =DEGREES(ACOS(SIN(G$5)*SIN($C$6)+COS(G$5)*COS($C$6)*COS($B36))) -> 85.419065 | G36: =90-F36 -> 4.5809352 | H36: =DEGREES(-ACOS((SIN(RADIANS(G36))*SIN($C$6)-SIN(G$5))/(COS(RADIANS(G36))*COS($C$6)))) -> -101.51303 | I36: =DEGREES(ACOS(SIN(J$5)*SIN($C$6)+COS(J$5)*COS($C$6)*COS($B36))) -> 93.042848 | J36: =90-I36 -> -3.0428479 | K36: =DEGREES(-ACOS((SIN(RADIANS(J36))*SIN($C$6)-SIN(J$5))/(COS(RADIANS(J36))*COS($C$6)))) -> -92.59758 | L36: =DEGREES(ACOS(SIN(M$5)*SIN($C$6)+COS(M$5)*COS($C$6)*COS($B36))) -> 100.5922 | M36: =90-L36 -> -10.5922 | N36: =DEGREES(-ACOS((SIN(RADIANS(M36))*SIN($C$6)-SIN(M$5))/(COS(RADIANS(M36))*COS($C$6)))) -> -83.555506 | O36: =DEGREES(ACOS(SIN(P$5)*SIN($C$6)+COS(P$5)*COS($C$6)*COS($B36))) -> 107.87138 | P36: =90-O36 -> -17.871384 | Q36: =DEGREES(-ACOS((SIN(RADIANS(P36))*SIN($C$6)-SIN(P$5))/(COS(RADIANS(P36))*COS($C$6)))) -> -74.064391 | R36: =DEGREES(ACOS(SIN(S$5)*SIN($C$6)+COS(S$5)*COS($C$6)*COS($B36))) -> 101.26504 | S36: =90-R36 -> -11.265045 | T36: =DEGREES(-ACOS((SIN(RADIANS(S36))*SIN($C$6)-SIN(S$5))/(COS(RADIANS(S36))*COS($C$6)))) -> -82.720129
A37: -93 | B37: =RADIANS(A37) -> -1.6231562 | C37: =DEGREES(ACOS(SIN(C$5)*SIN($C$6)+COS(C$5)*COS($C$6)*COS($B37))) -> 77.194276 | D37: =90-C37 -> 12.805724 | E37: =DEGREES(-ACOS((SIN(RADIANS(D37))*SIN($C$6)-SIN(C$5))/(COS(RADIANS(D37))*COS($C$6)))) -> -110.02909 | F37: =DEGREES(ACOS(SIN(G$5)*SIN($C$6)+COS(G$5)*COS($C$6)*COS($B37))) -> 84.672576 | G37: =90-F37 -> 5.3274242 | H37: =DEGREES(-ACOS((SIN(RADIANS(G37))*SIN($C$6)-SIN(G$5))/(COS(RADIANS(G37))*COS($C$6)))) -> -100.87705 | I37: =DEGREES(ACOS(SIN(J$5)*SIN($C$6)+COS(J$5)*COS($C$6)*COS($B37))) -> 92.282478 | J37: =90-I37 -> -2.282478 | K37: =DEGREES(-ACOS((SIN(RADIANS(J37))*SIN($C$6)-SIN(J$5))/(COS(RADIANS(J37))*COS($C$6)))) -> -91.947383 | L37: =DEGREES(ACOS(SIN(M$5)*SIN($C$6)+COS(M$5)*COS($C$6)*COS($B37))) -> 99.836523 | M37: =90-L37 -> -9.8365227 | N37: =DEGREES(-ACOS((SIN(RADIANS(M37))*SIN($C$6)-SIN(M$5))/(COS(RADIANS(M37))*COS($C$6)))) -> -82.922855 | O37: =DEGREES(ACOS(SIN(P$5)*SIN($C$6)+COS(P$5)*COS($C$6)*COS($B37))) -> 107.14073 | P37: =90-O37 -> -17.140729 | Q37: =DEGREES(-ACOS((SIN(RADIANS(P37))*SIN($C$6)-SIN(P$5))/(COS(RADIANS(P37))*COS($C$6)))) -> -73.482668 | R37: =DEGREES(ACOS(SIN(S$5)*SIN($C$6)+COS(S$5)*COS($C$6)*COS($B37))) -> 100.51075 | S37: =90-R37 -> -10.510751 | T37: =DEGREES(-ACOS((SIN(RADIANS(S37))*SIN($C$6)-SIN(S$5))/(COS(RADIANS(S37))*COS($C$6)))) -> -82.090681
A38: -92 | B38: =RADIANS(A38) -> -1.6057029 | C38: =DEGREES(ACOS(SIN(C$5)*SIN($C$6)+COS(C$5)*COS($C$6)*COS($B38))) -> 76.478001 | D38: =90-C38 -> 13.521999 | E38: =DEGREES(-ACOS((SIN(RADIANS(D38))*SIN($C$6)-SIN(C$5))/(COS(RADIANS(D38))*COS($C$6)))) -> -109.44039 | F38: =DEGREES(ACOS(SIN(G$5)*SIN($C$6)+COS(G$5)*COS($C$6)*COS($B38))) -> 83.924494 | G38: =90-F38 -> 6.0755058 | H38: =DEGREES(-ACOS((SIN(RADIANS(G38))*SIN($C$6)-SIN(G$5))/(COS(RADIANS(G38))*COS($C$6)))) -> -100.24218 | I38: =DEGREES(ACOS(SIN(J$5)*SIN($C$6)+COS(J$5)*COS($C$6)*COS($B38))) -> 91.521815 | J38: =90-I38 -> -1.5218147 | K38: =DEGREES(-ACOS((SIN(RADIANS(J38))*SIN($C$6)-SIN(J$5))/(COS(RADIANS(J38))*COS($C$6)))) -> -91.297874 | L38: =DEGREES(ACOS(SIN(M$5)*SIN($C$6)+COS(M$5)*COS($C$6)*COS($B38))) -> 99.081881 | M38: =90-L38 -> -9.0818808 | N38: =DEGREES(-ACOS((SIN(RADIANS(M38))*SIN($C$6)-SIN(M$5))/(COS(RADIANS(M38))*COS($C$6)))) -> -82.290376 | O38: =DEGREES(ACOS(SIN(P$5)*SIN($C$6)+COS(P$5)*COS($C$6)*COS($B38))) -> 106.41227 | P38: =90-O38 -> -16.412271 | Q38: =DEGREES(-ACOS((SIN(RADIANS(P38))*SIN($C$6)-SIN(P$5))/(COS(RADIANS(P38))*COS($C$6)))) -> -72.900215 | R38: =DEGREES(ACOS(SIN(S$5)*SIN($C$6)+COS(S$5)*COS($C$6)*COS($B38))) -> 99.757608 | S38: =90-R38 -> -9.7576083 | T38: =DEGREES(-ACOS((SIN(RADIANS(S38))*SIN($C$6)-SIN(S$5))/(COS(RADIANS(S38))*COS($C$6)))) -> -81.461343
A39: -91 | B39: =RADIANS(A39) -> -1.5882496 | C39: =DEGREES(ACOS(SIN(C$5)*SIN($C$6)+COS(C$5)*COS($C$6)*COS($B39))) -> 75.759128 | D39: =90-C39 -> 14.240872 | E39: =DEGREES(-ACOS((SIN(RADIANS(D39))*SIN($C$6)-SIN(C$5))/(COS(RADIANS(D39))*COS($C$6)))) -> -108.85328 | F39: =DEGREES(ACOS(SIN(G$5)*SIN($C$6)+COS(G$5)*COS($C$6)*COS($B39))) -> 83.174914 | G39: =90-F39 -> 6.8250856 | H39: =DEGREES(-ACOS((SIN(RADIANS(G39))*SIN($C$6)-SIN(G$5))/(COS(RADIANS(G39))*COS($C$6)))) -> -99.608211 | I39: =DEGREES(ACOS(SIN(J$5)*SIN($C$6)+COS(J$5)*COS($C$6)*COS($B39))) -> 90.760956 | J39: =90-I39 -> -0.76095616 | K39: =DEGREES(-ACOS((SIN(RADIANS(J39))*SIN($C$6)-SIN(J$5))/(COS(RADIANS(J39))*COS($C$6)))) -> -90.648822 | L39: =DEGREES(ACOS(SIN(M$5)*SIN($C$6)+COS(M$5)*COS($C$6)*COS($B39))) -> 98.328366 | M39: =90-L39 -> -8.3283658 | N39: =DEGREES(-ACOS((SIN(RADIANS(M39))*SIN($C$6)-SIN(M$5))/(COS(RADIANS(M39))*COS($C$6)))) -> -81.65785 | O39: =DEGREES(ACOS(SIN(P$5)*SIN($C$6)+COS(P$5)*COS($C$6)*COS($B39))) -> 105.68609 | P39: =90-O39 -> -15.686089 | Q39: =DEGREES(-ACOS((SIN(RADIANS(P39))*SIN($C$6)-SIN(P$5))/(COS(RADIANS(P39))*COS($C$6)))) -> -72.316854 | R39: =DEGREES(ACOS(SIN(S$5)*SIN($C$6)+COS(S$5)*COS($C$6)*COS($B39))) -> 99.005706 | S39: =90-R39 -> -9.0057063 | T39: =DEGREES(-ACOS((SIN(RADIANS(S39))*SIN($C$6)-SIN(S$5))/(COS(RADIANS(S39))*COS($C$6)))) -> -80.8319
A40: -90 | B40: =RADIANS(A40) -> -1.5707963 | C40: =DEGREES(ACOS(SIN(C$5)*SIN($C$6)+COS(C$5)*COS($C$6)*COS($B40))) -> 75.037737 | D40: =90-C40 -> 14.962263 | E40: =DEGREES(-ACOS((SIN(RADIANS(D40))*SIN($C$6)-SIN(C$5))/(COS(RADIANS(D40))*COS($C$6)))) -> -108.26759 | F40: =DEGREES(ACOS(SIN(G$5)*SIN($C$6)+COS(G$5)*COS($C$6)*COS($B40))) -> 82.42393 | G40: =90-F40 -> 7.5760699 | H40: =DEGREES(-ACOS((SIN(RADIANS(G40))*SIN($C$6)-SIN(G$5))/(COS(RADIANS(G40))*COS($C$6)))) -> -98.97494 | I40: =DEGREES(ACOS(SIN(J$5)*SIN($C$6)+COS(J$5)*COS($C$6)*COS($B40))) -> 90 | J40: =90-I40 -> 0 | K40: =DEGREES(-ACOS((SIN(RADIANS(J40))*SIN($C$6)-SIN(J$5))/(COS(RADIANS(J40))*COS($C$6)))) -> -90 | L40: =DEGREES(ACOS(SIN(M$5)*SIN($C$6)+COS(M$5)*COS($C$6)*COS($B40))) -> 97.57607 | M40: =90-L40 -> -7.5760699 | N40: =DEGREES(-ACOS((SIN(RADIANS(M40))*SIN($C$6)-SIN(M$5))/(COS(RADIANS(M40))*COS($C$6)))) -> -81.02506 | O40: =DEGREES(ACOS(SIN(P$5)*SIN($C$6)+COS(P$5)*COS($C$6)*COS($B40))) -> 104.96226 | P40: =90-O40 -> -14.962263 | Q40: =DEGREES(-ACOS((SIN(RADIANS(P40))*SIN($C$6)-SIN(P$5))/(COS(RADIANS(P40))*COS($C$6)))) -> -71.732413 | R40: =DEGREES(ACOS(SIN(S$5)*SIN($C$6)+COS(S$5)*COS($C$6)*COS($B40))) -> 98.255137 | S40: =90-R40 -> -8.2551365 | T40: =DEGREES(-ACOS((SIN(RADIANS(S40))*SIN($C$6)-SIN(S$5))/(COS(RADIANS(S40))*COS($C$6)))) -> -80.202136 | V40: =E40 -> -108.26759 | Y40: =D40 -> 14.962263
A41: -89 | B41: =RADIANS(A41) -> -1.553343 | C41: =DEGREES(ACOS(SIN(C$5)*SIN($C$6)+COS(C$5)*COS($C$6)*COS($B41))) -> 74.313911 | D41: =90-C41 -> 15.686089 | E41: =DEGREES(-ACOS((SIN(RADIANS(D41))*SIN($C$6)-SIN(C$5))/(COS(RADIANS(D41))*COS($C$6)))) -> -107.68315 | F41: =DEGREES(ACOS(SIN(G$5)*SIN($C$6)+COS(G$5)*COS($C$6)*COS($B41))) -> 81.671634 | G41: =90-F41 -> 8.3283658 | H41: =DEGREES(-ACOS((SIN(RADIANS(G41))*SIN($C$6)-SIN(G$5))/(COS(RADIANS(G41))*COS($C$6)))) -> -98.34215 | I41: =DEGREES(ACOS(SIN(J$5)*SIN($C$6)+COS(J$5)*COS($C$6)*COS($B41))) -> 89.239044 | J41: =90-I41 -> 0.76095616 | K41: =DEGREES(-ACOS((SIN(RADIANS(J41))*SIN($C$6)-SIN(J$5))/(COS(RADIANS(J41))*COS($C$6)))) -> -89.351178 | L41: =DEGREES(ACOS(SIN(M$5)*SIN($C$6)+COS(M$5)*COS($C$6)*COS($B41))) -> 96.825086 | M41: =90-L41 -> -6.8250856 | N41: =DEGREES(-ACOS((SIN(RADIANS(M41))*SIN($C$6)-SIN(M$5))/(COS(RADIANS(M41))*COS($C$6)))) -> -80.391789 | O41: =DEGREES(ACOS(SIN(P$5)*SIN($C$6)+COS(P$5)*COS($C$6)*COS($B41))) -> 104.24087 | P41: =90-O41 -> -14.240872 | Q41: =DEGREES(-ACOS((SIN(RADIANS(P41))*SIN($C$6)-SIN(P$5))/(COS(RADIANS(P41))*COS($C$6)))) -> -71.146721 | R41: =DEGREES(ACOS(SIN(S$5)*SIN($C$6)+COS(S$5)*COS($C$6)*COS($B41))) -> 97.505991 | S41: =90-R41 -> -7.5059908 | T41: =DEGREES(-ACOS((SIN(RADIANS(S41))*SIN($C$6)-SIN(S$5))/(COS(RADIANS(S41))*COS($C$6)))) -> -79.571837 | V41: =H40 -> -98.97494 | Y41: =G40 -> 7.5760699
A42: -88 | B42: =RADIANS(A42) -> -1.5358897 | C42: =DEGREES(ACOS(SIN(C$5)*SIN($C$6)+COS(C$5)*COS($C$6)*COS($B42))) -> 73.587729 | D42: =90-C42 -> 16.412271 | E42: =DEGREES(-ACOS((SIN(RADIANS(D42))*SIN($C$6)-SIN(C$5))/(COS(RADIANS(D42))*COS($C$6)))) -> -107.09979 | F42: =DEGREES(ACOS(SIN(G$5)*SIN($C$6)+COS(G$5)*COS($C$6)*COS($B42))) -> 80.918119 | G42: =90-F42 -> 9.0818808 | H42: =DEGREES(-ACOS((SIN(RADIANS(G42))*SIN($C$6)-SIN(G$5))/(COS(RADIANS(G42))*COS($C$6)))) -> -97.709624 | I42: =DEGREES(ACOS(SIN(J$5)*SIN($C$6)+COS(J$5)*COS($C$6)*COS($B42))) -> 88.478185 | J42: =90-I42 -> 1.5218147 | K42: =DEGREES(-ACOS((SIN(RADIANS(J42))*SIN($C$6)-SIN(J$5))/(COS(RADIANS(J42))*COS($C$6)))) -> -88.702126 | L42: =DEGREES(ACOS(SIN(M$5)*SIN($C$6)+COS(M$5)*COS($C$6)*COS($B42))) -> 96.075506 | M42: =90-L42 -> -6.0755058 | N42: =DEGREES(-ACOS((SIN(RADIANS(M42))*SIN($C$6)-SIN(M$5))/(COS(RADIANS(M42))*COS($C$6)))) -> -79.757824 | O42: =DEGREES(ACOS(SIN(P$5)*SIN($C$6)+COS(P$5)*COS($C$6)*COS($B42))) -> 103.522 | P42: =90-O42 -> -13.521999 | Q42: =DEGREES(-ACOS((SIN(RADIANS(P42))*SIN($C$6)-SIN(P$5))/(COS(RADIANS(P42))*COS($C$6)))) -> -70.55961 | R42: =DEGREES(ACOS(SIN(S$5)*SIN($C$6)+COS(S$5)*COS($C$6)*COS($B42))) -> 96.758361 | S42: =90-R42 -> -6.7583611 | T42: =DEGREES(-ACOS((SIN(RADIANS(S42))*SIN($C$6)-SIN(S$5))/(COS(RADIANS(S42))*COS($C$6)))) -> -78.940794 | V42: =K40 -> -90 | Y42: =J40 -> 0
...

Sheet Ej-2b_Munich
C3: S.Junio | I3: Equinocios | O3: S.Diciembre | R3: Día, dn= | S3: ='Ej-2a_TraySol_Mad'!S3 -> 297
C4: (rad) | F4: (º) | G4: (rad) | L4: (º) | M4: (rad) | O4: (º) | P4: (rad) | R4: (º) | S4: (rad)
A5: Declinación (º): | B5: 23.45 | C5: =RADIANS(B5) -> 0.40927971 | F5: =B5/2 -> 11.725 | G5: =RADIANS(F5) -> 0.20463985 | I5: 0 | J5: =RADIANS(I5) -> 0 | L5: =-F5 -> -11.725 | M5: =RADIANS(L5) -> -0.20463985 | O5: =-B5 -> -23.45 | P5: =RADIANS(O5) -> -0.40927971 | R5: =IF(S3<>"",23.45*SIN(RADIANS(360*(S3+284)/365)),"") -> -12.785888 | S5: =RADIANS(R5) -> -0.22315585 | W5: 1 | X5: 17 | Z5: 7 | AA5: 198
A6: Latitud (º): | B6: 48.133333 | C6: =RADIANS(B6) -> 0.84008515 | W6: 2 | X6: 46 | Z6: 8 | AA6: 228
A7: 8.14 | D7: SVER | J7: EQUI | P7: SINV
D8: Elevación | E8: Acimut | W8: =A10 -> -120 | X8: =A25 -> -105 | Y8: =A40 -> -90 | Z8: =A55 -> -75 | AA8: =A70 -> -60 | AB8: =A85 -> -45 | AC8: =A100 -> -30 | AD8: =A115 -> -15 | AE8: =A131 -> 0.001 | AF8: =A146 -> 15 | AG8: =A161 -> 30 | AH8: =A176 -> 45 | AI8: =A191 -> 60 | AJ8: =A206 -> 75 | AK8: =A221 -> 90 | AL8: =A236 -> 105 | AM8: =A251 -> 120
A9: w (º) | B9: w (rad) | C9: JZS (º) | D9: gS (º) | E9: yS (º) | F9: JZS (º) | G9: gS (º) | H9: yS (º) | I9: JZS (º) | J9: gS (º) | K9: yS (º) | L9: JZS (º) | M9: gS (º) | N9: yS (º) | O9: JZS (º) | P9: gS (º) | Q9: yS (º) | R9: JZS (º) | S9: gS (º) | T9: yS (º) | V9: yS | W9: w = -8 | X9: w = -7 | Y9: w = -6 | Z9: w = -5 | AA9: w = -4 | AB9: w = -3 | AC9: w = -2 | AD9: w = -1 | AE9: w = 0 | AF9: w = 1 | AG9: w = 2 | AH9: w = 3 | AI9: w = 4 | AJ9: w = 5 | AK9: w = 6 | AL9: w = 7 | AM9: w = 8
A10: -120 | B10: =RADIANS(A10) -> -2.0943951 | C10: =DEGREES(ACOS(SIN(C$5)*SIN($C$6)+COS(C$5)*COS($C$6)*COS($B10))) -> 90.560726 | D10: =90-C10 -> -0.56072593 | E10: =DEGREES(-ACOS((SIN(RADIANS(D10))*SIN($C$6)-SIN(C$5))/(COS(RADIANS(D10))*COS($C$6)))) -> -127.38851 | F10: =DEGREES(ACOS(SIN(G$5)*SIN($C$6)+COS(G$5)*COS($C$6)*COS($B10))) -> 100.10211 | G10: =90-F10 -> -10.102108 | H10: =DEGREES(-ACOS((SIN(RADIANS(G10))*SIN($C$6)-SIN(G$5))/(COS(RADIANS(G10))*COS($C$6)))) -> -120.53621 | I10: =DEGREES(ACOS(SIN(J$5)*SIN($C$6)+COS(J$5)*COS($C$6)*COS($B10))) -> 109.49349 | J10: =90-I10 -> -19.493487 | K10: =DEGREES(-ACOS((SIN(RADIANS(J10))*SIN($C$6)-SIN(J$5))/(COS(RADIANS(J10))*COS($C$6)))) -> -113.26542 | L10: =DEGREES(ACOS(SIN(M$5)*SIN($C$6)+COS(M$5)*COS($C$6)*COS($B10))) -> 118.55947 | M10: =90-L10 -> -28.55947 | N10: =DEGREES(-ACOS((SIN(RADIANS(M10))*SIN($C$6)-SIN(M$5))/(COS(RADIANS(M10))*COS($C$6)))) -> -105.11004 | O10: =DEGREES(ACOS(SIN(P$5)*SIN($C$6)+COS(P$5)*COS($C$6)*COS($B10))) -> 127.04851 | P10: =90-O10 -> -37.048512 | Q10: =DEGREES(-ACOS((SIN(RADIANS(P10))*SIN($C$6)-SIN(P$5))/(COS(RADIANS(P10))*COS($C$6)))) -> -95.464597 | R10: =DEGREES(ACOS(SIN(S$5)*SIN($C$6)+COS(S$5)*COS($C$6)*COS($B10))) -> 119.35593 | S10: =90-R10 -> -29.355933 | T10: =DEGREES(-ACOS((SIN(RADIANS(S10))*SIN($C$6)-SIN(S$5))/(COS(RADIANS(S10))*COS($C$6)))) -> -104.30909 | V10: =E10 -> -127.38851 | W10: =D10 -> -0.56072593
A11: -119 | B11: =RADIANS(A11) -> -2.0769418 | C11: =DEGREES(ACOS(SIN(C$5)*SIN($C$6)+COS(C$5)*COS($C$6)*COS($B11))) -> 90.027825 | D11: =90-C11 -> -0.027824648 | E11: =DEGREES(-ACOS((SIN(RADIANS(D11))*SIN($C$6)-SIN(C$5))/(COS(RADIANS(D11))*COS($C$6)))) -> -126.64174 | F11: =DEGREES(ACOS(SIN(G$5)*SIN($C$6)+COS(G$5)*COS($C$6)*COS($B11))) -> 99.524913 | G11: =90-F11 -> -9.5249128 | H11: =DEGREES(-ACOS((SIN(RADIANS(G11))*SIN($C$6)-SIN(G$5))/(COS(RADIANS(G11))*COS($C$6)))) -> -119.73355 | I11: =DEGREES(ACOS(SIN(J$5)*SIN($C$6)+COS(J$5)*COS($C$6)*COS($B11))) -> 108.87846 | J11: =90-I11 -> -18.878456 | K11: =DEGREES(-ACOS((SIN(RADIANS(J11))*SIN($C$6)-SIN(J$5))/(COS(RADIANS(J11))*COS($C$6)))) -> -112.43054 | L11: =DEGREES(ACOS(SIN(M$5)*SIN($C$6)+COS(M$5)*COS($C$6)*COS($B11))) -> 117.9139 | M11: =90-L11 -> -27.913897 | N11: =DEGREES(-ACOS((SIN(RADIANS(M11))*SIN($C$6)-SIN(M$5))/(COS(RADIANS(M11))*COS($C$6)))) -> -104.27443 | O11: =DEGREES(ACOS(SIN(P$5)*SIN($C$6)+COS(P$5)*COS($C$6)*COS($B11))) -> 126.38373 | P11: =90-O11 -> -36.383729 | Q11: =DEGREES(-ACOS((SIN(RADIANS(P11))*SIN($C$6)-SIN(P$5))/(COS(RADIANS(P11))*COS($C$6)))) -> -94.675898 | R11: =DEGREES(ACOS(SIN(S$5)*SIN($C$6)+COS(S$5)*COS($C$6)*COS($B11))) -> 118.70806 | S11: =90-R11 -> -28.70806 | T11: =DEGREES(-ACOS((SIN(RADIANS(S11))*SIN($C$6)-SIN(S$5))/(COS(RADIANS(S11))*COS($C$6)))) -> -103.47544 | V11: =H10 -> -120.53621 | W11: =G11 -> -9.5249128
A12: -118 | B12: =RADIANS(A12) -> -2.0594885 | C12: =DEGREES(ACOS(SIN(C$5)*SIN($C$6)+COS(C$5)*COS($C$6)*COS($B12))) -> 89.489745 | D12: =90-C12 -> 0.5102551 | E12: =DEGREES(-ACOS((SIN(RADIANS(D12))*SIN($C$6)-SIN(C$5))/(COS(RADIANS(D12))*COS($C$6)))) -> -125.89869 | F12: =DEGREES(ACOS(SIN(G$5)*SIN($C$6)+COS(G$5)*COS($C$6)*COS($B12))) -> 98.943094 | G12: =90-F12 -> -8.9430942 | H12: =DEGREES(-ACOS((SIN(RADIANS(G12))*SIN($C$6)-SIN(G$5))/(COS(RADIANS(G12))*COS($C$6)))) -> -118.93568 | I12: =DEGREES(ACOS(SIN(J$5)*SIN($C$6)+COS(J$5)*COS($C$6)*COS($B12))) -> 108.25973 | J12: =90-I12 -> -18.259728 | K12: =DEGREES(-ACOS((SIN(RADIANS(J12))*SIN($C$6)-SIN(J$5))/(COS(RADIANS(J12))*COS($C$6)))) -> -111.60178 | L12: =DEGREES(ACOS(SIN(M$5)*SIN($C$6)+COS(M$5)*COS($C$6)*COS($B12))) -> 117.26593 | M12: =90-L12 -> -27.265934 | N12: =DEGREES(-ACOS((SIN(RADIANS(M12))*SIN($C$6)-SIN(M$5))/(COS(RADIANS(M12))*COS($C$6)))) -> -103.44618 | O12: =DEGREES(ACOS(SIN(P$5)*SIN($C$6)+COS(P$5)*COS($C$6)*COS($B12))) -> 125.7182 | P12: =90-O12 -> -35.7182 | Q12: =DEGREES(-ACOS((SIN(RADIANS(P12))*SIN($C$6)-SIN(P$5))/(COS(RADIANS(P12))*COS($C$6)))) -> -93.894888 | R12: =DEGREES(ACOS(SIN(S$5)*SIN($C$6)+COS(S$5)*COS($C$6)*COS($B12))) -> 118.05793 | S12: =90-R12 -> -28.057934 | T12: =DEGREES(-ACOS((SIN(RADIANS(S12))*SIN($C$6)-SIN(S$5))/(COS(RADIANS(S12))*COS($C$6)))) -> -102.64923 | V12: =K10 -> -113.26542 | W12: =J10 -> -19.493487
