Workbook
Name AL: #REF!
Name AL: #REF!
Name AL: #REF!
Name AL: #REF!
Name AL: #REF!
Name BE: Datos_ejercicios!#REF!
Name BE: #REF!
Name BE: #REF!
Name BE: #REF!
Name BE: Gdm!#REF!
Name BE: Gdm!#REF!
Name BEOP: #REF!
Name BEOP: #REF!
Name BEOP: #REF!
Name BEOP: #REF!
Name BEOP: #REF!
Name beta: #REF!
Name beta: #REF!
Name beta: #REF!
Name beta: #REF!
Name BOP: #REF!
Name BOP: #REF!
Name BOP: #REF!
Name BOP: #REF!
Name decli1: #REF!
Name decli1: #REF!
Name decli1: #REF!
Name decli1: TraySol!$C$5
Name decli1: #REF!
Name Hp: #REF!
Name Hp: #REF!
Name Hp: #REF!
Name Hp: #REF!
Name Hvp: #REF!
Name Hvp: #REF!
Name Hvp: #REF!
Name Hvp: #REF!
Name l: #REF!
Name l: #REF!
Name l: #REF!
Name l: #REF!
Name LAT: [1]Ghm!$C$4
Name LAT: [2]Ghm!$C$3
Name LAT: [2]Ghm!$C$3
Name LAT: [3]Ghm!$C$3
Name LAT: Ghm!$C$4
Name lm: #REF!
Name lm: #REF!
Name lm: #REF!
Name lm: #REF!

Sheet Instrucciones
A1: 1) Busque datos de partida fiables de la localidad bajo estudio: latitud y promedios diarios de irradiación sobre superficie horizontal (unidades deseables, kWh/m2)
A3: 2) Copie los datos en la fila 3 de la pestaña "Gdm"
B4: Pueden utilizarse otros datos de partida (promedios diarios mensuales y anual) en la fila 4, siempre que tengan las unidades esperadas (kWh/m2)
A6: 3) En la pestaña "Gdm", indique los valores alfa y beta que determinan, respectivamente, la orientación e inclinación de la superficie de captación,así como el coeficiente de reflectividad del suelo, rho (r)
B7: Los resultados de irradiación global (promedios mensuales de valores diarios, promedio anual de valores diarios y valor anual) se muestran en la columna S
A9: Nota: La pestaña "Ghm" contiene los cálculos horarios cuya suma proporciona los valores diarios. No permite modificaciones.
B10: Modelo de irradiancia difusa: Modelo de Perez & Seals [Richard Perez, Robert Seals, "A new simplifed version of the Perez diffuse irradiance model for tilted surfaces". Solar Energy 39 (3), 1987]
A12: 4) La pestaña "TraySol" calcula y representa las trayectorias del sol en días característicos de la localidad seleccionada (diagrama de trayectorias del sol simplificado).
B13: (Se muestra asimismo un ejemplo del diagrama de trayectorias del sol en Madrid).
B14: Admite la representación de la trayectoria de un día específico, indicando en la casilla S3 el día escogido.
A16: 5) La pestaña "Tabla_FS" muestra la tabla de coeficientes en los que se basa el método de análisis de sombras: "pesos" energéticos de las zonas del hemisferio celeste
B17: (A1, A2,…D14), expresados en % respecto de la irradiación global anual incidente esperada (sin sombras) en la localidad y superficie de captación seleccionas.
B18: Incluye una representación del diagrama de trayectorias del sol simplificado en Madrid, para identificación de las zonas.
A20: 6) La pestaña "Pobs_H" calcula y representa el perfil de obstáculos que afecta al punto más desfavorable de filas de módulos fotovoltaicos paralelas sobre el plano horizontal,
B21: a partir de datos introducidos por el usuario (localidad seleccionada en el paso 1).
A23: 7) La pestaña "Pobs_V" calcula y representa el perfil de obstáculos que afecta al punto más desfavorable de hileras de módulos fotovoltaicos paralelas sobre el plano vertical,
B24: a partir de datos introducidos por el usuario (localidad seleccionada en el paso 1).
A26: 8) La pestaña "Psombras_ej" representa un perfil de obstáculos cualquiera, definido por por sus coordenadas acimut (y: columna A) y elevación (g: columna B),
B27: en el diagrama de trayectorias del sol de la localidad seleccionada en el paso 1.

Sheet Gdm
A1: * RESULTADOS: IRRADIACIÓN GLOBAL (PROMEDIOS DIARIOS MENSUALES Y VALOR ANUAL)
D3: Promedio diario mensual (kWh/m2)
A4: PAIS | B4: Localidad | C4: Latitud (º) | D4: Ene | E4: Feb | F4: Mar | G4: Abr | H4: May | I4: Jun | J4: Jul | K4: Ago | L4: Sep | M4: Oct | N4: Nov | O4: Dic
A5: ESPAÑA-AEMET | B5: Madrid | C5: 40.45 | D5: 2.27 | E5: 3.25 | F5: 4.65 | G5: 5.75 | H5: 6.6 | I5: 7.74 | J5: 8.04 | K5: 7 | L5: 5.47 | M5: 3.56 | N5: 2.43 | O5: 1.87
A7: Latitud, F (º) = | B7: =C5 -> 40.45
A8: Inclinación, b (º)= | B8: 65
A9: Orientación, a (º) = | B9: 0 | C9: (0º: sur; 180º: norte; valores < 0: sureste/noreste; valores >0: suroeste/noroeste)
A10: Coeficiente r = | B10: 0.2 | C10: Coeficiente de reflexión del suelo (0,2 por defecto)
D12: (º) | F12: (º) | G12: (º) | H12: (rad) | I12: (º) | J12: (Wh/m2) | K12: (Wh/m2) | N12: (Wh/m2) | O12: (Wh/m2) | P12: (Wh/m2) | Q12: (Wh/m2) | R12: (Wh/m2) | S12: (Wh/m2)
A13: Mes | B13: Dia | C13: Eps.o | D13: Declinac | F13: gs (w=0) | G13: gs (w=12h) | H13: ws | I13: ws | J13: Bodm(0) | K13: Gdm(0) | L13: Ktm | M13: Kdm | N13: Ddm(0) | O13: Bdm(0) | P13: Bdm(a,b) | Q13: Ddm(a,b) | R13: Rdm(a,b) | S13: Gdm(a,b) | V13: Gdm(a,b)-Gdm(0) [%Gdm(0)]
A14: 1 | B14: 17 | C14: =1+0.033*COS(RADIANS(360/365*B14)) -> 1.031597 | D14: =23.45*SIN(RADIANS(360/365*(B14+284))) -> -20.916963 | E14: =TAN(RADIANS($D14))*TAN(RADIANS(B$7)) -> -0.32585505 | F14: =90-ABS($B$7)+D14*SIGN($B$7) -> 28.633037 | G14: =D14*SIGN($B$7)-(90-ABS($B$7)) -> -70.466963 | H14: =IF(E14>=1,-PI(),IF(E14<-1,0,-ACOS(-E14))) -> -1.2388803 | I14: =H14*180/PI() -> -70.982614 | J14: =IF(E14>1,(24*1367/PI())*$C14*SIN(RADIANS(D14))*SIN(RADIANS(B$7))*PI(),(24*1367/PI())*$C14*COS(RADIANS(D14))*COS(RADIANS(B$7))*(H14*COS(H14)-SIN(H14))) -> 4148.3944 | K14: =D$5*1000 -> 2270 | L14: =IF(J14-K14>0,K14/J14,0) -> 0.54719966 | M14: =IF(L14<>0,1-1.13*L14,0) -> 0.38166439 | N14: =M14*K14 -> 866.37816 | O14: =K14-N14 -> 1403.6218 | P14: =Ghm!L47 -> 3449.7371 | Q14: =Ghm!Z47 -> 1512.7483 | R14: =Ghm!AA47 -> 130.35744 | S14: =SUM(P14:R14) -> 5092.8428 | V14: =IF(K14<>0,(S14-K14)/K14,0) -> 1.2435431
A15: 2 | B15: 46 | C15: =1+0.033*COS(RADIANS(360/365*B15)) -> 1.0231834 | D15: =23.45*SIN(RADIANS(360/365*(B15+284))) -> -13.289156 | E15: =TAN(RADIANS($D15))*TAN(RADIANS(B$7)) -> -0.20136925 | F15: =90-ABS($B$7)+D15*SIGN($B$7) -> 36.260844 | G15: =D15*SIGN($B$7)-(90-ABS($B$7)) -> -62.839156 | H15: =IF(E15>=1,-PI(),IF(E15<-1,0,-ACOS(-E15))) -> -1.3680407 | I15: =H15*180/PI() -> -78.38296 | J15: =IF(E15>1,(24*1367/PI())*$C15*SIN(RADIANS(D15))*SIN(RADIANS(B$7))*PI(),(24*1367/PI())*$C15*COS(RADIANS(D15))*COS(RADIANS(B$7))*(H15*COS(H15)-SIN(H15))) -> 5571.3195 | K15: =E$5*1000 -> 3250 | L15: =IF(J15-K15>0,K15/J15,0) -> 0.58334476 | M15: =1-1.13*L15 -> 0.34082043 | N15: =M15*K15 -> 1107.6664 | O15: =K15-N15 -> 2142.3336 | P15: =Ghm!L83 -> 3880.8572 | Q15: =Ghm!Z83 -> 1608.6464 | R15: =Ghm!AA83 -> 186.3205 | S15: =SUM(P15:R15) -> 5675.8241 | V15: =IF(K15<>0,(S15-K15)/K15,0) -> 0.74640742
A16: 3 | B16: 75 | C16: =1+0.033*COS(RADIANS(360/365*B16)) -> 1.0091112 | D16: =23.45*SIN(RADIANS(360/365*(B16+284))) -> -2.4177348 | E16: =TAN(RADIANS($D16))*TAN(RADIANS(B$7)) -> -0.035997743 | F16: =90-ABS($B$7)+D16*SIGN($B$7) -> 47.132265 | G16: =D16*SIGN($B$7)-(90-ABS($B$7)) -> -51.967735 | H16: =IF(E16>=1,-PI(),IF(E16<-1,0,-ACOS(-E16))) -> -1.5347908 | I16: =H16*180/PI() -> -87.937036 | J16: =IF(E16>1,(24*1367/PI())*$C16*SIN(RADIANS(D16))*SIN(RADIANS(B$7))*PI(),(24*1367/PI())*$C16*COS(RADIANS(D16))*COS(RADIANS(B$7))*(H16*COS(H16)-SIN(H16))) -> 7564.3284 | K16: =F$5*1000 -> 4650 | L16: =IF(J16-K16>0,K16/J16,0) -> 0.61472741 | M16: =1-1.13*L16 -> 0.30535803 | N16: =M16*K16 -> 1419.9148 | O16: =K16-N16 -> 3230.0852 | P16: =Ghm!L119 -> 4132.8512 | Q16: =Ghm!Z119 -> 1706.7705 | R16: =Ghm!AA119 -> 266.54638 | S16: =SUM(P16:R16) -> 6106.1681 | V16: =IF(K16<>0,(S16-K16)/K16,0) -> 0.31315444
A17: 4 | B17: 105 | C17: =1+0.033*COS(RADIANS(360/365*B17)) -> 0.99226178 | D17: =23.45*SIN(RADIANS(360/365*(B17+284))) -> 9.4148933 | E17: =TAN(RADIANS($D17))*TAN(RADIANS(B$7)) -> 0.14137017 | F17: =90-ABS($B$7)+D17*SIGN($B$7) -> 58.964893 | G17: =D17*SIGN($B$7)-(90-ABS($B$7)) -> -40.135107 | H17: =IF(E17>=1,-PI(),IF(E17<-1,0,-ACOS(-E17))) -> -1.7126417 | I17: =H17*180/PI() -> -98.12714 | J17: =IF(E17>1,(24*1367/PI())*$C17*SIN(RADIANS(D17))*SIN(RADIANS(B$7))*PI(),(24*1367/PI())*$C17*COS(RADIANS(D17))*COS(RADIANS(B$7))*(H17*COS(H17)-SIN(H17))) -> 9584.5506 | K17: =G$5*1000 -> 5750 | L17: =IF(J17-K17>0,K17/J17,0) -> 0.5999238 | M17: =1-1.13*L17 -> 0.32208611 | N17: =M17*K17 -> 1851.9951 | O17: =K17-N17 -> 3898.0049 | P17: =Ghm!L155 -> 3406.3171 | Q17: =Ghm!Z155 -> 1787.8705 | R17: =Ghm!AA155 -> 329.31597 | S17: =SUM(P17:R17) -> 5523.5036 | V17: =IF(K17<>0,(S17-K17)/K17,0) -> -0.039390682
A18: 5 | B18: 135 | C18: =1+0.033*COS(RADIANS(360/365*B18)) -> 0.97743066 | D18: =23.45*SIN(RADIANS(360/365*(B18+284))) -> 18.791918 | E18: =TAN(RADIANS($D18))*TAN(RADIANS(B$7)) -> 0.29010518 | F18: =90-ABS($B$7)+D18*SIGN($B$7) -> 68.341918 | G18: =D18*SIGN($B$7)-(90-ABS($B$7)) -> -30.758082 | H18: =IF(E18>=1,-PI(),IF(E18<-1,0,-ACOS(-E18))) -> -1.8651331 | I18: =H18*180/PI() -> -106.86425 | J18: =IF(E18>1,(24*1367/PI())*$C18*SIN(RADIANS(D18))*SIN(RADIANS(B$7))*PI(),(24*1367/PI())*$C18*COS(RADIANS(D18))*COS(RADIANS(B$7))*(H18*COS(H18)-SIN(H18))) -> 11016.143 | K18: =H$5*1000 -> 6600 | L18: =IF(J18-K18>0,K18/J18,0) -> 0.59912074 | M18: =1-1.13*L18 -> 0.32299356 | N18: =M18*K18 -> 2131.7575 | O18: =K18-N18 -> 4468.2425 | P18: =IF($L18>0,Ghm!L191,0) -> 2860.8017 | Q18: =IF($L18>0,Ghm!Z191,0) -> 1774.1507 | R18: =IF($L18>0,Ghm!AA191,0) -> 381.0609 | S18: =SUM(P18:R18) -> 5016.0132 | V18: =IF(K18<>0,(S18-K18)/K18,0) -> -0.239998
A19: 6 | B19: 161 | C19: =1+0.033*COS(RADIANS(360/365*B19)) -> 0.96923446 | D19: =23.45*SIN(RADIANS(360/365*(B19+284))) -> 23.011637 | E19: =TAN(RADIANS($D19))*TAN(RADIANS(B$7)) -> 0.36209996 | F19: =90-ABS($B$7)+D19*SIGN($B$7) -> 72.561637 | G19: =D19*SIGN($B$7)-(90-ABS($B$7)) -> -26.538363 | H19: =IF(E19>=1,-PI(),IF(E19<-1,0,-ACOS(-E19))) -> -1.9413161 | I19: =H19*180/PI() -> -111.22922 | J19: =IF(E19>1,(24*1367/PI())*$C19*SIN(RADIANS(D19))*SIN(RADIANS(B$7))*PI(),(24*1367/PI())*$C19*COS(RADIANS(D19))*COS(RADIANS(B$7))*(H19*COS(H19)-SIN(H19))) -> 11591.987 | K19: =I$5*1000 -> 7740 | L19: =IF(J19-K19>0,K19/J19,0) -> 0.66770263 | M19: =1-1.13*L19 -> 0.24549603 | N19: =M19*K19 -> 1900.1393 | O19: =K19-N19 -> 5839.8607 | P19: =Ghm!L227 -> 3213.3241 | Q19: =Ghm!Z227 -> 1523.9078 | R19: =Ghm!AA227 -> 447.10196 | S19: =SUM(P19:R19) -> 5184.3338 | V19: =IF(K19<>0,(S19-K19)/K19,0) -> -0.33018943
A20: 7 | B20: 198 | C20: =1+0.033*COS(RADIANS(360/365*B20)) -> 0.96816773 | D20: =23.45*SIN(RADIANS(360/365*(B20+284))) -> 21.183694 | E20: =TAN(RADIANS($D20))*TAN(RADIANS(B$7)) -> 0.33041199 | F20: =90-ABS($B$7)+D20*SIGN($B$7) -> 70.733694 | G20: =D20*SIGN($B$7)-(90-ABS($B$7)) -> -28.366306 | H20: =IF(E20>=1,-PI(),IF(E20<-1,0,-ACOS(-E20))) -> -1.9075364 | I20: =H20*180/PI() -> -109.29378 | J20: =IF(E20>1,(24*1367/PI())*$C20*SIN(RADIANS(D20))*SIN(RADIANS(B$7))*PI(),(24*1367/PI())*$C20*COS(RADIANS(D20))*COS(RADIANS(B$7))*(H20*COS(H20)-SIN(H20))) -> 11292.734 | K20: =J$5*1000 -> 8040 | L20: =IF(J20-K20>0,K20/J20,0) -> 0.71196223 | M20: =1-1.13*L20 -> 0.19548268 | N20: =M20*K20 -> 1571.6808 | O20: =K20-N20 -> 6468.3192 | P20: =Ghm!L263 -> 3786.0591 | Q20: =Ghm!Z263 -> 1330.3382 | R20: =Ghm!AA263 -> 464.44422 | S20: =SUM(P20:R20) -> 5580.8415 | V20: =IF(K20<>0,(S20-K20)/K20,0) -> -0.30586549
A21: 8 | B21: 228 | C21: =1+0.033*COS(RADIANS(360/365*B21)) -> 0.97661532 | D21: =23.45*SIN(RADIANS(360/365*(B21+284))) -> 13.45496 | E21: =TAN(RADIANS($D21))*TAN(RADIANS(B$7)) -> 0.20397586 | F21: =90-ABS($B$7)+D21*SIGN($B$7) -> 63.00496 | G21: =D21*SIGN($B$7)-(90-ABS($B$7)) -> -36.09504 | H21: =IF(E21>=1,-PI(),IF(E21<-1,0,-ACOS(-E21))) -> -1.7762138 | I21: =H21*180/PI() -> -101.76955 | J21: =IF(E21>1,(24*1367/PI())*$C21*SIN(RADIANS(D21))*SIN(RADIANS(B$7))*PI(),(24*1367/PI())*$C21*COS(RADIANS(D21))*COS(RADIANS(B$7))*(H21*COS(H21)-SIN(H21))) -> 10124.075 | K21: =K$5*1000 -> 7000 | L21: =IF(J21-K21>0,K21/J21,0) -> 0.69142122 | M21: =1-1.13*L21 -> 0.21869402 | N21: =M21*K21 -> 1530.8581 | O21: =K21-N21 -> 5469.1419 | P21: =Ghm!L299 -> 4166.823 | Q21: =Ghm!Z299 -> 1455.2454 | R21: =Ghm!AA299 -> 402.78594 | S21: =SUM(P21:R21) -> 6024.8543 | V21: =IF(K21<>0,(S21-K21)/K21,0) -> -0.13930653
A22: 9 | B22: 258 | C22: =1+0.033*COS(RADIANS(360/365*B22)) -> 0.99116213 | D22: =23.45*SIN(RADIANS(360/365*(B22+284))) -> 2.2168868 | E22: =TAN(RADIANS($D22))*TAN(RADIANS(B$7)) -> 0.033004187 | F22: =90-ABS($B$7)+D22*SIGN($B$7) -> 51.766887 | G22: =D22*SIGN($B$7)-(90-ABS($B$7)) -> -47.333113 | H22: =IF(E22>=1,-PI(),IF(E22<-1,0,-ACOS(-E22))) -> -1.6038065 | I22: =H22*180/PI() -> -91.891344 | J22: =IF(E22>1,(24*1367/PI())*$C22*SIN(RADIANS(D22))*SIN(RADIANS(B$7))*PI(),(24*1367/PI())*$C22*COS(RADIANS(D22))*COS(RADIANS(B$7))*(H22*COS(H22)-SIN(H22))) -> 8283.1216 | K22: =L$5*1000 -> 5470 | L22: =IF(J22-K22>0,K22/J22,0) -> 0.66037905 | M22: =1-1.13*L22 -> 0.25377167 | N22: =M22*K22 -> 1388.131 | O22: =K22-N22 -> 4081.869 | P22: =Ghm!L335 -> 4496.73 | Q22: =Ghm!Z335 -> 1569.2488 | R22: =Ghm!AA335 -> 313.81512 | S22: =SUM(P22:R22) -> 6379.7939 | V22: =IF(K22<>0,(S22-K22)/K22,0) -> 0.16632429
A23: 10 | B23: 289 | C23: =1+0.033*COS(RADIANS(360/365*B23)) -> 1.0085639 | D23: =23.45*SIN(RADIANS(360/365*(B23+284))) -> -9.966258 | E23: =TAN(RADIANS($D23))*TAN(RADIANS(B$7)) -> -0.1498139 | F23: =90-ABS($B$7)+D23*SIGN($B$7) -> 39.583742 | G23: =D23*SIGN($B$7)-(90-ABS($B$7)) -> -59.516258 | H23: =IF(E23>=1,-PI(),IF(E23<-1,0,-ACOS(-E23))) -> -1.4204163 | I23: =H23*180/PI() -> -81.383858 | J23: =IF(E23>1,(24*1367/PI())*$C23*SIN(RADIANS(D23))*SIN(RADIANS(B$7))*PI(),(24*1367/PI())*$C23*COS(RADIANS(D23))*COS(RADIANS(B$7))*(H23*COS(H23)-SIN(H23))) -> 6125.104 | K23: =M$5*1000 -> 3560 | L23: =IF(J23-K23>0,K23/J23,0) -> 0.58121463 | M23: =1-1.13*L23 -> 0.34322747 | N23: =M23*K23 -> 1221.8898 | O23: =K23-N23 -> 2338.1102 | P23: =Ghm!L371 -> 3758.1383 | Q23: =Ghm!Z371 -> 1636.7877 | R23: =Ghm!AA371 -> 203.18144 | S23: =SUM(P23:R23) -> 5598.1074 | V23: =IF(K23<>0,(S23-K23)/K23,0) -> 0.57250209
A24: 11 | B24: 319 | C24: =1+0.033*COS(RADIANS(360/365*B24)) -> 1.0231834 | D24: =23.45*SIN(RADIANS(360/365*(B24+284))) -> -19.147817 | E24: =TAN(RADIANS($D24))*TAN(RADIANS(B$7)) -> -0.29602681 | F24: =90-ABS($B$7)+D24*SIGN($B$7) -> 30.402183 | G24: =D24*SIGN($B$7)-(90-ABS($B$7)) -> -68.697817 | H24: =IF(E24>=1,-PI(),IF(E24<-1,0,-ACOS(-E24))) -> -1.270266 | I24: =H24*180/PI() -> -72.780881 | J24: =IF(E24>1,(24*1367/PI())*$C24*SIN(RADIANS(D24))*SIN(RADIANS(B$7))*PI(),(24*1367/PI())*$C24*COS(RADIANS(D24))*COS(RADIANS(B$7))*(H24*COS(H24)-SIN(H24))) -> 4448.6029 | K24: =N$5*1000 -> 2430 | L24: =IF(J24-K24>0,K24/J24,0) -> 0.54623891 | M24: =1-1.13*L24 -> 0.38275003 | N24: =M24*K24 -> 930.08257 | O24: =K24-N24 -> 1499.9174 | P24: =Ghm!L407 -> 3412.9687 | Q24: =Ghm!Z407 -> 1548.5009 | R24: =Ghm!AA407 -> 139.70814 | S24: =SUM(P24:R24) -> 5101.1778 | V24: =IF(K24<>0,(S24-K24)/K24,0) -> 1.0992501
A25: 12 | B25: 345 | C25: =1+0.033*COS(RADIANS(360/365*B25)) -> 1.0310635 | D25: =23.45*SIN(RADIANS(360/365*(B25+284))) -> -23.120484 | E25: =TAN(RADIANS($D25))*TAN(RADIANS(B$7)) -> -0.36401334 | F25: =90-ABS($B$7)+D25*SIGN($B$7) -> 26.429516 | G25: =D25*SIGN($B$7)-(90-ABS($B$7)) -> -72.670484 | H25: =IF(E25>=1,-PI(),IF(E25<-1,0,-ACOS(-E25))) -> -1.1982231 | I25: =H25*180/PI() -> -68.653126 | J25: =IF(E25>1,(24*1367/PI())*$C25*SIN(RADIANS(D25))*SIN(RADIANS(B$7))*PI(),(24*1367/PI())*$C25*COS(RADIANS(D25))*COS(RADIANS(B$7))*(H25*COS(H25)-SIN(H25))) -> 3731.8456 | K25: =O$5*1000 -> 1870 | L25: =IF(J25-K25>0,K25/J25,0) -> 0.50109254 | M25: =1-1.13*L25 -> 0.43376543 | N25: =M25*K25 -> 811.14135 | O25: =K25-N25 -> 1058.8587 | P25: =Ghm!L443 -> 2859.2487 | Q25: =Ghm!Z443 -> 1500.5592 | R25: =Ghm!AA443 -> 107.0083 | S25: =SUM(P25:R25) -> 4466.8161 | V25: =IF(K25<>0,(S25-K25)/K25,0) -> 1.3886717
J26: =1000*J30/365 -> 7800.8936 | K26: =1000*K30/365 -> 4894.2192 | L26: Prom.diario | S26: =1000*S30/365 -> 5476.8282 | T26: Promedio diario anual | V26: =IF(K30<>0,(S30-K30)/K30,0) -> 0.11904024
F28: =1784/1517 -> 1.1760053 | J28: Ba(0) | K28: Ga(0) | P28: Ba(a,b) | Q28: Da(a,b) | R28: Ra(a,b) | S28: Ga(a,b)
J29: (kWh/m2) | K29: (kWh/m2) | P29: (kWh/m2) | Q29: (kWh/m2) | R29: (kWh/m2) | S29: (kWh/m2)
I30: Extra-atmosférica anual | J30: =(31*J14+28*J15+31*J16+30*J17+31*J18+30*J19+31*J20+31*J21+30*J22+31*J23+30*J24+31*J25)/1000 -> 2847.3262 | K30: =(31*K14+28*K15+31*K16+30*K17+31*K18+30*K19+31*K20+31*K21+30*K22+31*K23+30*K24+31*K25)/1000 -> 1786.39 | L30: Global anual | P30: =(31*P14+28*P15+31*P16+30*P17+31*P18+30*P19+31*P20+31*P21+30*P22+31*P23+30*P24+31*P25)/1000 -> 1319.9676 | Q30: =(31*Q14+28*Q15+31*Q16+30*Q17+31*Q18+30*Q19+31*Q20+31*Q21+30*Q22+31*Q23+30*Q24+31*Q25)/1000 -> 576.34254 | R30: =(31*R14+28*R15+31*R16+30*R17+31*R18+30*R19+31*R20+31*R21+30*R22+31*R23+30*R24+31*R25)/1000 -> 102.73213 | S30: =(31*S14+28*S15+31*S16+30*S17+31*S18+30*S19+31*S20+31*S21+30*S22+31*S23+30*S24+31*S25)/1000 -> 1999.0423 | T30: Global anual
K31: =K30/J30 -> 0.62739212 | P31: =P30/$S$30 -> 0.6603 | Q31: =Q30/$S$30 -> 0.28830933 | R31: =R30/$S$30 -> 0.051390675 | S31: =S30/$S$30 -> 1

Sheet Ghm
A1: * CÁLCULOS HORARIOS (Difusa: Modelo Perez-Seals, 1987) | M1: * Para análisis de sombras (Pestaña "Tabla_FS"): Irradiación horaria potencialmente interceptable (kWh/m2)
N2: Mes
A3: DATOS GENERALES: | C3: (rad) | E3: Para cálculos de difusa: | H3: Tabla de Pérez | M3: W (h) | N3: 1 | O3: 2 | P3: 3 | Q3: 4 | R3: 5 | S3: 6 | T3: 7 | U3: 8 | V3: 9 | W3: 10 | X3: 11 | Y3: 12
A4: Latitud (º) = | B4: =Gdm!B7 -> 40.45 | C4: =RADIANS(B4) -> 0.70598568 | E4: einf | F4: k31 | G4: k32 | H4: k33 | I4: k41 | J4: k42 | K4: k43 | M4: -6.5 | N4: =AC28 -> 0 | O4: =AC64 -> 0 | P4: =AC100 -> 0 | Q4: =AC136 -> 0 | R4: =AC172 -> 0 | S4: =AC208 -> 0 | T4: =AC244 -> 0 | U4: =AC280 -> 0 | V4: =AC316 -> 0 | W4: =AC352 -> 0 | X4: =AC388 -> 0 | Y4: =AC424 -> 0
A5: Beta, b (º) = | B5: =Gdm!B8 -> 65 | C5: =RADIANS(B5) -> 1.134464 | E5: 1 | F5: -0.011 | G5: 0.748 | H5: -0.08 | I5: -0.048 | J5: 0.073 | K5: -0.024 | M5: -5.5 | N5: =AC29 -> 0 | O5: =AC65 -> 0 | P5: =AC101 -> 61.244346 | Q5: =AC137 -> 23.04669 | R5: =AC173 -> 0 | S5: =AC209 -> 0 | T5: =AC245 -> 0 | U5: =AC281 -> 11.587191 | V5: =AC317 -> 53.979475 | W5: =AC353 -> 0 | X5: =AC389 -> 0 | Y5: =AC425 -> 0
A6: Alfa, a (º) = | B6: =Gdm!B9 -> 0 | C6: =RADIANS(B6) -> 0 | E6: 1.056 | F6: -0.038 | G6: 1.115 | H6: -0.109 | I6: -0.023 | J6: 0.106 | K6: -0.037 | M6: -4.5 | N6: =AC30 -> 184.16077 | O6: =AC66 -> 200.86631 | P6: =AC102 -> 196.77258 | Q6: =AC138 -> 153.58761 | R6: =AC174 -> 114.37025 | S6: =AC210 -> 109.76035 | T6: =AC246 -> 132.07497 | U6: =AC282 -> 169.24106 | V6: =AC318 -> 204.13232 | W6: =AC354 -> 190.3521 | X6: =AC390 -> 182.22461 | Y6: =AC426 -> 157.03422
A7: Rho = | B7: =Gdm!B10 -> 0.2 | E7: 1.253 | F7: 0.166 | G7: 0.909 | H7: -0.179 | I7: 0.062 | J7: -0.021 | K7: -0.05 | M7: -3.5 | N7: =AC31 -> 321.00088 | O7: =AC67 -> 354.0739 | P7: =AC103 -> 362.93627 | Q7: =AC139 -> 305.749 | R7: =AC175 -> 255.85001 | S7: =AC211 -> 267.33577 | T7: =AC247 -> 303.68535 | U7: =AC283 -> 344.83999 | V7: =AC319 -> 380.25872 | W7: =AC355 -> 344.75797 | X7: =AC391 -> 318.90006 | Y7: =AC427 -> 276.54901
E8: 1.586 | F8: 0.419 | G8: 0.646 | H8: -0.262 | I8: 0.14 | J8: -0.167 | K8: -0.042 | M8: -2.5 | N8: =AC32 -> 470.02624 | O8: =AC68 -> 515.32492 | P8: =AC104 -> 528.89031 | Q8: =AC140 -> 455.55101 | R8: =AC176 -> 393.01403 | S8: =AC212 -> 415.9512 | T8: =AC248 -> 465.01096 | U8: =AC284 -> 517.89046 | V8: =AC320 -> 557.35259 | W8: =AC356 -> 502.64705 | X8: =AC392 -> 466.78467 | Y8: =AC428 -> 409.20029
E9: 2.134 | F9: 0.71 | G9: 0.025 | H9: -0.29 | I9: 0.243 | J9: -0.511 | K9: -0.004 | M9: -1.5 | N9: =AC33 -> 594.69268 | O9: =AC69 -> 647.47247 | P9: =AC105 -> 663.24479 | Q9: =AC141 -> 576.33715 | R9: =AC177 -> 503.14109 | S9: =AC213 -> 533.55384 | T9: =AC249 -> 591.46555 | U9: =AC285 -> 652.90538 | V9: =AC321 -> 697.5549 | W9: =AC357 -> 631.55812 | X9: =AC393 -> 590.1009 | Y9: =AC429 -> 521.87292
E10: 3.23 | F10: 0.857 | G10: -0.37 | H10: -0.279 | I10: 0.267 | J10: -0.792 | K10: 0.076 | M10: -0.5 | N10: =AC34 -> 665.09523 | O10: =AC70 -> 721.82582 | P10: =AC106 -> 738.56769 | Q10: =AC142 -> 644.219 | R10: =AC178 -> 565.37888 | S10: =AC214 -> 599.56918 | T10: =AC250 -> 669.86532 | U10: =AC286 -> 728.09031 | V10: =AC322 -> 775.8369 | W10: =AC358 -> 704.06338 | X10: =AC394 -> 659.72072 | Y10: =AC430 -> 585.70262
E11: 5.98 | F11: 0.734 | G11: -0.073 | H11: -0.228 | I11: 0.231 | J11: -1.18 | K11: 0.199 | M11: 0.5 | N11: =AC35 -> 665.09523 | O11: =AC71 -> 721.82582 | P11: =AC107 -> 738.56769 | Q11: =AC143 -> 644.219 | R11: =AC179 -> 565.37888 | S11: =AC215 -> 599.56918 | T11: =AC251 -> 669.86532 | U11: =AC287 -> 728.09031 | V11: =AC323 -> 775.8369 | W11: =AC359 -> 704.06338 | X11: =AC395 -> 659.72072 | Y11: =AC431 -> 585.70262
E12: 10.08 | F12: 0.421 | G12: -0.661 | H12: 0.097 | I12: 0.119 | J12: -2.125 | K12: 0.446 | M12: 1.5 | N12: =AC36 -> 594.69268 | O12: =AC72 -> 647.47247 | P12: =AC108 -> 663.24479 | Q12: =AC144 -> 576.33715 | R12: =AC180 -> 503.14109 | S12: =AC216 -> 533.55384 | T12: =AC252 -> 591.46555 | U12: =AC288 -> 652.90538 | V12: =AC324 -> 697.5549 | W12: =AC360 -> 631.55812 | X12: =AC396 -> 590.1009 | Y12: =AC432 -> 521.87292
A13: MES: | B13: =Gdm!A14 -> 1 | M13: 2.5 | N13: =AC37 -> 470.02624 | O13: =AC73 -> 515.32492 | P13: =AC109 -> 528.89031 | Q13: =AC145 -> 455.55101 | R13: =AC181 -> 393.01403 | S13: =AC217 -> 415.9512 | T13: =AC253 -> 465.01096 | U13: =AC289 -> 517.89046 | V13: =AC325 -> 557.35259 | W13: =AC361 -> 502.64705 | X13: =AC397 -> 466.78467 | Y13: =AC433 -> 409.20029
A14: Epsilon_0 = | B14: =Gdm!C14 -> 1.031597 | M14: 3.5 | N14: =AC38 -> 321.00088 | O14: =AC74 -> 354.0739 | P14: =AC110 -> 362.93627 | Q14: =AC146 -> 305.749 | R14: =AC182 -> 255.85001 | S14: =AC218 -> 267.33577 | T14: =AC254 -> 303.68535 | U14: =AC290 -> 344.83999 | V14: =AC326 -> 380.25872 | W14: =AC362 -> 344.75797 | X14: =AC398 -> 318.90006 | Y14: =AC434 -> 276.54901
A15: Declinación (º)= | B15: =Gdm!D14 -> -20.916963 | M15: 4.5 | N15: =AC39 -> 184.16077 | O15: =AC75 -> 200.86631 | P15: =AC111 -> 196.77258 | Q15: =AC147 -> 153.58761 | R15: =AC183 -> 114.37025 | S15: =AC219 -> 109.76035 | T15: =AC255 -> 132.07497 | U15: =AC291 -> 169.24106 | V15: =AC327 -> 204.13232 | W15: =AC363 -> 190.3521 | X15: =AC399 -> 182.22461 | Y15: =AC435 -> 157.03422
A16: Ws (rad)= | B16: =Gdm!H14 -> -1.2388803 | C16: Ws (º): | D16: =B16*180/PI() -> -70.982614 | M16: 5.5 | N16: =AC40 -> 0 | O16: =AC76 -> 0 | P16: =AC112 -> 61.244346 | Q16: =AC148 -> 23.04669 | R16: =AC184 -> 0 | S16: =AC220 -> 0 | T16: =AC256 -> 0 | U16: =AC292 -> 11.587191 | V16: =AC328 -> 53.979475 | W16: =AC364 -> 0 | X16: =AC400 -> 0 | Y16: =AC436 -> 0
A17: Ddm(0) (Wh/m2) = | B17: =Gdm!N14 -> 866.37816 | C17: Ws (h): | D17: =D16/15 -> -4.7321743 | M17: 6.5 | N17: =AC41 -> 0 | O17: =AC77 -> 0 | P17: =AC113 -> 0 | Q17: =AC149 -> 0 | R17: =AC185 -> 0 | S17: =AC221 -> 0 | T17: =AC257 -> 0 | U17: =AC293 -> 0 | V17: =AC329 -> 0 | W17: =AC365 -> 0 | X17: =AC401 -> 0 | Y17: =AC437 -> 0
A18: Gdm(0) (Wh/m2) = | B18: =Gdm!K14 -> 2270
A19: a= | B19: =0.409-0.5016*SIN(B16+PI()/3) -> 0.50456038
A20: b= | B20: =0.6609+0.4767*SIN(B16+PI()/3) -> 0.57008335
Z21: D=Dc+Di+bh
A22: w (h) | B22: w (rad) | C22: rd | D22: D(0) | E22: rg | F22: G(0) | G22: B(0) | H22: Cos(qZS) | I22: qZS (rad) | J22: Cos(qS) | K22: qS (rad) | L22: B(a,b) | M22: epsilon | N22: AM | O22: delta | P22: k31 | Q22: k32 | R22: k33 | S22: k41 | T22: k42 | U22: k43 | V22: k3 | W22: k4 | X22: Dc(a,b) | Y22: Di+bh (a,b) | Z22: D(a,b) | AA22: R(a,b) | AB22: G(a,b)= Ghm(a,b) | AC22: B(a,b)+Dc(a,b)
A23: -11.5 | B23: =A23*PI()/12 -> -3.010693 | C23: =IF($B$16<>0,(PI()/24)*(COS($B23)-COS($B$16))/($B$16*COS($B$16)-SIN($B$16)),0) -> -0.3183061 | D23: =IF(C23>0,$B$17*C23,0) -> 0 | E23: =C23*($B$19+$B$20*COS(B23)) -> 0.019303939 | F23: =IF(C23>0,$B$18*E23,0) -> 0 | G23: =IF(AND(F23>0,F23>D23),F23-D23,0) -> 0 | H23: =SIN(RADIANS($B$15))*SIN(LAT)+COS(RADIANS($B$15))*COS(LAT)*COS(B23) -> -0.93636766 | I23: =ACOS(H23) -> 2.7829316 | J23: =SIN(RADIANS($B$15))*SIN(LAT)*COS($C$5)-SIN(RADIANS($B$15))*COS(LAT)*SIN($C$5)*COS($C$6)+COS(RADIANS($B$15))*COS(LAT)*COS($C$5)*COS(B23)+COS(RADIANS($B$15))*SIN(LAT)*SIN($C$5)*COS($C$6)*COS(B23)+COS(RADIANS($B$15))*SIN($C$6)*SIN(B23)*SIN($C$5) -> -0.6940515 | K23: =ACOS(J23) -> 2.3378979 | L23: =(G23/H23)*MAX(0,J23) -> 0 | M23: =IF(D23=0,0,1+G23/(D23*H23)) -> 0 | N23: =1/H23 -> -1.0679566 | O23: =D23*N23/1367 -> 0 | P23: =IF($M23=0,0,IF(AND($M23>=$E$5,$M23<$E$6),$F$5,IF(AND($M23>=$E$6,$M23<$E$7),$F$6,IF(AND($M23>=$E$7,$M23<$E$8),$F$7,IF(AND($M23>=$E$8,$M23<$E$9),$F$8,IF(AND($M23>=$E$9,$M23<$E$10),$F$9,IF(AND($M23>=$E$10,$M23<$E$11),$F$10,IF(AND($M23>=$E$11,$M23<$E$12),$F$11,IF($M23>=$E$12,$F$12,"error"))))))))) -> 0 | Q23: =IF($M23=0,0,IF(AND($M23>=$E$5,$M23<$E$6),$G$5,IF(AND($M23>=$E$6,$M23<$E$7),$G$6,IF(AND($M23>=$E$7,$M23<$E$8),$G$7,IF(AND($M23>=$E$8,$M23<$E$9),$G$8,IF(AND($M23>=$E$9,$M23<$E$10),$G$9,IF(AND($M23>=$E$10,$M23<$E$11),$G$10,IF(AND($M23>=$E$11,$M23<$E$12),$G$11,IF($M23>=$E$12,$G$12,"error"))))))))) -> 0 | R23: =IF($M23=0,0,IF(AND($M23>=$E$5,$M23<$E$6),$H$5,IF(AND($M23>=$E$6,$M23<$E$7),$H$6,IF(AND($M23>=$E$7,$M23<$E$8),$H$7,IF(AND($M23>=$E$8,$M23<$E$9),$H$8,IF(AND($M23>=$E$9,$M23<$E$10),$H$9,IF(AND($M23>=$E$10,$M23<$E$11),$H$10,IF(AND($M23>=$E$11,$M23<$E$12),$H$11,IF($M23>=$E$12,$H$12,"error"))))))))) -> 0 | S23: =IF($M23=0,0,IF(AND($M23>=$E$5,$M23<$E$6),$I$5,IF(AND($M23>=$E$6,$M23<$E$7),$I$6,IF(AND($M23>=$E$7,$M23<$E$8),$I$7,IF(AND($M23>=$E$8,$M23<$E$9),$I$8,IF(AND($M23>=$E$9,$M23<$E$10),$I$9,IF(AND($M23>=$E$10,$M23<$E$11),$I$10,IF(AND($M23>=$E$11,$M23<$E$12),$I$11,IF($M23>=$E$12,$I$12,"error"))))))))) -> 0 | T23: =IF($M23=0,0,IF(AND($M23>=$E$5,$M23<$E$6),$J$5,IF(AND($M23>=$E$6,$M23<$E$7),$J$6,IF(AND($M23>=$E$7,$M23<$E$8),$J$7,IF(AND($M23>=$E$8,$M23<$E$9),$J$8,IF(AND($M23>=$E$9,$M23<$E$10),$J$9,IF(AND($M23>=$E$10,$M23<$E$11),$J$10,IF(AND($M23>=$E$11,$M23<$E$12),$J$11,IF($M23>=$E$12,$J$12,"error"))))))))) -> 0 | U23: =IF($M23=0,0,IF(AND($M23>=$E$5,$M23<$E$6),$K$5,IF(AND($M23>=$E$6,$M23<$E$7),$K$6,IF(AND($M23>=$E$7,$M23<$E$8),$K$7,IF(AND($M23>=$E$8,$M23<$E$9),$K$8,IF(AND($M23>=$E$9,$M23<$E$10),$K$9,IF(AND($M23>=$E$10,$M23<$E$11),$K$10,IF(AND($M23>=$E$11,$M23<$E$12),$K$11,IF($M23>=$E$12,$K$12,"error"))))))))) -> 0 | V23: =P23+Q23*O23+R23*I23 -> 0 | W23: =S23+T23*O23+U23*I23 -> 0 | X23: =D23*V23*MAX(0,J23)/H23 -> 0 | Y23: =D23*(0.5*(1+COS($C$5))*(1-V23)+W23*SIN(ABS($C$5))) -> 0 | Z23: =X23+Y23 -> 0 | AA23: =IF(F23>0,F23*$B$7*(1-COS($C$5))/2,0) -> 0 | AB23: =L23+Z23+AA23 -> 0 | AC23: =L23+X23 -> 0
A24: -10.5 | B24: =A24*PI()/12 -> -2.7488936 | C24: =IF($B$16<>0,(PI()/24)*(COS($B24)-COS($B$16))/($B$16*COS($B$16)-SIN($B$16)),0) -> -0.30197993 | D24: =IF(C24>0,$B$17*C24,0) -> 0 | E24: =C24*($B$19+$B$20*COS(B24)) -> 0.0066822012 | F24: =IF(C24>0,$B$18*E24,0) -> 0 | G24: =IF(AND(F24>0,F24>D24),F24-D24,0) -> 0 | H24: =SIN(RADIANS($B$15))*SIN(LAT)+COS(RADIANS($B$15))*COS(LAT)*COS(B24) -> -0.88834064 | I24: =ACOS(H24) -> 2.6645151 | J24: =SIN(RADIANS($B$15))*SIN(LAT)*COS($C$5)-SIN(RADIANS($B$15))*COS(LAT)*SIN($C$5)*COS($C$6)+COS(RADIANS($B$15))*COS(LAT)*COS($C$5)*COS(B24)+COS(RADIANS($B$15))*SIN(LAT)*SIN($C$5)*COS($C$6)*COS(B24)+COS(RADIANS($B$15))*SIN($C$6)*SIN(B24)*SIN($C$5) -> -0.63664425 | K24: =ACOS(J24) -> 2.2609352 | L24: =(G24/H24)*MAX(0,J24) -> 0 | M24: =IF(D24=0,0,1+G24/(D24*H24)) -> 0 | N24: =1/H24 -> -1.1256943 | O24: =D24*N24/1367 -> 0 | P24: =IF($M24=0,0,IF(AND($M24>=$E$5,$M24<$E$6),$F$5,IF(AND($M24>=$E$6,$M24<$E$7),$F$6,IF(AND($M24>=$E$7,$M24<$E$8),$F$7,IF(AND($M24>=$E$8,$M24<$E$9),$F$8,IF(AND($M24>=$E$9,$M24<$E$10),$F$9,IF(AND($M24>=$E$10,$M24<$E$11),$F$10,IF(AND($M24>=$E$11,$M24<$E$12),$F$11,IF($M24>=$E$12,$F$12,"error"))))))))) -> 0 | Q24: =IF($M24=0,0,IF(AND($M24>=$E$5,$M24<$E$6),$G$5,IF(AND($M24>=$E$6,$M24<$E$7),$G$6,IF(AND($M24>=$E$7,$M24<$E$8),$G$7,IF(AND($M24>=$E$8,$M24<$E$9),$G$8,IF(AND($M24>=$E$9,$M24<$E$10),$G$9,IF(AND($M24>=$E$10,$M24<$E$11),$G$10,IF(AND($M24>=$E$11,$M24<$E$12),$G$11,IF($M24>=$E$12,$G$12,"error"))))))))) -> 0 | R24: =IF($M24=0,0,IF(AND($M24>=$E$5,$M24<$E$6),$H$5,IF(AND($M24>=$E$6,$M24<$E$7),$H$6,IF(AND($M24>=$E$7,$M24<$E$8),$H$7,IF(AND($M24>=$E$8,$M24<$E$9),$H$8,IF(AND($M24>=$E$9,$M24<$E$10),$H$9,IF(AND($M24>=$E$10,$M24<$E$11),$H$10,IF(AND($M24>=$E$11,$M24<$E$12),$H$11,IF($M24>=$E$12,$H$12,"error"))))))))) -> 0 | S24: =IF($M24=0,0,IF(AND($M24>=$E$5,$M24<$E$6),$I$5,IF(AND($M24>=$E$6,$M24<$E$7),$I$6,IF(AND($M24>=$E$7,$M24<$E$8),$I$7,IF(AND($M24>=$E$8,$M24<$E$9),$I$8,IF(AND($M24>=$E$9,$M24<$E$10),$I$9,IF(AND($M24>=$E$10,$M24<$E$11),$I$10,IF(AND($M24>=$E$11,$M24<$E$12),$I$11,IF($M24>=$E$12,$I$12,"error"))))))))) -> 0 | T24: =IF($M24=0,0,IF(AND($M24>=$E$5,$M24<$E$6),$J$5,IF(AND($M24>=$E$6,$M24<$E$7),$J$6,IF(AND($M24>=$E$7,$M24<$E$8),$J$7,IF(AND($M24>=$E$8,$M24<$E$9),$J$8,IF(AND($M24>=$E$9,$M24<$E$10),$J$9,IF(AND($M24>=$E$10,$M24<$E$11),$J$10,IF(AND($M24>=$E$11,$M24<$E$12),$J$11,IF($M24>=$E$12,$J$12,"error"))))))))) -> 0 | U24: =IF($M24=0,0,IF(AND($M24>=$E$5,$M24<$E$6),$K$5,IF(AND($M24>=$E$6,$M24<$E$7),$K$6,IF(AND($M24>=$E$7,$M24<$E$8),$K$7,IF(AND($M24>=$E$8,$M24<$E$9),$K$8,IF(AND($M24>=$E$9,$M24<$E$10),$K$9,IF(AND($M24>=$E$10,$M24<$E$11),$K$10,IF(AND($M24>=$E$11,$M24<$E$12),$K$11,IF($M24>=$E$12,$K$12,"error"))))))))) -> 0 | V24: =P24+Q24*O24+R24*I24 -> 0 | W24: =S24+T24*O24+U24*I24 -> 0 | X24: =D24*V24*MAX(0,J24)/H24 -> 0 | Y24: =D24*(0.5*(1+COS($C$5))*(1-V24)+W24*SIN(ABS($C$5))) -> 0 | Z24: =X24+Y24 -> 0 | AA24: =IF(F24>0,F24*$B$7*(1-COS($C$5))/2,0) -> 0 | AB24: =L24+Z24+AA24 -> 0 | AC24: =L24+X24 -> 0
A25: -9.5 | B25: =A25*PI()/12 -> -2.4870942 | C25: =IF($B$16<>0,(PI()/24)*(COS($B25)-COS($B$16))/($B$16*COS($B$16)-SIN($B$16)),0) -> -0.2704402 | D25: =IF(C25>0,$B$17*C25,0) -> 0 | E25: =C25*($B$19+$B$20*COS(B25)) -> -0.014139383 | F25: =IF(C25>0,$B$18*E25,0) -> 0 | G25: =IF(AND(F25>0,F25>D25),F25-D25,0) -> 0 | H25: =SIN(RADIANS($B$15))*SIN(LAT)+COS(RADIANS($B$15))*COS(LAT)*COS(B25) -> -0.79555957 | I25: =ACOS(H25) -> 2.4907269 | J25: =SIN(RADIANS($B$15))*SIN(LAT)*COS($C$5)-SIN(RADIANS($B$15))*COS(LAT)*SIN($C$5)*COS($C$6)+COS(RADIANS($B$15))*COS(LAT)*COS($C$5)*COS(B25)+COS(RADIANS($B$15))*SIN(LAT)*SIN($C$5)*COS($C$6)*COS(B25)+COS(RADIANS($B$15))*SIN($C$6)*SIN(B25)*SIN($C$5) -> -0.52574197 | K25: =ACOS(J25) -> 2.1243834 | L25: =(G25/H25)*MAX(0,J25) -> 0 | M25: =IF(D25=0,0,1+G25/(D25*H25)) -> 0 | N25: =1/H25 -> -1.2569769 | O25: =D25*N25/1367 -> 0 | P25: =IF($M25=0,0,IF(AND($M25>=$E$5,$M25<$E$6),$F$5,IF(AND($M25>=$E$6,$M25<$E$7),$F$6,IF(AND($M25>=$E$7,$M25<$E$8),$F$7,IF(AND($M25>=$E$8,$M25<$E$9),$F$8,IF(AND($M25>=$E$9,$M25<$E$10),$F$9,IF(AND($M25>=$E$10,$M25<$E$11),$F$10,IF(AND($M25>=$E$11,$M25<$E$12),$F$11,IF($M25>=$E$12,$F$12,"error"))))))))) -> 0 | Q25: =IF($M25=0,0,IF(AND($M25>=$E$5,$M25<$E$6),$G$5,IF(AND($M25>=$E$6,$M25<$E$7),$G$6,IF(AND($M25>=$E$7,$M25<$E$8),$G$7,IF(AND($M25>=$E$8,$M25<$E$9),$G$8,IF(AND($M25>=$E$9,$M25<$E$10),$G$9,IF(AND($M25>=$E$10,$M25<$E$11),$G$10,IF(AND($M25>=$E$11,$M25<$E$12),$G$11,IF($M25>=$E$12,$G$12,"error"))))))))) -> 0 | R25: =IF($M25=0,0,IF(AND($M25>=$E$5,$M25<$E$6),$H$5,IF(AND($M25>=$E$6,$M25<$E$7),$H$6,IF(AND($M25>=$E$7,$M25<$E$8),$H$7,IF(AND($M25>=$E$8,$M25<$E$9),$H$8,IF(AND($M25>=$E$9,$M25<$E$10),$H$9,IF(AND($M25>=$E$10,$M25<$E$11),$H$10,IF(AND($M25>=$E$11,$M25<$E$12),$H$11,IF($M25>=$E$12,$H$12,"error"))))))))) -> 0 | S25: =IF($M25=0,0,IF(AND($M25>=$E$5,$M25<$E$6),$I$5,IF(AND($M25>=$E$6,$M25<$E$7),$I$6,IF(AND($M25>=$E$7,$M25<$E$8),$I$7,IF(AND($M25>=$E$8,$M25<$E$9),$I$8,IF(AND($M25>=$E$9,$M25<$E$10),$I$9,IF(AND($M25>=$E$10,$M25<$E$11),$I$10,IF(AND($M25>=$E$11,$M25<$E$12),$I$11,IF($M25>=$E$12,$I$12,"error"))))))))) -> 0 | T25: =IF($M25=0,0,IF(AND($M25>=$E$5,$M25<$E$6),$J$5,IF(AND($M25>=$E$6,$M25<$E$7),$J$6,IF(AND($M25>=$E$7,$M25<$E$8),$J$7,IF(AND($M25>=$E$8,$M25<$E$9),$J$8,IF(AND($M25>=$E$9,$M25<$E$10),$J$9,IF(AND($M25>=$E$10,$M25<$E$11),$J$10,IF(AND($M25>=$E$11,$M25<$E$12),$J$11,IF($M25>=$E$12,$J$12,"error"))))))))) -> 0 | U25: =IF($M25=0,0,IF(AND($M25>=$E$5,$M25<$E$6),$K$5,IF(AND($M25>=$E$6,$M25<$E$7),$K$6,IF(AND($M25>=$E$7,$M25<$E$8),$K$7,IF(AND($M25>=$E$8,$M25<$E$9),$K$8,IF(AND($M25>=$E$9,$M25<$E$10),$K$9,IF(AND($M25>=$E$10,$M25<$E$11),$K$10,IF(AND($M25>=$E$11,$M25<$E$12),$K$11,IF($M25>=$E$12,$K$12,"error"))))))))) -> 0 | V25: =P25+Q25*O25+R25*I25 -> 0 | W25: =S25+T25*O25+U25*I25 -> 0 | X25: =D25*V25*MAX(0,J25)/H25 -> 0 | Y25: =D25*(0.5*(1+COS($C$5))*(1-V25)+W25*SIN(ABS($C$5))) -> 0 | Z25: =X25+Y25 -> 0 | AA25: =IF(F25>0,F25*$B$7*(1-COS($C$5))/2,0) -> 0 | AB25: =L25+Z25+AA25 -> 0 | AC25: =L25+X25 -> 0
A26: -8.5 | B26: =A26*PI()/12 -> -2.2252948 | C26: =IF($B$16<>0,(PI()/24)*(COS($B26)-COS($B$16))/($B$16*COS($B$16)-SIN($B$16)),0) -> -0.22583629 | D26: =IF(C26>0,$B$17*C26,0) -> 0 | E26: =C26*($B$19+$B$20*COS(B26)) -> -0.035572743 | F26: =IF(C26>0,$B$18*E26,0) -> 0 | G26: =IF(AND(F26>0,F26>D26),F26-D26,0) -> 0 | H26: =SIN(RADIANS($B$15))*SIN(LAT)+COS(RADIANS($B$15))*COS(LAT)*COS(B26) -> -0.66434731 | I26: =ACOS(H26) -> 2.2974166 | J26: =SIN(RADIANS($B$15))*SIN(LAT)*COS($C$5)-SIN(RADIANS($B$15))*COS(LAT)*SIN($C$5)*COS($C$6)+COS(RADIANS($B$15))*COS(LAT)*COS($C$5)*COS(B26)+COS(RADIANS($B$15))*SIN(LAT)*SIN($C$5)*COS($C$6)*COS(B26)+COS(RADIANS($B$15))*SIN($C$6)*SIN(B26)*SIN($C$5) -> -0.36890246 | K26: =ACOS(J26) -> 1.9486242 | L26: =(G26/H26)*MAX(0,J26) -> 0 | M26: =IF(D26=0,0,1+G26/(D26*H26)) -> 0 | N26: =1/H26 -> -1.5052368 | O26: =D26*N26/1367 -> 0 | P26: =IF($M26=0,0,IF(AND($M26>=$E$5,$M26<$E$6),$F$5,IF(AND($M26>=$E$6,$M26<$E$7),$F$6,IF(AND($M26>=$E$7,$M26<$E$8),$F$7,IF(AND($M26>=$E$8,$M26<$E$9),$F$8,IF(AND($M26>=$E$9,$M26<$E$10),$F$9,IF(AND($M26>=$E$10,$M26<$E$11),$F$10,IF(AND($M26>=$E$11,$M26<$E$12),$F$11,IF($M26>=$E$12,$F$12,"error"))))))))) -> 0 | Q26: =IF($M26=0,0,IF(AND($M26>=$E$5,$M26<$E$6),$G$5,IF(AND($M26>=$E$6,$M26<$E$7),$G$6,IF(AND($M26>=$E$7,$M26<$E$8),$G$7,IF(AND($M26>=$E$8,$M26<$E$9),$G$8,IF(AND($M26>=$E$9,$M26<$E$10),$G$9,IF(AND($M26>=$E$10,$M26<$E$11),$G$10,IF(AND($M26>=$E$11,$M26<$E$12),$G$11,IF($M26>=$E$12,$G$12,"error"))))))))) -> 0 | R26: =IF($M26=0,0,IF(AND($M26>=$E$5,$M26<$E$6),$H$5,IF(AND($M26>=$E$6,$M26<$E$7),$H$6,IF(AND($M26>=$E$7,$M26<$E$8),$H$7,IF(AND($M26>=$E$8,$M26<$E$9),$H$8,IF(AND($M26>=$E$9,$M26<$E$10),$H$9,IF(AND($M26>=$E$10,$M26<$E$11),$H$10,IF(AND($M26>=$E$11,$M26<$E$12),$H$11,IF($M26>=$E$12,$H$12,"error"))))))))) -> 0 | S26: =IF($M26=0,0,IF(AND($M26>=$E$5,$M26<$E$6),$I$5,IF(AND($M26>=$E$6,$M26<$E$7),$I$6,IF(AND($M26>=$E$7,$M26<$E$8),$I$7,IF(AND($M26>=$E$8,$M26<$E$9),$I$8,IF(AND($M26>=$E$9,$M26<$E$10),$I$9,IF(AND($M26>=$E$10,$M26<$E$11),$I$10,IF(AND($M26>=$E$11,$M26<$E$12),$I$11,IF($M26>=$E$12,$I$12,"error"))))))))) -> 0 | T26: =IF($M26=0,0,IF(AND($M26>=$E$5,$M26<$E$6),$J$5,IF(AND($M26>=$E$6,$M26<$E$7),$J$6,IF(AND($M26>=$E$7,$M26<$E$8),$J$7,IF(AND($M26>=$E$8,$M26<$E$9),$J$8,IF(AND($M26>=$E$9,$M26<$E$10),$J$9,IF(AND($M26>=$E$10,$M26<$E$11),$J$10,IF(AND($M26>=$E$11,$M26<$E$12),$J$11,IF($M26>=$E$12,$J$12,"error"))))))))) -> 0 | U26: =IF($M26=0,0,IF(AND($M26>=$E$5,$M26<$E$6),$K$5,IF(AND($M26>=$E$6,$M26<$E$7),$K$6,IF(AND($M26>=$E$7,$M26<$E$8),$K$7,IF(AND($M26>=$E$8,$M26<$E$9),$K$8,IF(AND($M26>=$E$9,$M26<$E$10),$K$9,IF(AND($M26>=$E$10,$M26<$E$11),$K$10,IF(AND($M26>=$E$11,$M26<$E$12),$K$11,IF($M26>=$E$12,$K$12,"error"))))))))) -> 0 | V26: =P26+Q26*O26+R26*I26 -> 0 | W26: =S26+T26*O26+U26*I26 -> 0 | X26: =D26*V26*MAX(0,J26)/H26 -> 0 | Y26: =D26*(0.5*(1+COS($C$5))*(1-V26)+W26*SIN(ABS($C$5))) -> 0 | Z26: =X26+Y26 -> 0 | AA26: =IF(F26>0,F26*$B$7*(1-COS($C$5))/2,0) -> 0 | AB26: =L26+Z26+AA26 -> 0 | AC26: =L26+X26 -> 0
A27: -7.5 | B27: =A27*PI()/12 -> -1.9634954 | C27: =IF($B$16<>0,(PI()/24)*(COS($B27)-COS($B$16))/($B$16*COS($B$16)-SIN($B$16)),0) -> -0.17120788 | D27: =IF(C27>0,$B$17*C27,0) -> 0 | E27: =C27*($B$19+$B$20*COS(B27)) -> -0.049033751 | F27: =IF(C27>0,$B$18*E27,0) -> 0 | G27: =IF(AND(F27>0,F27>D27),F27-D27,0) -> 0 | H27: =SIN(RADIANS($B$15))*SIN(LAT)+COS(RADIANS($B$15))*COS(LAT)*COS(B27) -> -0.50364577 | I27: =ACOS(H27) -> 2.09861 | J27: =SIN(RADIANS($B$15))*SIN(LAT)*COS($C$5)-SIN(RADIANS($B$15))*COS(LAT)*SIN($C$5)*COS($C$6)+COS(RADIANS($B$15))*COS(LAT)*COS($C$5)*COS(B27)+COS(RADIANS($B$15))*SIN(LAT)*SIN($C$5)*COS($C$6)*COS(B27)+COS(RADIANS($B$15))*SIN($C$6)*SIN(B27)*SIN($C$5) -> -0.17681407 | K27: =ACOS(J27) -> 1.7485449 | L27: =(G27/H27)*MAX(0,J27) -> 0 | M27: =IF(D27=0,0,1+G27/(D27*H27)) -> 0 | N27: =1/H27 -> -1.9855225 | O27: =D27*N27/1367 -> 0 | P27: =IF($M27=0,0,IF(AND($M27>=$E$5,$M27<$E$6),$F$5,IF(AND($M27>=$E$6,$M27<$E$7),$F$6,IF(AND($M27>=$E$7,$M27<$E$8),$F$7,IF(AND($M27>=$E$8,$M27<$E$9),$F$8,IF(AND($M27>=$E$9,$M27<$E$10),$F$9,IF(AND($M27>=$E$10,$M27<$E$11),$F$10,IF(AND($M27>=$E$11,$M27<$E$12),$F$11,IF($M27>=$E$12,$F$12,"error"))))))))) -> 0 | Q27: =IF($M27=0,0,IF(AND($M27>=$E$5,$M27<$E$6),$G$5,IF(AND($M27>=$E$6,$M27<$E$7),$G$6,IF(AND($M27>=$E$7,$M27<$E$8),$G$7,IF(AND($M27>=$E$8,$M27<$E$9),$G$8,IF(AND($M27>=$E$9,$M27<$E$10),$G$9,IF(AND($M27>=$E$10,$M27<$E$11),$G$10,IF(AND($M27>=$E$11,$M27<$E$12),$G$11,IF($M27>=$E$12,$G$12,"error"))))))))) -> 0 | R27: =IF($M27=0,0,IF(AND($M27>=$E$5,$M27<$E$6),$H$5,IF(AND($M27>=$E$6,$M27<$E$7),$H$6,IF(AND($M27>=$E$7,$M27<$E$8),$H$7,IF(AND($M27>=$E$8,$M27<$E$9),$H$8,IF(AND($M27>=$E$9,$M27<$E$10),$H$9,IF(AND($M27>=$E$10,$M27<$E$11),$H$10,IF(AND($M27>=$E$11,$M27<$E$12),$H$11,IF($M27>=$E$12,$H$12,"error"))))))))) -> 0 | S27: =IF($M27=0,0,IF(AND($M27>=$E$5,$M27<$E$6),$I$5,IF(AND($M27>=$E$6,$M27<$E$7),$I$6,IF(AND($M27>=$E$7,$M27<$E$8),$I$7,IF(AND($M27>=$E$8,$M27<$E$9),$I$8,IF(AND($M27>=$E$9,$M27<$E$10),$I$9,IF(AND($M27>=$E$10,$M27<$E$11),$I$10,IF(AND($M27>=$E$11,$M27<$E$12),$I$11,IF($M27>=$E$12,$I$12,"error"))))))))) -> 0 | T27: =IF($M27=0,0,IF(AND($M27>=$E$5,$M27<$E$6),$J$5,IF(AND($M27>=$E$6,$M27<$E$7),$J$6,IF(AND($M27>=$E$7,$M27<$E$8),$J$7,IF(AND($M27>=$E$8,$M27<$E$9),$J$8,IF(AND($M27>=$E$9,$M27<$E$10),$J$9,IF(AND($M27>=$E$10,$M27<$E$11),$J$10,IF(AND($M27>=$E$11,$M27<$E$12),$J$11,IF($M27>=$E$12,$J$12,"error"))))))))) -> 0 | U27: =IF($M27=0,0,IF(AND($M27>=$E$5,$M27<$E$6),$K$5,IF(AND($M27>=$E$6,$M27<$E$7),$K$6,IF(AND($M27>=$E$7,$M27<$E$8),$K$7,IF(AND($M27>=$E$8,$M27<$E$9),$K$8,IF(AND($M27>=$E$9,$M27<$E$10),$K$9,IF(AND($M27>=$E$10,$M27<$E$11),$K$10,IF(AND($M27>=$E$11,$M27<$E$12),$K$11,IF($M27>=$E$12,$K$12,"error"))))))))) -> 0 | V27: =P27+Q27*O27+R27*I27 -> 0 | W27: =S27+T27*O27+U27*I27 -> 0 | X27: =D27*V27*MAX(0,J27)/H27 -> 0 | Y27: =D27*(0.5*(1+COS($C$5))*(1-V27)+W27*SIN(ABS($C$5))) -> 0 | Z27: =X27+Y27 -> 0 | AA27: =IF(F27>0,F27*$B$7*(1-COS($C$5))/2,0) -> 0 | AB27: =L27+Z27+AA27 -> 0 | AC27: =L27+X27 -> 0
A28: -6.5 | B28: =A28*PI()/12 -> -1.701696 | C28: =IF($B$16<>0,(PI()/24)*(COS($B28)-COS($B$16))/($B$16*COS($B$16)-SIN($B$16)),0) -> -0.1102778 | D28: =IF(C28>0,$B$17*C28,0) -> 0 | E28: =C28*($B$19+$B$20*COS(B28)) -> -0.047435947 | F28: =IF(C28>0,$B$18*E28,0) -> 0 | G28: =IF(AND(F28>0,F28>D28),F28-D28,0) -> 0 | H28: =SIN(RADIANS($B$15))*SIN(LAT)+COS(RADIANS($B$15))*COS(LAT)*COS(B28) -> -0.32440649 | I28: =ACOS(H28) -> 1.9011805 | J28: =SIN(RADIANS($B$15))*SIN(LAT)*COS($C$5)-SIN(RADIANS($B$15))*COS(LAT)*SIN($C$5)*COS($C$6)+COS(RADIANS($B$15))*COS(LAT)*COS($C$5)*COS(B28)+COS(RADIANS($B$15))*SIN(LAT)*SIN($C$5)*COS($C$6)*COS(B28)+COS(RADIANS($B$15))*SIN($C$6)*SIN(B28)*SIN($C$5) -> 0.037432688 | K28: =ACOS(J28) -> 1.5333549 | L28: =(G28/H28)*MAX(0,J28) -> 0 | M28: =IF(D28=0,0,1+G28/(D28*H28)) -> 0 | N28: =1/H28 -> -3.0825524 | O28: =D28*N28/1367 -> 0 | P28: =IF($M28=0,0,IF(AND($M28>=$E$5,$M28<$E$6),$F$5,IF(AND($M28>=$E$6,$M28<$E$7),$F$6,IF(AND($M28>=$E$7,$M28<$E$8),$F$7,IF(AND($M28>=$E$8,$M28<$E$9),$F$8,IF(AND($M28>=$E$9,$M28<$E$10),$F$9,IF(AND($M28>=$E$10,$M28<$E$11),$F$10,IF(AND($M28>=$E$11,$M28<$E$12),$F$11,IF($M28>=$E$12,$F$12,"error"))))))))) -> 0 | Q28: =IF($M28=0,0,IF(AND($M28>=$E$5,$M28<$E$6),$G$5,IF(AND($M28>=$E$6,$M28<$E$7),$G$6,IF(AND($M28>=$E$7,$M28<$E$8),$G$7,IF(AND($M28>=$E$8,$M28<$E$9),$G$8,IF(AND($M28>=$E$9,$M28<$E$10),$G$9,IF(AND($M28>=$E$10,$M28<$E$11),$G$10,IF(AND($M28>=$E$11,$M28<$E$12),$G$11,IF($M28>=$E$12,$G$12,"error"))))))))) -> 0 | R28: =IF($M28=0,0,IF(AND($M28>=$E$5,$M28<$E$6),$H$5,IF(AND($M28>=$E$6,$M28<$E$7),$H$6,IF(AND($M28>=$E$7,$M28<$E$8),$H$7,IF(AND($M28>=$E$8,$M28<$E$9),$H$8,IF(AND($M28>=$E$9,$M28<$E$10),$H$9,IF(AND($M28>=$E$10,$M28<$E$11),$H$10,IF(AND($M28>=$E$11,$M28<$E$12),$H$11,IF($M28>=$E$12,$H$12,"error"))))))))) -> 0 | S28: =IF($M28=0,0,IF(AND($M28>=$E$5,$M28<$E$6),$I$5,IF(AND($M28>=$E$6,$M28<$E$7),$I$6,IF(AND($M28>=$E$7,$M28<$E$8),$I$7,IF(AND($M28>=$E$8,$M28<$E$9),$I$8,IF(AND($M28>=$E$9,$M28<$E$10),$I$9,IF(AND($M28>=$E$10,$M28<$E$11),$I$10,IF(AND($M28>=$E$11,$M28<$E$12),$I$11,IF($M28>=$E$12,$I$12,"error"))))))))) -> 0 | T28: =IF($M28=0,0,IF(AND($M28>=$E$5,$M28<$E$6),$J$5,IF(AND($M28>=$E$6,$M28<$E$7),$J$6,IF(AND($M28>=$E$7,$M28<$E$8),$J$7,IF(AND($M28>=$E$8,$M28<$E$9),$J$8,IF(AND($M28>=$E$9,$M28<$E$10),$J$9,IF(AND($M28>=$E$10,$M28<$E$11),$J$10,IF(AND($M28>=$E$11,$M28<$E$12),$J$11,IF($M28>=$E$12,$J$12,"error"))))))))) -> 0 | U28: =IF($M28=0,0,IF(AND($M28>=$E$5,$M28<$E$6),$K$5,IF(AND($M28>=$E$6,$M28<$E$7),$K$6,IF(AND($M28>=$E$7,$M28<$E$8),$K$7,IF(AND($M28>=$E$8,$M28<$E$9),$K$8,IF(AND($M28>=$E$9,$M28<$E$10),$K$9,IF(AND($M28>=$E$10,$M28<$E$11),$K$10,IF(AND($M28>=$E$11,$M28<$E$12),$K$11,IF($M28>=$E$12,$K$12,"error"))))))))) -> 0 | V28: =P28+Q28*O28+R28*I28 -> 0 | W28: =S28+T28*O28+U28*I28 -> 0 | X28: =D28*V28*MAX(0,J28)/H28 -> 0 | Y28: =D28*(0.5*(1+COS($C$5))*(1-V28)+W28*SIN(ABS($C$5))) -> 0 | Z28: =X28+Y28 -> 0 | AA28: =IF(F28>0,F28*$B$7*(1-COS($C$5))/2,0) -> 0 | AB28: =L28+Z28+AA28 -> 0 | AC28: =L28+X28 -> 0
A29: -5.5 | B29: =A29*PI()/12 -> -1.4398966 | C29: =IF($B$16<>0,(PI()/24)*(COS($B29)-COS($B$16))/($B$16*COS($B$16)-SIN($B$16)),0) -> -0.047198339 | D29: =IF(C29>0,$B$17*C29,0) -> 0 | E29: =C29*($B$19+$B$20*COS(B29)) -> -0.027326478 | F29: =IF(C29>0,$B$18*E29,0) -> 0 | G29: =IF(AND(F29>0,F29>D29),F29-D29,0) -> 0 | H29: =SIN(RADIANS($B$15))*SIN(LAT)+COS(RADIANS($B$15))*COS(LAT)*COS(B29) -> -0.13884433 | I29: =ACOS(H29) -> 1.7100907 | J29: =SIN(RADIANS($B$15))*SIN(LAT)*COS($C$5)-SIN(RADIANS($B$15))*COS(LAT)*SIN($C$5)*COS($C$6)+COS(RADIANS($B$15))*COS(LAT)*COS($C$5)*COS(B29)+COS(RADIANS($B$15))*SIN(LAT)*SIN($C$5)*COS($C$6)*COS(B29)+COS(RADIANS($B$15))*SIN($C$6)*SIN(B29)*SIN($C$5) -> 0.25923725 | K29: =ACOS(J29) -> 1.308564 | L29: =(G29/H29)*MAX(0,J29) -> 0 | M29: =IF(D29=0,0,1+G29/(D29*H29)) -> 0 | N29: =1/H29 -> -7.2023105 | O29: =D29*N29/1367 -> 0 | P29: =IF($M29=0,0,IF(AND($M29>=$E$5,$M29<$E$6),$F$5,IF(AND($M29>=$E$6,$M29<$E$7),$F$6,IF(AND($M29>=$E$7,$M29<$E$8),$F$7,IF(AND($M29>=$E$8,$M29<$E$9),$F$8,IF(AND($M29>=$E$9,$M29<$E$10),$F$9,IF(AND($M29>=$E$10,$M29<$E$11),$F$10,IF(AND($M29>=$E$11,$M29<$E$12),$F$11,IF($M29>=$E$12,$F$12,"error"))))))))) -> 0 | Q29: =IF($M29=0,0,IF(AND($M29>=$E$5,$M29<$E$6),$G$5,IF(AND($M29>=$E$6,$M29<$E$7),$G$6,IF(AND($M29>=$E$7,$M29<$E$8),$G$7,IF(AND($M29>=$E$8,$M29<$E$9),$G$8,IF(AND($M29>=$E$9,$M29<$E$10),$G$9,IF(AND($M29>=$E$10,$M29<$E$11),$G$10,IF(AND($M29>=$E$11,$M29<$E$12),$G$11,IF($M29>=$E$12,$G$12,"error"))))))))) -> 0 | R29: =IF($M29=0,0,IF(AND($M29>=$E$5,$M29<$E$6),$H$5,IF(AND($M29>=$E$6,$M29<$E$7),$H$6,IF(AND($M29>=$E$7,$M29<$E$8),$H$7,IF(AND($M29>=$E$8,$M29<$E$9),$H$8,IF(AND($M29>=$E$9,$M29<$E$10),$H$9,IF(AND($M29>=$E$10,$M29<$E$11),$H$10,IF(AND($M29>=$E$11,$M29<$E$12),$H$11,IF($M29>=$E$12,$H$12,"error"))))))))) -> 0 | S29: =IF($M29=0,0,IF(AND($M29>=$E$5,$M29<$E$6),$I$5,IF(AND($M29>=$E$6,$M29<$E$7),$I$6,IF(AND($M29>=$E$7,$M29<$E$8),$I$7,IF(AND($M29>=$E$8,$M29<$E$9),$I$8,IF(AND($M29>=$E$9,$M29<$E$10),$I$9,IF(AND($M29>=$E$10,$M29<$E$11),$I$10,IF(AND($M29>=$E$11,$M29<$E$12),$I$11,IF($M29>=$E$12,$I$12,"error"))))))))) -> 0 | T29: =IF($M29=0,0,IF(AND($M29>=$E$5,$M29<$E$6),$J$5,IF(AND($M29>=$E$6,$M29<$E$7),$J$6,IF(AND($M29>=$E$7,$M29<$E$8),$J$7,IF(AND($M29>=$E$8,$M29<$E$9),$J$8,IF(AND($M29>=$E$9,$M29<$E$10),$J$9,IF(AND($M29>=$E$10,$M29<$E$11),$J$10,IF(AND($M29>=$E$11,$M29<$E$12),$J$11,IF($M29>=$E$12,$J$12,"error"))))))))) -> 0 | U29: =IF($M29=0,0,IF(AND($M29>=$E$5,$M29<$E$6),$K$5,IF(AND($M29>=$E$6,$M29<$E$7),$K$6,IF(AND($M29>=$E$7,$M29<$E$8),$K$7,IF(AND($M29>=$E$8,$M29<$E$9),$K$8,IF(AND($M29>=$E$9,$M29<$E$10),$K$9,IF(AND($M29>=$E$10,$M29<$E$11),$K$10,IF(AND($M29>=$E$11,$M29<$E$12),$K$11,IF($M29>=$E$12,$K$12,"error"))))))))) -> 0 | V29: =P29+Q29*O29+R29*I29 -> 0 | W29: =S29+T29*O29+U29*I29 -> 0 | X29: =D29*V29*MAX(0,J29)/H29 -> 0 | Y29: =D29*(0.5*(1+COS($C$5))*(1-V29)+W29*SIN(ABS($C$5))) -> 0 | Z29: =X29+Y29 -> 0 | AA29: =IF(F29>0,F29*$B$7*(1-COS($C$5))/2,0) -> 0 | AB29: =L29+Z29+AA29 -> 0 | AC29: =L29+X29 -> 0
A30: -4.5 | B30: =A30*PI()/12 -> -1.1780972 | C30: =IF($B$16<>0,(PI()/24)*(COS($B30)-COS($B$16))/($B$16*COS($B$16)-SIN($B$16)),0) -> 0.01373174 | D30: =IF(C30>0,$B$17*C30,0) -> 11.896879 | E30: =C30*($B$19+$B$20*COS(B30)) -> 0.009924228 | F30: =IF(C30>0,$B$18*E30,0) -> 22.527998 | G30: =IF(AND(F30>0,F30>D30),F30-D30,0) -> 10.631118 | H30: =SIN(RADIANS($B$15))*SIN(LAT)+COS(RADIANS($B$15))*COS(LAT)*COS(B30) -> 0.040394944 | I30: =ACOS(H30) -> 1.5303904 | J30: =SIN(RADIANS($B$15))*SIN(LAT)*COS($C$5)-SIN(RADIANS($B$15))*COS(LAT)*SIN($C$5)*COS($C$6)+COS(RADIANS($B$15))*COS(LAT)*COS($C$5)*COS(B30)+COS(RADIANS($B$15))*SIN(LAT)*SIN($C$5)*COS($C$6)*COS(B30)+COS(RADIANS($B$15))*SIN($C$6)*SIN(B30)*SIN($C$5) -> 0.47348401 | K30: =ACOS(J30) -> 1.0775542 | L30: =(G30/H30)*MAX(0,J30) -> 124.61125 | M30: =IF(D30=0,0,1+G30/(D30*H30)) -> 23.121719 | N30: =1/H30 -> 24.755573 | O30: =D30*N30/1367 -> 0.21544555 | P30: =IF($M30=0,0,IF(AND($M30>=$E$5,$M30<$E$6),$F$5,IF(AND($M30>=$E$6,$M30<$E$7),$F$6,IF(AND($M30>=$E$7,$M30<$E$8),$F$7,IF(AND($M30>=$E$8,$M30<$E$9),$F$8,IF(AND($M30>=$E$9,$M30<$E$10),$F$9,IF(AND($M30>=$E$10,$M30<$E$11),$F$10,IF(AND($M30>=$E$11,$M30<$E$12),$F$11,IF($M30>=$E$12,$F$12,"error"))))))))) -> 0.421 | Q30: =IF($M30=0,0,IF(AND($M30>=$E$5,$M30<$E$6),$G$5,IF(AND($M30>=$E$6,$M30<$E$7),$G$6,IF(AND($M30>=$E$7,$M30<$E$8),$G$7,IF(AND($M30>=$E$8,$M30<$E$9),$G$8,IF(AND($M30>=$E$9,$M30<$E$10),$G$9,IF(AND($M30>=$E$10,$M30<$E$11),$G$10,IF(AND($M30>=$E$11,$M30<$E$12),$G$11,IF($M30>=$E$12,$G$12,"error"))))))))) -> -0.661 | R30: =IF($M30=0,0,IF(AND($M30>=$E$5,$M30<$E$6),$H$5,IF(AND($M30>=$E$6,$M30<$E$7),$H$6,IF(AND($M30>=$E$7,$M30<$E$8),$H$7,IF(AND($M30>=$E$8,$M30<$E$9),$H$8,IF(AND($M30>=$E$9,$M30<$E$10),$H$9,IF(AND($M30>=$E$10,$M30<$E$11),$H$10,IF(AND($M30>=$E$11,$M30<$E$12),$H$11,IF($M30>=$E$12,$H$12,"error"))))))))) -> 0.097 | S30: =IF($M30=0,0,IF(AND($M30>=$E$5,$M30<$E$6),$I$5,IF(AND($M30>=$E$6,$M30<$E$7),$I$6,IF(AND($M30>=$E$7,$M30<$E$8),$I$7,IF(AND($M30>=$E$8,$M30<$E$9),$I$8,IF(AND($M30>=$E$9,$M30<$E$10),$I$9,IF(AND($M30>=$E$10,$M30<$E$11),$I$10,IF(AND($M30>=$E$11,$M30<$E$12),$I$11,IF($M30>=$E$12,$I$12,"error"))))))))) -> 0.119 | T30: =IF($M30=0,0,IF(AND($M30>=$E$5,$M30<$E$6),$J$5,IF(AND($M30>=$E$6,$M30<$E$7),$J$6,IF(AND($M30>=$E$7,$M30<$E$8),$J$7,IF(AND($M30>=$E$8,$M30<$E$9),$J$8,IF(AND($M30>=$E$9,$M30<$E$10),$J$9,IF(AND($M30>=$E$10,$M30<$E$11),$J$10,IF(AND($M30>=$E$11,$M30<$E$12),$J$11,IF($M30>=$E$12,$J$12,"error"))))))))) -> -2.125 | U30: =IF($M30=0,0,IF(AND($M30>=$E$5,$M30<$E$6),$K$5,IF(AND($M30>=$E$6,$M30<$E$7),$K$6,IF(AND($M30>=$E$7,$M30<$E$8),$K$7,IF(AND($M30>=$E$8,$M30<$E$9),$K$8,IF(AND($M30>=$E$9,$M30<$E$10),$K$9,IF(AND($M30>=$E$10,$M30<$E$11),$K$10,IF(AND($M30>=$E$11,$M30<$E$12),$K$11,IF($M30>=$E$12,$K$12,"error"))))))))) -> 0.446 | V30: =P30+Q30*O30+R30*I30 -> 0.42703836 | W30: =S30+T30*O30+U30*I30 -> 0.34373232 | X30: =D30*V30*MAX(0,J30)/H30 -> 59.549518 | Y30: =D30*(0.5*(1+COS($C$5))*(1-V30)+W30*SIN(ABS($C$5))) -> 8.5548095 | Z30: =X30+Y30 -> 68.104327 | AA30: =IF(F30>0,F30*$B$7*(1-COS($C$5))/2,0) -> 1.3007254 | AB30: =L30+Z30+AA30 -> 194.0163 | AC30: =L30+X30 -> 184.16077
A31: -3.5 | B31: =A31*PI()/12 -> -0.91629786 | C31: =IF($B$16<>0,(PI()/24)*(COS($B31)-COS($B$16))/($B$16*COS($B$16)-SIN($B$16)),0) -> 0.068360153 | D31: =IF(C31>0,$B$17*C31,0) -> 59.225744 | E31: =C31*($B$19+$B$20*COS(B31)) -> 0.058215857 | F31: =IF(C31>0,$B$18*E31,0) -> 132.15 | G31: =IF(AND(F31>0,F31>D31),F31-D31,0) -> 72.924252 | H31: =SIN(RADIANS($B$15))*SIN(LAT)+COS(RADIANS($B$15))*COS(LAT)*COS(B31) -> 0.20109648 | I31: =ACOS(H31) -> 1.3683192 | J31: =SIN(RADIANS($B$15))*SIN(LAT)*COS($C$5)-SIN(RADIANS($B$15))*COS(LAT)*SIN($C$5)*COS($C$6)+COS(RADIANS($B$15))*COS(LAT)*COS($C$5)*COS(B31)+COS(RADIANS($B$15))*SIN(LAT)*SIN($C$5)*COS($C$6)*COS(B31)+COS(RADIANS($B$15))*SIN($C$6)*SIN(B31)*SIN($C$5) -> 0.6655724 | K31: =ACOS(J31) -> 0.84253582 | L31: =(G31/H31)*MAX(0,J31) -> 241.35862 | M31: =IF(D31=0,0,1+G31/(D31*H31)) -> 7.1228974 | N31: =1/H31 -> 4.9727373 | O31: =D31*N31/1367 -> 0.21544555 | P31: =IF($M31=0,0,IF(AND($M31>=$E$5,$M31<$E$6),$F$5,IF(AND($M31>=$E$6,$M31<$E$7),$F$6,IF(AND($M31>=$E$7,$M31<$E$8),$F$7,IF(AND($M31>=$E$8,$M31<$E$9),$F$8,IF(AND($M31>=$E$9,$M31<$E$10),$F$9,IF(AND($M31>=$E$10,$M31<$E$11),$F$10,IF(AND($M31>=$E$11,$M31<$E$12),$F$11,IF($M31>=$E$12,$F$12,"error"))))))))) -> 0.734 | Q31: =IF($M31=0,0,IF(AND($M31>=$E$5,$M31<$E$6),$G$5,IF(AND($M31>=$E$6,$M31<$E$7),$G$6,IF(AND($M31>=$E$7,$M31<$E$8),$G$7,IF(AND($M31>=$E$8,$M31<$E$9),$G$8,IF(AND($M31>=$E$9,$M31<$E$10),$G$9,IF(AND($M31>=$E$10,$M31<$E$11),$G$10,IF(AND($M31>=$E$11,$M31<$E$12),$G$11,IF($M31>=$E$12,$G$12,"error"))))))))) -> -0.073 | R31: =IF($M31=0,0,IF(AND($M31>=$E$5,$M31<$E$6),$H$5,IF(AND($M31>=$E$6,$M31<$E$7),$H$6,IF(AND($M31>=$E$7,$M31<$E$8),$H$7,IF(AND($M31>=$E$8,$M31<$E$9),$H$8,IF(AND($M31>=$E$9,$M31<$E$10),$H$9,IF(AND($M31>=$E$10,$M31<$E$11),$H$10,IF(AND($M31>=$E$11,$M31<$E$12),$H$11,IF($M31>=$E$12,$H$12,"error"))))))))) -> -0.228 | S31: =IF($M31=0,0,IF(AND($M31>=$E$5,$M31<$E$6),$I$5,IF(AND($M31>=$E$6,$M31<$E$7),$I$6,IF(AND($M31>=$E$7,$M31<$E$8),$I$7,IF(AND($M31>=$E$8,$M31<$E$9),$I$8,IF(AND($M31>=$E$9,$M31<$E$10),$I$9,IF(AND($M31>=$E$10,$M31<$E$11),$I$10,IF(AND($M31>=$E$11,$M31<$E$12),$I$11,IF($M31>=$E$12,$I$12,"error"))))))))) -> 0.231 | T31: =IF($M31=0,0,IF(AND($M31>=$E$5,$M31<$E$6),$J$5,IF(AND($M31>=$E$6,$M31<$E$7),$J$6,IF(AND($M31>=$E$7,$M31<$E$8),$J$7,IF(AND($M31>=$E$8,$M31<$E$9),$J$8,IF(AND($M31>=$E$9,$M31<$E$10),$J$9,IF(AND($M31>=$E$10,$M31<$E$11),$J$10,IF(AND($M31>=$E$11,$M31<$E$12),$J$11,IF($M31>=$E$12,$J$12,"error"))))))))) -> -1.18 | U31: =IF($M31=0,0,IF(AND($M31>=$E$5,$M31<$E$6),$K$5,IF(AND($M31>=$E$6,$M31<$E$7),$K$6,IF(AND($M31>=$E$7,$M31<$E$8),$K$7,IF(AND($M31>=$E$8,$M31<$E$9),$K$8,IF(AND($M31>=$E$9,$M31<$E$10),$K$9,IF(AND($M31>=$E$10,$M31<$E$11),$K$10,IF(AND($M31>=$E$11,$M31<$E$12),$K$11,IF($M31>=$E$12,$K$12,"error"))))))))) -> 0.199 | V31: =P31+Q31*O31+R31*I31 -> 0.4062957 | W31: =S31+T31*O31+U31*I31 -> 0.24906977 | X31: =D31*V31*MAX(0,J31)/H31 -> 79.64226 | Y31: =D31*(0.5*(1+COS($C$5))*(1-V31)+W31*SIN(ABS($C$5))) -> 38.38072 | Z31: =X31+Y31 -> 118.02298 | AA31: =IF(F31>0,F31*$B$7*(1-COS($C$5))/2,0) -> 7.6300994 | AB31: =L31+Z31+AA31 -> 367.0117 | AC31: =L31+X31 -> 321.00088
A32: -2.5 | B32: =A32*PI()/12 -> -0.65449847 | C32: =IF($B$16<>0,(PI()/24)*(COS($B32)-COS($B$16))/($B$16*COS($B$16)-SIN($B$16)),0) -> 0.11296407 | D32: =IF(C32>0,$B$17*C32,0) -> 97.8696 | E32: =C32*($B$19+$B$20*COS(B32)) -> 0.1080883 | F32: =IF(C32>0,$B$18*E32,0) -> 245.36044 | G32: =IF(AND(F32>0,F32>D32),F32-D32,0) -> 147.49084 | H32: =SIN(RADIANS($B$15))*SIN(LAT)+COS(RADIANS($B$15))*COS(LAT)*COS(B32) -> 0.33230874 | I32: =ACOS(H32) -> 1.232046 | J32: =SIN(RADIANS($B$15))*SIN(LAT)*COS($C$5)-SIN(RADIANS($B$15))*COS(LAT)*SIN($C$5)*COS($C$6)+COS(RADIANS($B$15))*COS(LAT)*COS($C$5)*COS(B32)+COS(RADIANS($B$15))*SIN(LAT)*SIN($C$5)*COS($C$6)*COS(B32)+COS(RADIANS($B$15))*SIN($C$6)*SIN(B32)*SIN($C$5) -> 0.82241191 | K32: =ACOS(J32) -> 0.60515855 | L32: =(G32/H32)*MAX(0,J32) -> 365.01665 | M32: =IF(D32=0,0,1+G32/(D32*H32)) -> 5.5349811 | N32: =1/H32 -> 3.0092497 | O32: =D32*N32/1367 -> 0.21544555 | P32: =IF($M32=0,0,IF(AND($M32>=$E$5,$M32<$E$6),$F$5,IF(AND($M32>=$E$6,$M32<$E$7),$F$6,IF(AND($M32>=$E$7,$M32<$E$8),$F$7,IF(AND($M32>=$E$8,$M32<$E$9),$F$8,IF(AND($M32>=$E$9,$M32<$E$10),$F$9,IF(AND($M32>=$E$10,$M32<$E$11),$F$10,IF(AND($M32>=$E$11,$M32<$E$12),$F$11,IF($M32>=$E$12,$F$12,"error"))))))))) -> 0.857 | Q32: =IF($M32=0,0,IF(AND($M32>=$E$5,$M32<$E$6),$G$5,IF(AND($M32>=$E$6,$M32<$E$7),$G$6,IF(AND($M32>=$E$7,$M32<$E$8),$G$7,IF(AND($M32>=$E$8,$M32<$E$9),$G$8,IF(AND($M32>=$E$9,$M32<$E$10),$G$9,IF(AND($M32>=$E$10,$M32<$E$11),$G$10,IF(AND($M32>=$E$11,$M32<$E$12),$G$11,IF($M32>=$E$12,$G$12,"error"))))))))) -> -0.37 | R32: =IF($M32=0,0,IF(AND($M32>=$E$5,$M32<$E$6),$H$5,IF(AND($M32>=$E$6,$M32<$E$7),$H$6,IF(AND($M32>=$E$7,$M32<$E$8),$H$7,IF(AND($M32>=$E$8,$M32<$E$9),$H$8,IF(AND($M32>=$E$9,$M32<$E$10),$H$9,IF(AND($M32>=$E$10,$M32<$E$11),$H$10,IF(AND($M32>=$E$11,$M32<$E$12),$H$11,IF($M32>=$E$12,$H$12,"error"))))))))) -> -0.279 | S32: =IF($M32=0,0,IF(AND($M32>=$E$5,$M32<$E$6),$I$5,IF(AND($M32>=$E$6,$M32<$E$7),$I$6,IF(AND($M32>=$E$7,$M32<$E$8),$I$7,IF(AND($M32>=$E$8,$M32<$E$9),$I$8,IF(AND($M32>=$E$9,$M32<$E$10),$I$9,IF(AND($M32>=$E$10,$M32<$E$11),$I$10,IF(AND($M32>=$E$11,$M32<$E$12),$I$11,IF($M32>=$E$12,$I$12,"error"))))))))) -> 0.267 | T32: =IF($M32=0,0,IF(AND($M32>=$E$5,$M32<$E$6),$J$5,IF(AND($M32>=$E$6,$M32<$E$7),$J$6,IF(AND($M32>=$E$7,$M32<$E$8),$J$7,IF(AND($M32>=$E$8,$M32<$E$9),$J$8,IF(AND($M32>=$E$9,$M32<$E$10),$J$9,IF(AND($M32>=$E$10,$M32<$E$11),$J$10,IF(AND($M32>=$E$11,$M32<$E$12),$J$11,IF($M32>=$E$12,$J$12,"error"))))))))) -> -0.792 | U32: =IF($M32=0,0,IF(AND($M32>=$E$5,$M32<$E$6),$K$5,IF(AND($M32>=$E$6,$M32<$E$7),$K$6,IF(AND($M32>=$E$7,$M32<$E$8),$K$7,IF(AND($M32>=$E$8,$M32<$E$9),$K$8,IF(AND($M32>=$E$9,$M32<$E$10),$K$9,IF(AND($M32>=$E$10,$M32<$E$11),$K$10,IF(AND($M32>=$E$11,$M32<$E$12),$K$11,IF($M32>=$E$12,$K$12,"error"))))))))) -> 0.076 | V32: =P32+Q32*O32+R32*I32 -> 0.43354433 | W32: =S32+T32*O32+U32*I32 -> 0.19000262 | X32: =D32*V32*MAX(0,J32)/H32 -> 105.00958 | Y32: =D32*(0.5*(1+COS($C$5))*(1-V32)+W32*SIN(ABS($C$5))) -> 56.287346 | Z32: =X32+Y32 -> 161.29693 | AA32: =IF(F32>0,F32*$B$7*(1-COS($C$5))/2,0) -> 14.166664 | AB32: =L32+Z32+AA32 -> 540.48025 | AC32: =L32+X32 -> 470.02624
A33: -1.5 | B33: =A33*PI()/12 -> -0.39269908 | C33: =IF($B$16<>0,(PI()/24)*(COS($B33)-COS($B$16))/($B$16*COS($B$16)-SIN($B$16)),0) -> 0.1445038 | D33: =IF(C33>0,$B$17*C33,0) -> 125.19493 | E33: =C33*($B$19+$B$20*COS(B33)) -> 0.14901935 | F33: =IF(C33>0,$B$18*E33,0) -> 338.27393 | G33: =IF(AND(F33>0,F33>D33),F33-D33,0) -> 213.079 | H33: =SIN(RADIANS($B$15))*SIN(LAT)+COS(RADIANS($B$15))*COS(LAT)*COS(B33) -> 0.42508982 | I33: =ACOS(H33) -> 1.1317352 | J33: =SIN(RADIANS($B$15))*SIN(LAT)*COS($C$5)-SIN(RADIANS($B$15))*COS(LAT)*SIN($C$5)*COS($C$6)+COS(RADIANS($B$15))*COS(LAT)*COS($C$5)*COS(B33)+COS(RADIANS($B$15))*SIN(LAT)*SIN($C$5)*COS($C$6)*COS(B33)+COS(RADIANS($B$15))*SIN($C$6)*SIN(B33)*SIN($C$5) -> 0.93331419 | K33: =ACOS(J33) -> 0.36726134 | L33: =(G33/H33)*MAX(0,J33) -> 467.82973 | M33: =IF(D33=0,0,1+G33/(D33*H33)) -> 5.0038076 | N33: =1/H33 -> 2.352444 | O33: =D33*N33/1367 -> 0.21544555 | P33: =IF($M33=0,0,IF(AND($M33>=$E$5,$M33<$E$6),$F$5,IF(AND($M33>=$E$6,$M33<$E$7),$F$6,IF(AND($M33>=$E$7,$M33<$E$8),$F$7,IF(AND($M33>=$E$8,$M33<$E$9),$F$8,IF(AND($M33>=$E$9,$M33<$E$10),$F$9,IF(AND($M33>=$E$10,$M33<$E$11),$F$10,IF(AND($M33>=$E$11,$M33<$E$12),$F$11,IF($M33>=$E$12,$F$12,"error"))))))))) -> 0.857 | Q33: =IF($M33=0,0,IF(AND($M33>=$E$5,$M33<$E$6),$G$5,IF(AND($M33>=$E$6,$M33<$E$7),$G$6,IF(AND($M33>=$E$7,$M33<$E$8),$G$7,IF(AND($M33>=$E$8,$M33<$E$9),$G$8,IF(AND($M33>=$E$9,$M33<$E$10),$G$9,IF(AND($M33>=$E$10,$M33<$E$11),$G$10,IF(AND($M33>=$E$11,$M33<$E$12),$G$11,IF($M33>=$E$12,$G$12,"error"))))))))) -> -0.37 | R33: =IF($M33=0,0,IF(AND($M33>=$E$5,$M33<$E$6),$H$5,IF(AND($M33>=$E$6,$M33<$E$7),$H$6,IF(AND($M33>=$E$7,$M33<$E$8),$H$7,IF(AND($M33>=$E$8,$M33<$E$9),$H$8,IF(AND($M33>=$E$9,$M33<$E$10),$H$9,IF(AND($M33>=$E$10,$M33<$E$11),$H$10,IF(AND($M33>=$E$11,$M33<$E$12),$H$11,IF($M33>=$E$12,$H$12,"error"))))))))) -> -0.279 | S33: =IF($M33=0,0,IF(AND($M33>=$E$5,$M33<$E$6),$I$5,IF(AND($M33>=$E$6,$M33<$E$7),$I$6,IF(AND($M33>=$E$7,$M33<$E$8),$I$7,IF(AND($M33>=$E$8,$M33<$E$9),$I$8,IF(AND($M33>=$E$9,$M33<$E$10),$I$9,IF(AND($M33>=$E$10,$M33<$E$11),$I$10,IF(AND($M33>=$E$11,$M33<$E$12),$I$11,IF($M33>=$E$12,$I$12,"error"))))))))) -> 0.267 | T33: =IF($M33=0,0,IF(AND($M33>=$E$5,$M33<$E$6),$J$5,IF(AND($M33>=$E$6,$M33<$E$7),$J$6,IF(AND($M33>=$E$7,$M33<$E$8),$J$7,IF(AND($M33>=$E$8,$M33<$E$9),$J$8,IF(AND($M33>=$E$9,$M33<$E$10),$J$9,IF(AND($M33>=$E$10,$M33<$E$11),$J$10,IF(AND($M33>=$E$11,$M33<$E$12),$J$11,IF($M33>=$E$12,$J$12,"error"))))))))) -> -0.792 | U33: =IF($M33=0,0,IF(AND($M33>=$E$5,$M33<$E$6),$K$5,IF(AND($M33>=$E$6,$M33<$E$7),$K$6,IF(AND($M33>=$E$7,$M33<$E$8),$K$7,IF(AND($M33>=$E$8,$M33<$E$9),$K$8,IF(AND($M33>=$E$9,$M33<$E$10),$K$9,IF(AND($M33>=$E$10,$M33<$E$11),$K$10,IF(AND($M33>=$E$11,$M33<$E$12),$K$11,IF($M33>=$E$12,$K$12,"error"))))))))) -> 0.076 | V33: =P33+Q33*O33+R33*I33 -> 0.46153102 | W33: =S33+T33*O33+U33*I33 -> 0.182379 | X33: =D33*V33*MAX(0,J33)/H33 -> 126.86295 | Y33: =D33*(0.5*(1+COS($C$5))*(1-V33)+W33*SIN(ABS($C$5))) -> 68.645559 | Z33: =X33+Y33 -> 195.50851 | AA33: =IF(F33>0,F33*$B$7*(1-COS($C$5))/2,0) -> 19.531319 | AB33: =L33+Z33+AA33 -> 682.86956 | AC33: =L33+X33 -> 594.69268
