Workbook
Name Apalancamiento: [1]INPUTS!#REF!
Name Apalancamiento: [1]INPUTS!#REF!
Name Name: [2]Cuadro_de_Mandos!$D$7
Name SFDeuda: [1]INPUTS!#REF!
Name SFDeuda: [1]INPUTS!#REF!

Sheet Caso planta PV agro
F2: Sistema fotovoltaico en cubierta
B3: Potencia sistema fotovoltaico | E3: kW | F3: 239 | G3: Dimensionamiento realizado en función del espacio disponible, potencias unitarias de módulos, configuración de planta, características estructurales, etc.
F4: Resultados obtenidos
B6: Producción anual fotovoltaica | E6: MWhe | F6: 345.13547 | G6: Obtenido de las simulaciones con PVSYST para esta planta (considerando orientación, selección de módulos, inversores, pérdidas, irradiación, etc.)
B7: Producción anual fotovoltaica autoconsumida | E7: MWhe | F7: 339.60862 | G7: Obtenido tras la comparación hora a hora con la demanda de la instalación industrial
B8: Factor de degradación anual | E8: % | F8: 0.4
B9: Ahorro término energía | E9: €/año | F9: 25920.857 | G9: Corresponde con el coste de la energía eléctrica que hubiera tenido el industrial si la hubiera importado de la red (suma hora a hora anual)
B10: Ahorro impuesto eléctrico | E10: €/año | F10: 1325.2547 | G10: Corresponde con el coste asociado al impuesto eléctrico (5,11269632%) que hubiera tenido el industrial si la hubiera importado de la red
B11: Remuneración por exportación | E11: €/año | F11: 241.90734 | G11: Volumen exportado (MWh) por precio de venta en las horas de exportación correspondientes (€/MWh)
B12: Peaje de acceso a la generación vertida a red | E12: €/año | F12: =(F6-F7)*0.28 -> 1.5475184 | G12: Mutiplicando la energía excedentaria vertida a la red por el coste de colocación (0,28 €/MWh)
B13: Impuesto a la generación eléctrica | E13: €/año | F13: =F11*0.07 -> 16.933514 | G13: Corresponde con el 7% del ingreso percibido por la energía colocada en la red
B14: Total ahorro variable | E14: €/año | F14: =SUM(F9:F11)-SUM(F12:F13) -> 27469.538 | G14: Suma de los anteriores
B15: Mantenimiento (OPEX) | E15: €/año | F15: =F3*10 -> 2390 | G15: OPEX unitario = 10 EUR/kW
B16: Balance ahorro | E16: €/año | F16: =F14-F15 -> 25079.538 | G16: EBITDA hipotético año 0
B18: Relación de inversiones
B19: Refuerzo estructural de la cubierta | E19: € | F19: 30000 | G19: Estimación para este caso
B20: Suministro, ingeniería, montaje y dirección de obra del sistema fotovoltaico | E20: € | F20: =F3*G20 -> 215100 | G20: 900 | H20: EUR/kWp | I20: Referencia coste inversión de este tipo de instalaciones
B21: Total | E21: € | F21: =+SUM(F19:F20) -> 245100 | G21: =F21/F3 -> 1025.523 | H21: EUR/kWp | I21: Incluyendo coste de refuerzo estructural en este caso
E23: PRSI | F23: =+F21/F16 -> 9.7729074
I25: 2026 | J25: 2027 | K25: 2028 | L25: 2029 | M25: 2030 | N25: 2031 | O25: 2032 | P25: 2033 | Q25: 2034 | R25: 2035 | S25: 2036 | T25: 2037 | U25: 2038 | V25: 2039 | W25: 2040 | X25: 2041 | Y25: 2042 | Z25: 2043 | AA25: 2044 | AB25: 2045
H26: IPC | I26: 0.019 | J26: 0.019 | K26: 0.02 | L26: 0.02 | M26: 0.02 | N26: 0.02 | O26: 0.0201 | P26: 0.0201 | Q26: 0.0201 | R26: 0.0201 | S26: 0.0201 | T26: 0.0201 | U26: 0.0201 | V26: 0.0201 | W26: 0.0201 | X26: 0.0201 | Y26: 0.0201 | Z26: 0.0201 | AA26: 0.0201 | AB26: 0.0201
I28: Senda aumento precio energía importada | J28: EU | K28: CARG 2020/2030 | L28: 0.05
K29: CARG 2030/2040 | L29: 0.03
H31: 2025 | I31: 2026 | J31: 2027 | K31: 2028 | L31: 2029 | M31: 2030 | N31: 2031 | O31: 2032 | P31: 2033 | Q31: 2034 | R31: 2035 | S31: 2036 | T31: 2037 | U31: 2038 | V31: 2039 | W31: 2040 | X31: 2041 | Y31: 2042 | Z31: 2043 | AA31: 2044 | AB31: 2045
H32: 0 | I32: 1 | J32: 2 | K32: 3 | L32: 4 | M32: 5 | N32: 6 | O32: 7 | P32: 8 | Q32: 9 | R32: 10 | S32: 11 | T32: 12 | U32: 13 | V32: 14 | W32: 15 | X32: 16 | Y32: 17 | Z32: 18 | AA32: 19 | AB32: 20
G33: Senda de degradación | I33: =0.98-($F$8/100)*(I32-1) -> 0.98 | J33: =0.98-($F$8/100)*(J32-1) -> 0.976 | K33: =0.98-($F$8/100)*(K32-1) -> 0.972 | L33: =0.98-($F$8/100)*(L32-1) -> 0.968 | M33: =0.98-($F$8/100)*(M32-1) -> 0.964 | N33: =0.98-($F$8/100)*(N32-1) -> 0.96 | O33: =0.98-($F$8/100)*(O32-1) -> 0.956 | P33: =0.98-($F$8/100)*(P32-1) -> 0.952 | ... AB33: =0.98-($F$8/100)*(AB32-1) -> 0.904
G34: Ingresos | I34: =F14*(1+$L$28)*I33 -> 28266.154 | J34: =I34*(1+$L$28)*J33 -> 28967.155 | K34: =J34*(1+$L$28)*K33 -> 29563.878 | L34: =K34*(1+$L$28)*L33 -> 30048.726 | M34: =L34*(1+$L$28)*M33 -> 30415.32 | N34: =M34*(1+$L$28)*N33 -> 30658.643 | O34: =N34*(1+$L$28)*O33 -> 30775.146 | P34: =O34*(1+$L$29)*P33 -> 30176.877 | Q34: =P34*(1+$L$29)*Q33 -> 29465.91 | R34: =Q34*(1+$L$29)*R33 -> 28650.293 | S34: =R34*(1+$L$29)*S33 -> 27739.214 | T34: =S34*(1+$L$29)*T33 -> 26742.821 | U34: =T34*(1+$L$29)*U33 -> 25672.039 | V34: =U34*(1+$L$29)*V33 -> 24538.362 | W34: =V34*(1+$L$29)*W33 -> 23353.65 | ... AB34: =AA34*(1+$L$29)*AB33 -> 17079.427
G35: Gastos | I35: =F15*(1+I26) -> 2435.41 | J35: =I35*(1+J26) -> 2481.6828 | K35: =J35*(1+K26) -> 2531.3164 | L35: =K35*(1+L26) -> 2581.9428 | M35: =L35*(1+M26) -> 2633.5816 | N35: =M35*(1+N26) -> 2686.2533 | O35: =N35*(1+O26) -> 2740.247 | P35: =O35*(1+P26) -> 2795.3259 | Q35: =P35*(1+Q26) -> 2851.512 | ... AB35: =AA35*(1+AB26) -> 3549.3222
G36: EBITDA | I36: =I34-I35 -> 25830.744 | J36: =J34-J35 -> 26485.472 | K36: =K34-K35 -> 27032.562 | L36: =L34-L35 -> 27466.783 | M36: =M34-M35 -> 27781.739 | N36: =N34-N35 -> 27972.39 | O36: =O34-O35 -> 28034.899 | P36: =P34-P35 -> 27381.551 | ... AB36: =AB34-AB35 -> 13530.105
G38: Amortización lineal 20 años | I38: =$F$21/20 -> 12255 | J38: =$F$21/20 -> 12255 | K38: =$F$21/20 -> 12255 | L38: =$F$21/20 -> 12255 | M38: =$F$21/20 -> 12255 | N38: =$F$21/20 -> 12255 | O38: =$F$21/20 -> 12255 | P38: =$F$21/20 -> 12255 | ... AB38: =$F$21/20 -> 12255
G40: EBIT | I40: =I36-I38 -> 13575.744 | J40: =J36-J38 -> 14230.472 | K40: =K36-K38 -> 14777.562 | L40: =L36-L38 -> 15211.783 | M40: =M36-M38 -> 15526.739 | N40: =N36-N38 -> 15717.39 | O40: =O36-O38 -> 15779.899 | P40: =P36-P38 -> 15126.551 | ... AB40: =AB36-AB38 -> 1275.105
G42: Impuesto sociedades (25%) | I42: =0.25*I40 -> 3393.9361 | J42: =0.25*J40 -> 3557.618 | K42: =0.25*K40 -> 3694.3905 | L42: =0.25*L40 -> 3802.9458 | M42: =0.25*M40 -> 3881.6847 | N42: =0.25*N40 -> 3929.3474 | O42: =0.25*O40 -> 3944.9747 | P42: =0.25*P40 -> 3781.6378 | ... AA42: =0.25*AA40 -> 652.12464 | AB42: 0
G44: BDI | I44: =I40-I42 -> 10181.808 | J44: =J40-J42 -> 10672.854 | K44: =K40-K42 -> 11083.171 | L44: =L40-L42 -> 11408.837 | M44: =M40-M42 -> 11645.054 | N44: =N40-N42 -> 11788.042 | O44: =O40-O42 -> 11834.924 | P44: =P40-P42 -> 11344.913 | ... AB44: =AB40-AB42 -> 1275.105
G46: FCF | H46: =-F21 -> -245100 | I46: =I44+I38 -> 22436.808 | J46: =J44+J38 -> 22927.854 | K46: =K44+K38 -> 23338.171 | L46: =L44+L38 -> 23663.837 | M46: =M44+M38 -> 23900.054 | N46: =N44+N38 -> 24043.042 | O46: =O44+O38 -> 24089.924 | P46: =P44+P38 -> 23599.913 | ... AB46: =AB44+AB38 -> 13530.105
G47: FC agregado | H47: =H46 -> -245100 | I47: =H47+I46 -> -222663.19 | J47: =I47+J46 -> -199735.34 | K47: =J47+K46 -> -176397.17 | L47: =K47+L46 -> -152733.33 | M47: =L47+M46 -> -128833.27 | N47: =M47+N46 -> -104790.23 | O47: =N47+O46 -> -80700.309 | P47: =O47+P46 -> -57100.395 | ... AB47: =AA47+AB46 -> 164438.7
F49: WACC | G49: ='Estructura capital'!F19 -> 0.0474525
F50: TIR | G50: =IRR(H46:AB46) -> 0.060425622
F51: VAN | G51: =NPV(G49,I46:AB46)+H46 -> 25644.645
F54: Ahorro CO2
F56: Factor emisión mix (REE, 2018) | G56: 0.246 | H56: tCO2/MWhe
...

Sheet Estructura capital
B2: Procedimiento de cálculo del coste de capital
E4: E | F4: 0.7 | G4: Endeudamiento
E5: A | F5: =F4/(1-F4) -> 2.3333333 | G5: Apalancamiento
E7: Tf | F7: 0.25 | G7: Tasa fiscal = Impuesto sociedades España
E8: Beta desapalancada | F8: 0.67 | G8: Valor del riesgo intrínseco al activo | K8: http://pages.stern.nyu.edu/~adamodar/New_Home_Page/datafile/Betas.html | M8: (Prof. Damodaran)
E9: Beta apalancada | F9: =F8*(1+((1-F7)*F5)) -> 1.8425 | G9: Apalancamiento de Beta. Inclusión del riesgo financiero
E11: Tlr | F11: 0.0329 | G11: Ref. rentabilidad deuda pública | J11: https://www.bde.es/webbde/es/estadis/infoest/si_1_2.pdf
E12: Prm | F12: 0.03 | G12: Lo que el inversor adicionalmente exige a los fondos propios que introduce en el proyecto
E13: Ke | F13: =(F11+F9*F12) -> 0.088175 | G13: Componente del WACC asociada a los fondos propios (Equity en inglés)
E15: Cdm | F15: 0.04 | G15: Prima exigida por el agente que aporta la deuda (banco, fondo de inversión) para entrar en el proyecto
E16: Kd | F16: =F15*(1-F7) -> 0.03 | G16: Componente del WACC asociada a la deuda (Debt en inglés)
E19: WACC | F19: =(F13*(1-F4)+F16*F4) -> 0.0474525 | G19: Tasa de descuento a considerar. Valor mínimo que exigimos a un proyecto, de acuerdo con esta estructura de capital, para invertir en el mismo

Sheet Caso planta PV auto
B2: Potencia (MWp) | C2: 7.63 | E2: Degradación | F2: Según senda
I3: Tipo impositivo (%) | J3: 0.25 | N3: *Cálculo VR si distinto de cero
B4: Factor de capacidad (%) | C4: =C5/8760 -> 0.22716895 | I4: Peaje incorporación a red (€/MWh) | J4: 0 | K4: Sin valorización excedentes
B5: HEPC (kWh/kWp/año) | C5: 1990 | E5: % entregado | F5: 0.94948077 | I5: Impuesto GEN EE (%) | J5: 0 | K5: Sin valorización excedentes | N5: (1) Valor en libros = | O5: CAPEX - valor ya amortizado
N6: (2) Valor de mercado = | O6: f (mercado)
I7: PPA (€/MWh) | J7: 40
B8: CAPEX (€) | C8: =C2*0.66*1000000 -> 5035800 | N8: (3) Escudo fiscal = | O8: ((1) - (2)) * tipo impositivo
B9: OPEX anual año 0 (€) | C9: =11500*C2 -> 87745 | D9: Evolución con inflación
N10: Valor residual = | O10: (2) + (3)
B11: Vida contrato (años) | C11: 20 | N11: (a sumar en los flujos el último año del proyecto)
B12: Vida útil (años) | C12: 30 | D12: *Se amortiza toda la instalación en la vida útil del contrato (VR=0)
C14: Construcción 2025 | D14: 2026 | E14: 2027 | F14: 2028 | G14: 2029 | H14: 2030 | I14: 2031 | J14: 2032 | K14: 2033 | L14: 2034 | M14: 2035 | N14: 2036 | O14: 2037 | P14: 2038 | Q14: 2039 | R14: 2040 | S14: 2041 | T14: 2042 | U14: 2043 | V14: 2044 | W14: 2045
B15: Degradación | D15: ='Caso planta PV agro'!I33 -> 0.98 | E15: ='Caso planta PV agro'!J33 -> 0.976 | F15: ='Caso planta PV agro'!K33 -> 0.972 | G15: ='Caso planta PV agro'!L33 -> 0.968 | H15: ='Caso planta PV agro'!M33 -> 0.964 | I15: ='Caso planta PV agro'!N33 -> 0.96 | J15: ='Caso planta PV agro'!O33 -> 0.956 | K15: ='Caso planta PV agro'!P33 -> 0.952 | ... W15: ='Caso planta PV agro'!AB33 -> 0.904
B16: Producción entregada (MWhe) | D16: =$C$2*$C$5*D15*$F$5 -> 14128.299 | E16: =$C$2*$C$5*E15*$F$5 -> 14070.632 | F16: =$C$2*$C$5*F15*$F$5 -> 14012.966 | G16: =$C$2*$C$5*G15*$F$5 -> 13955.299 | H16: =$C$2*$C$5*H15*$F$5 -> 13897.632 | I16: =$C$2*$C$5*I15*$F$5 -> 13839.966 | J16: =$C$2*$C$5*J15*$F$5 -> 13782.299 | K16: =$C$2*$C$5*K15*$F$5 -> 13724.633 | ... W16: =$C$2*$C$5*W15*$F$5 -> 13032.635
B17: OPEX anual (€) | D17: =C9*(1+D59) -> 89412.155 | E17: =D17*(1+E59) -> 91110.986 | F17: =E17*(1+F59) -> 92933.206 | G17: =F17*(1+G59) -> 94791.87 | H17: =G17*(1+H59) -> 96687.707 | I17: =H17*(1+I59) -> 98621.461 | J17: =I17*(1+J59) -> 100603.75 | K17: =J17*(1+K59) -> 102625.89 | L17: =K17*(1+L59) -> 104688.67 | ... W17: =V17*(1+W59) -> 130307.65
B19: Ingresos (€) | D19: =D16*$J$7 -> 565131.94 | E19: =E16*$J$7 -> 562825.28 | F19: =F16*$J$7 -> 560518.62 | G19: =G16*$J$7 -> 558211.96 | H19: =H16*$J$7 -> 555905.3 | I19: =I16*$J$7 -> 553598.64 | J19: =J16*$J$7 -> 551291.98 | K19: =K16*$J$7 -> 548985.32 | ... W19: =W16*$J$7 -> 521305.38
B20: OPEX planta (€) | D20: =D17 -> 89412.155 | E20: =E17 -> 91110.986 | F20: =F17 -> 92933.206 | G20: =G17 -> 94791.87 | H20: =H17 -> 96687.707 | I20: =I17 -> 98621.461 | J20: =J17 -> 100603.75 | K20: =K17 -> 102625.89 | ... W20: =W17 -> 130307.65
B21: OPEX peaje red (€) | D21: =D16*$J$4 -> 0 | E21: =E16*$J$4 -> 0 | F21: =F16*$J$4 -> 0 | G21: =G16*$J$4 -> 0 | H21: =H16*$J$4 -> 0 | I21: =I16*$J$4 -> 0 | J21: =J16*$J$4 -> 0 | K21: =K16*$J$4 -> 0 | ... W21: =W16*$J$4 -> 0
B22: Impuesto GEN EE (€) | D22: =D19*$J$5 -> 0 | E22: =E19*$J$5 -> 0 | F22: =F19*$J$5 -> 0 | G22: =G19*$J$5 -> 0 | H22: =H19*$J$5 -> 0 | I22: =I19*$J$5 -> 0 | J22: =J19*$J$5 -> 0 | K22: =K19*$J$5 -> 0 | ... W22: =W19*$J$5 -> 0
B24: EBITDA (€) | D24: =D19-D20-D21-D22 -> 475719.79 | E24: =E19-E20-E21-E22 -> 471714.3 | F24: =F19-F20-F21-F22 -> 467585.41 | G24: =G19-G20-G21-G22 -> 463420.09 | H24: =H19-H20-H21-H22 -> 459217.59 | I24: =I19-I20-I21-I22 -> 454977.18 | J24: =J19-J20-J21-J22 -> 450688.22 | K24: =K19-K20-K21-K22 -> 446359.43 | ... W24: =W19-W20-W21-W22 -> 390997.74
B26: Amortización (€) | D26: =$C$8/$C$11 -> 251790 | E26: =$C$8/$C$11 -> 251790 | F26: =$C$8/$C$11 -> 251790 | G26: =$C$8/$C$11 -> 251790 | H26: =$C$8/$C$11 -> 251790 | I26: =$C$8/$C$11 -> 251790 | J26: =$C$8/$C$11 -> 251790 | K26: =$C$8/$C$11 -> 251790 | ... W26: =$C$8/$C$11 -> 251790 | X26: =SUM(D26:W26) -> 5035800 | Y26: =IF(X26=C8,"OK","Revisar") -> OK
B28: EBIT (€) | D28: =D24-D26 -> 223929.79 | E28: =E24-E26 -> 219924.3 | F28: =F24-F26 -> 215795.41 | G28: =G24-G26 -> 211630.09 | H28: =H24-H26 -> 207427.59 | I28: =I24-I26 -> 203187.18 | J28: =J24-J26 -> 198898.22 | K28: =K24-K26 -> 194569.43 | ... W28: =W24-W26 -> 139207.74
B30: Impuestos (€) | D30: =D28*$J$3 -> 55982.447 | E30: =E28*$J$3 -> 54981.074 | F30: =F28*$J$3 -> 53948.854 | G30: =G28*$J$3 -> 52907.522 | H30: =H28*$J$3 -> 51856.898 | I30: =I28*$J$3 -> 50796.794 | J30: =J28*$J$3 -> 49724.556 | K30: =K28*$J$3 -> 48642.357 | ... W30: =W28*$J$3 -> 34801.934
B32: EBI (€) | D32: =D28-D30 -> 167947.34 | E32: =E28-E30 -> 164943.22 | F32: =F28-F30 -> 161846.56 | G32: =G28-G30 -> 158722.57 | H32: =H28-H30 -> 155570.69 | I32: =I28-I30 -> 152390.38 | J32: =J28-J30 -> 149173.67 | K32: =K28-K30 -> 145927.07 | ... W32: =W28-W30 -> 104405.8
B34: FCF Proyecto (€) | C34: =-C8 -> -5035800 | D34: =D32+D26 -> 419737.34 | E34: =E32+E26 -> 416733.22 | F34: =F32+F26 -> 413636.56 | G34: =G32+G26 -> 410512.57 | H34: =H32+H26 -> 407360.69 | I34: =I32+I26 -> 404180.38 | J34: =J32+J26 -> 400963.67 | K34: =K32+K26 -> 397717.07 | ... W34: =W32+W26 -> 356195.8
B36: TIR Proyecto | C36: =IRR(C34:W34) -> 0.047022609
B38: %Deuda | C38: 0.8 | E38: =C8*C38 -> 4028640 | F38: Principal de la deuda
B39: Años | C39: 18 | E39: =C8*(1-C38) -> 1007160 | F39: CAPEX Equity
B40: Kd | C40: 0.04
C42: Construcción 2025 | D42: 2026 | E42: 2027 | F42: 2028 | G42: 2029 | H42: 2030 | I42: 2031 | J42: 2032 | K42: 2033 | L42: 2034 | M42: 2035 | N42: 2036 | O42: 2037 | P42: 2038 | Q42: 2039 | R42: 2040 | S42: 2041 | T42: 2042 | U42: 2043 | V42: 2044 | W42: 2045
D43: 1 | E43: 2 | F43: 3 | G43: 4 | H43: 5 | I43: 6 | J43: 7 | K43: 8 | L43: 9 | M43: 10 | N43: 11 | O43: 12 | P43: 13 | Q43: 14 | R43: 15 | S43: 16 | T43: 17 | U43: 18 | V43: 19 | W43: 20
B44: =B28 -> EBIT (€) | D44: =D28 -> 223929.79 | E44: =E28 -> 219924.3 | F44: =F28 -> 215795.41 | G44: =G28 -> 211630.09 | H44: =H28 -> 207427.59 | I44: =I28 -> 203187.18 | J44: =J28 -> 198898.22 | K44: =K28 -> 194569.43 | ... W44: =W28 -> 139207.74
B46: Intereses deuda (€) | D46: =IPMT($C$40,D43,$C$39,$E$38) -> -161145.6 | E46: =IPMT($C$40,E43,$C$39,$E$38) -> -154862 | F46: =IPMT($C$40,F43,$C$39,$E$38) -> -148327.05 | G46: =IPMT($C$40,G43,$C$39,$E$38) -> -141530.7 | H46: =IPMT($C$40,H43,$C$39,$E$38) -> -134462.5 | I46: =IPMT($C$40,I43,$C$39,$E$38) -> -127111.58 | J46: =IPMT($C$40,J43,$C$39,$E$38) -> -119466.61 | K46: =IPMT($C$40,K43,$C$39,$E$38) -> -111515.85 | ... S46: =IPMT($C$40,S43,$C$39,$E$38) -> -35325.319
B47: Principal deuda (€) | D47: =PPMT($C$40,D43,$C$39,$E$38) -> -157090.08 | E47: =PPMT($C$40,E43,$C$39,$E$38) -> -163373.68 | F47: =PPMT($C$40,F43,$C$39,$E$38) -> -169908.63 | G47: =PPMT($C$40,G43,$C$39,$E$38) -> -176704.98 | H47: =PPMT($C$40,H43,$C$39,$E$38) -> -183773.18 | I47: =PPMT($C$40,I43,$C$39,$E$38) -> -191124.1 | J47: =PPMT($C$40,J43,$C$39,$E$38) -> -198769.07 | K47: =PPMT($C$40,K43,$C$39,$E$38) -> -206719.83 | ... S47: =PPMT($C$40,S43,$C$39,$E$38) -> -282910.36 | X47: =ABS(SUM(D47:W47)) -> 3428417.4 | Y47: =IF(X47=E38,"OK","Revisar") -> Revisar
B49: Impuestos (€) | D49: =IF((D44+D46)*$J$3<0,0,(D44+D46)*$J$3) -> 15696.047 | E49: =IF((E44+E46)*$J$3<0,0,(E44+E46)*$J$3) -> 16265.575 | F49: =IF((F44+F46)*$J$3<0,0,(F44+F46)*$J$3) -> 16867.091 | G49: =IF((G44+G46)*$J$3<0,0,(G44+G46)*$J$3) -> 17524.846 | H49: =IF((H44+H46)*$J$3<0,0,(H44+H46)*$J$3) -> 18241.272 | I49: =IF((I44+I46)*$J$3<0,0,(I44+I46)*$J$3) -> 19018.9 | J49: =IF((J44+J46)*$J$3<0,0,(J44+J46)*$J$3) -> 19857.903 | K49: =IF((K44+K46)*$J$3<0,0,(K44+K46)*$J$3) -> 20763.394 | ... W49: =IF((W44+W46)*$J$3<0,0,(W44+W46)*$J$3) -> 34801.934
B51: EBI (€) | D51: =D44+D46-D49 -> 47088.141 | E51: =E44+E46-E49 -> 48796.724 | F51: =F44+F46-F49 -> 50601.274 | G51: =G44+G46-G49 -> 52574.539 | H51: =H44+H46-H49 -> 54723.815 | I51: =I44+I46-I49 -> 57056.699 | J51: =J44+J46-J49 -> 59573.708 | K51: =K44+K46-K49 -> 62290.182 | ... W51: =W44+W46-W49 -> 104405.8
B53: FCF Equity (€) | C53: =-E39 -> -1007160 | D53: =D51+D26+D47 -> 141788.06 | E53: =E51+E26+E47 -> 137213.04 | F53: =F51+F26+F47 -> 132482.64 | G53: =G51+G26+G47 -> 127659.56 | H53: =H51+H26+H47 -> 122740.64 | I53: =I51+I26+I47 -> 117722.6 | J53: =J51+J26+J47 -> 112594.64 | K53: =K51+K26+K47 -> 107360.35 | ... W53: =W51+W26+W47 -> 356195.8
B55: TIR Equity | C55: =IRR(C53:W53) -> 0.11693975
B58: IPC (Enero-Diciembre) | D58: 2026 | E58: 2027 | F58: 2028 | G58: 2029 | H58: 2030 | I58: 2031 | J58: 2032 | K58: 2033 | L58: 2034 | M58: 2035 | N58: 2036 | O58: 2037 | P58: 2038 | Q58: 2039 | R58: 2040 | S58: 2041 | T58: 2042 | U58: 2043 | V58: 2044 | W58: 2045
B59: España | C59: % | D59: 0.019 | E59: 0.019 | F59: 0.02 | G59: 0.02 | H59: 0.02 | I59: 0.02 | J59: 0.0201 | K59: 0.0201 | L59: 0.0201 | M59: 0.0201 | N59: 0.0201 | O59: 0.0201 | P59: 0.0201 | Q59: 0.0201 | R59: 0.0201 | S59: 0.0201 | T59: 0.0201 | U59: 0.0201 | V59: 0.0201 | W59: 0.0201

Sheet Referencias CAPEX_OPEX
B2: Referencias para plantas de mayor tamaño
B5: CAPEX Fotovoltaica
D6: MEUR/MWp
B7: Módulos | C7: 0.28 | D7: =$C$20*C7 -> 0.196
B8: Seguidor | C8: 0.163 | D8: =$C$20*C8 -> 0.1141
B9: Inversores | C9: 0.077 | D9: =$C$20*C9 -> 0.0539
B10: Otros equipos (cables BT, MT, cajas de conexión, etc.) | C10: 0.109 | D10: =$C$20*C10 -> 0.0763
B11: Auxiliares planta | C11: 0.136 | D11: =$C$20*C11 -> 0.0952 | E11: =SUM(D7:D11) -> 0.5355
B12: SET + LAT | C12: 0.115 | D12: =$C$20*C12 -> 0.0805
B13: Conexión | C13: 0.054 | D13: =$C$20*C13 -> 0.0378
B14: Otros CAPEX | C14: 0.008 | D14: =$C$20*C14 -> 0.0056
B15: Tasas | C15: 0.032 | D15: =$C$20*C15 -> 0.0224
B16: Ingeniería y Dirección de Obra | C16: 0.016 | D16: =$C$20*C16 -> 0.0112
B17: DEVEX | C17: 0.01 | D17: =$C$20*C17 -> 0.007
B18: TOTAL | C18: =SUM(C7:C17) -> 1 | D18: =$C$20*C18 -> 0.7
B20: Precio referencia MEUR/MWp | C20: 0.7
B27: OPEX Fotovoltaica
D28: EUR/MWp
B29: O&M Planta | C29: 0.4 | D29: =$C$38*C29 -> 6400
B30: O&M Evacuación | C30: 0.032 | D30: =$C$38*C30 -> 512
B31: SCADA, Sistemas y comunicaciones | C31: 0.009 | D31: =$C$38*C31 -> 144
B32: Terrenos | C32: 0.152 | D32: =$C$38*C32 -> 2432
B33: Personal y gestión del parque | C33: 0.076 | D33: =$C$38*C33 -> 1216
B34: Otros (seguros, servicios, suministros) | C34: 0.066 | D34: =$C$38*C34 -> 1056
B35: Impuestos locales | C35: 0.265 | D35: =$C$38*C35 -> 4240
B36: TOTAL | C36: =SUM(C29:C35) -> 1 | D36: =SUM(D29:D35) -> 16000
B38: Precio referencia EUR/MWp | C38: 16000

Sheet PeriodosElectricos
B2: Potencia superior a 15 kW para acceso a tarifa en 6 períodos:
D4: Tarifa 6 periodos peninsular
D6: Días laborables | AH6: Días festivos
B8: Peninsula | I8: Hora | AK8: Hora
I9: 1 | J9: 2 | K9: 3 | L9: 4 | M9: 5 | N9: 6 | O9: 7 | P9: 8 | Q9: 9 | R9: 10 | S9: 11 | T9: 12 | U9: 13 | V9: 14 | W9: 15 | X9: 16 | Y9: 17 | Z9: 18 | AA9: 19 | AB9: 20 | AC9: 21 | AD9: 22 | AE9: 23 | AF9: 24 | AK9: 1 | AL9: 2 | AM9: 3 | AN9: 4 | AO9: 5 | AP9: 6 | AQ9: 7 | AR9: 8 | AS9: 9 | AT9: 10 | AU9: 11 | AV9: 12 | AW9: 13 | AX9: 14 | AY9: 15 | AZ9: 16 | BA9: 17 | BB9: 18 | BC9: 19 | BD9: 20 | BE9: 21 | BF9: 22 | BG9: 23 | BH9: 24
C10: Año | E10: Identificación mes | G10: Inicio | H10: Fin | I10: 0-1 | J10: 1-2 | K10: 2-3 | L10: 3-4 | M10: 4-5 | N10: 5-6 | O10: 6-7 | P10: 7-8 | Q10: 8-9 | R10: 9-10 | S10: 10-11 | T10: 11-12 | U10: 12-13 | V10: 13-14 | W10: 14-15 | X10: 15-16 | Y10: 16-17 | Z10: 17-18 | AA10: 18-19 | AB10: 19-20 | AC10: 20-21 | AD10: 21-22 | AE10: 22-23 | AF10: 23-24 | AK10: 0-1 | AL10: 1-2 | AM10: 2-3 | AN10: 3-4 | AO10: 4-5 | AP10: 5-6 | AQ10: 6-7 | AR10: 7-8 | AS10: 8-9 | AT10: 9-10 | AU10: 10-11 | AV10: 11-12 | AW10: 12-13 | AX10: 13-14 | AY10: 14-15 | AZ10: 15-16 | BA10: 16-17 | BB10: 17-18 | BC10: 18-19 | BD10: 19-20 | BE10: 20-21 | BF10: 21-22 | BG10: 22-23 | BH10: 23-24
C11: 2025 | D11: Mes | E11: 1 | F11: Enero | G11: =+DATE(C11,PeriodosElectricos!E11,1) -> 45658 | H11: =+G11+30 -> 45688 | I11: 6 | J11: 6 | K11: 6 | L11: 6 | M11: 6 | N11: 6 | O11: 6 | P11: 6 | Q11: 2 | R11: 1 | S11: 1 | T11: 1 | U11: 1 | V11: 2 | W11: 2 | X11: 2 | Y11: 2 | Z11: 2 | AA11: 1 | AB11: 1 | AC11: 1 | AD11: 1 | AE11: 2 | AF11: 2 | AH11: Mes | AJ11: Enero | AK11: 6 | AL11: 6 | AM11: 6 | AN11: 6 | AO11: 6 | AP11: 6 | AQ11: 6 | AR11: 6 | AS11: 6 | AT11: 6 | AU11: 6 | AV11: 6 | AW11: 6 | AX11: 6 | AY11: 6 | AZ11: 6 | BA11: 6 | BB11: 6 | BC11: 6 | BD11: 6 | BE11: 6 | BF11: 6 | BG11: 6 | BH11: 6
C12: =+C11 -> 2025 | E12: 2 | F12: Febrero | G12: =+DATE(C12,PeriodosElectricos!E12,1) -> 45689 | H12: =+G12+27 -> 45716 | I12: 6 | J12: 6 | K12: 6 | L12: 6 | M12: 6 | N12: 6 | O12: 6 | P12: 6 | Q12: 2 | R12: 1 | S12: 1 | T12: 1 | U12: 1 | V12: 2 | W12: 2 | X12: 2 | Y12: 2 | Z12: 2 | AA12: 1 | AB12: 1 | AC12: 1 | AD12: 1 | AE12: 2 | AF12: 2 | AJ12: Febrero | AK12: 6 | AL12: 6 | AM12: 6 | AN12: 6 | AO12: 6 | AP12: 6 | AQ12: 6 | AR12: 6 | AS12: 6 | AT12: 6 | AU12: 6 | AV12: 6 | AW12: 6 | AX12: 6 | AY12: 6 | AZ12: 6 | BA12: 6 | BB12: 6 | BC12: 6 | BD12: 6 | BE12: 6 | BF12: 6 | BG12: 6 | BH12: 6
C13: =+C12 -> 2025 | E13: 3 | F13: Marzo | G13: =+DATE(C13,PeriodosElectricos!E13,1) -> 45717 | H13: =+G13+30 -> 45747 | I13: 6 | J13: 6 | K13: 6 | L13: 6 | M13: 6 | N13: 6 | O13: 6 | P13: 6 | Q13: 3 | R13: 2 | S13: 2 | T13: 2 | U13: 2 | V13: 3 | W13: 3 | X13: 3 | Y13: 3 | Z13: 3 | AA13: 2 | AB13: 2 | AC13: 2 | AD13: 2 | AE13: 3 | AF13: 3 | AJ13: Marzo | AK13: 6 | AL13: 6 | AM13: 6 | AN13: 6 | AO13: 6 | AP13: 6 | AQ13: 6 | AR13: 6 | AS13: 6 | AT13: 6 | AU13: 6 | AV13: 6 | AW13: 6 | AX13: 6 | AY13: 6 | AZ13: 6 | BA13: 6 | BB13: 6 | BC13: 6 | BD13: 6 | BE13: 6 | BF13: 6 | BG13: 6 | BH13: 6
C14: =+C13 -> 2025 | E14: 4 | F14: Abril | G14: =+DATE(C14,PeriodosElectricos!E14,1) -> 45748 | H14: =+G14+29 -> 45777 | I14: 6 | J14: 6 | K14: 6 | L14: 6 | M14: 6 | N14: 6 | O14: 6 | P14: 6 | Q14: 5 | R14: 4 | S14: 4 | T14: 4 | U14: 4 | V14: 5 | W14: 5 | X14: 5 | Y14: 5 | Z14: 5 | AA14: 4 | AB14: 4 | AC14: 4 | AD14: 4 | AE14: 5 | AF14: 5 | AJ14: Abril | AK14: 6 | AL14: 6 | AM14: 6 | AN14: 6 | AO14: 6 | AP14: 6 | AQ14: 6 | AR14: 6 | AS14: 6 | AT14: 6 | AU14: 6 | AV14: 6 | AW14: 6 | AX14: 6 | AY14: 6 | AZ14: 6 | BA14: 6 | BB14: 6 | BC14: 6 | BD14: 6 | BE14: 6 | BF14: 6 | BG14: 6 | BH14: 6
C15: =+C14 -> 2025 | E15: 5 | F15: Mayo | G15: =+DATE(C15,PeriodosElectricos!E15,1) -> 45778 | H15: =+G15+30 -> 45808 | I15: 6 | J15: 6 | K15: 6 | L15: 6 | M15: 6 | N15: 6 | O15: 6 | P15: 6 | Q15: 5 | R15: 4 | S15: 4 | T15: 4 | U15: 4 | V15: 5 | W15: 5 | X15: 5 | Y15: 5 | Z15: 5 | AA15: 4 | AB15: 4 | AC15: 4 | AD15: 4 | AE15: 5 | AF15: 5 | AJ15: Mayo | AK15: 6 | AL15: 6 | AM15: 6 | AN15: 6 | AO15: 6 | AP15: 6 | AQ15: 6 | AR15: 6 | AS15: 6 | AT15: 6 | AU15: 6 | AV15: 6 | AW15: 6 | AX15: 6 | AY15: 6 | AZ15: 6 | BA15: 6 | BB15: 6 | BC15: 6 | BD15: 6 | BE15: 6 | BF15: 6 | BG15: 6 | BH15: 6
C16: =+C15 -> 2025 | E16: 6 | F16: Junio | G16: =+DATE(C16,PeriodosElectricos!E16,1) -> 45809 | H16: =+G16+29 -> 45838 | I16: 6 | J16: 6 | K16: 6 | L16: 6 | M16: 6 | N16: 6 | O16: 6 | P16: 6 | Q16: 4 | R16: 3 | S16: 3 | T16: 3 | U16: 3 | V16: 4 | W16: 4 | X16: 4 | Y16: 4 | Z16: 4 | AA16: 3 | AB16: 3 | AC16: 3 | AD16: 3 | AE16: 4 | AF16: 4 | AJ16: Junio | AK16: 6 | AL16: 6 | AM16: 6 | AN16: 6 | AO16: 6 | AP16: 6 | AQ16: 6 | AR16: 6 | AS16: 6 | AT16: 6 | AU16: 6 | AV16: 6 | AW16: 6 | AX16: 6 | AY16: 6 | AZ16: 6 | BA16: 6 | BB16: 6 | BC16: 6 | BD16: 6 | BE16: 6 | BF16: 6 | BG16: 6 | BH16: 6
C17: =+C16 -> 2025 | E17: 7 | F17: Julio | G17: =+DATE(C17,PeriodosElectricos!E17,1) -> 45839 | H17: =+G17+30 -> 45869 | I17: 6 | J17: 6 | K17: 6 | L17: 6 | M17: 6 | N17: 6 | O17: 6 | P17: 6 | Q17: 2 | R17: 1 | S17: 1 | T17: 1 | U17: 1 | V17: 2 | W17: 2 | X17: 2 | Y17: 2 | Z17: 2 | AA17: 1 | AB17: 1 | AC17: 1 | AD17: 1 | AE17: 2 | AF17: 2 | AJ17: Julio | AK17: 6 | AL17: 6 | AM17: 6 | AN17: 6 | AO17: 6 | AP17: 6 | AQ17: 6 | AR17: 6 | AS17: 6 | AT17: 6 | AU17: 6 | AV17: 6 | AW17: 6 | AX17: 6 | AY17: 6 | AZ17: 6 | BA17: 6 | BB17: 6 | BC17: 6 | BD17: 6 | BE17: 6 | BF17: 6 | BG17: 6 | BH17: 6
C18: =+C17 -> 2025 | E18: 8 | F18: Agosto | G18: =+DATE(C18,PeriodosElectricos!E18,1) -> 45870 | H18: =+G18+30 -> 45900 | I18: 6 | J18: 6 | K18: 6 | L18: 6 | M18: 6 | N18: 6 | O18: 6 | P18: 6 | Q18: 4 | R18: 3 | S18: 3 | T18: 3 | U18: 3 | V18: 4 | W18: 4 | X18: 4 | Y18: 4 | Z18: 4 | AA18: 3 | AB18: 3 | AC18: 3 | AD18: 3 | AE18: 4 | AF18: 4 | AJ18: Agosto | AK18: 6 | AL18: 6 | AM18: 6 | AN18: 6 | AO18: 6 | AP18: 6 | AQ18: 6 | AR18: 6 | AS18: 6 | AT18: 6 | AU18: 6 | AV18: 6 | AW18: 6 | AX18: 6 | AY18: 6 | AZ18: 6 | BA18: 6 | BB18: 6 | BC18: 6 | BD18: 6 | BE18: 6 | BF18: 6 | BG18: 6 | BH18: 6
C19: =+C18 -> 2025 | E19: 9 | F19: Septiembre | G19: =+DATE(C19,PeriodosElectricos!E19,1) -> 45901 | H19: =+G19+29 -> 45930 | I19: 6 | J19: 6 | K19: 6 | L19: 6 | M19: 6 | N19: 6 | O19: 6 | P19: 6 | Q19: 4 | R19: 3 | S19: 3 | T19: 3 | U19: 3 | V19: 4 | W19: 4 | X19: 4 | Y19: 4 | Z19: 4 | AA19: 3 | AB19: 3 | AC19: 3 | AD19: 3 | AE19: 4 | AF19: 4 | AJ19: Septiembre | AK19: 6 | AL19: 6 | AM19: 6 | AN19: 6 | AO19: 6 | AP19: 6 | AQ19: 6 | AR19: 6 | AS19: 6 | AT19: 6 | AU19: 6 | AV19: 6 | AW19: 6 | AX19: 6 | AY19: 6 | AZ19: 6 | BA19: 6 | BB19: 6 | BC19: 6 | BD19: 6 | BE19: 6 | BF19: 6 | BG19: 6 | BH19: 6
C20: =+C19 -> 2025 | E20: 10 | F20: Octubre | G20: =+DATE(C20,PeriodosElectricos!E20,1) -> 45931 | H20: =+G20+30 -> 45961 | I20: 6 | J20: 6 | K20: 6 | L20: 6 | M20: 6 | N20: 6 | O20: 6 | P20: 6 | Q20: 5 | R20: 4 | S20: 4 | T20: 4 | U20: 4 | V20: 5 | W20: 5 | X20: 5 | Y20: 5 | Z20: 5 | AA20: 4 | AB20: 4 | AC20: 4 | AD20: 4 | AE20: 5 | AF20: 5 | AJ20: Octubre | AK20: 6 | AL20: 6 | AM20: 6 | AN20: 6 | AO20: 6 | AP20: 6 | AQ20: 6 | AR20: 6 | AS20: 6 | AT20: 6 | AU20: 6 | AV20: 6 | AW20: 6 | AX20: 6 | AY20: 6 | AZ20: 6 | BA20: 6 | BB20: 6 | BC20: 6 | BD20: 6 | BE20: 6 | BF20: 6 | BG20: 6 | BH20: 6
C21: =+C20 -> 2025 | E21: 11 | F21: Noviembre | G21: =+DATE(C21,PeriodosElectricos!E21,1) -> 45962 | H21: =+G21+29 -> 45991 | I21: 6 | J21: 6 | K21: 6 | L21: 6 | M21: 6 | N21: 6 | O21: 6 | P21: 6 | Q21: 3 | R21: 2 | S21: 2 | T21: 2 | U21: 2 | V21: 3 | W21: 3 | X21: 3 | Y21: 3 | Z21: 3 | AA21: 2 | AB21: 2 | AC21: 2 | AD21: 2 | AE21: 3 | AF21: 3 | AJ21: Noviembre | AK21: 6 | AL21: 6 | AM21: 6 | AN21: 6 | AO21: 6 | AP21: 6 | AQ21: 6 | AR21: 6 | AS21: 6 | AT21: 6 | AU21: 6 | AV21: 6 | AW21: 6 | AX21: 6 | AY21: 6 | AZ21: 6 | BA21: 6 | BB21: 6 | BC21: 6 | BD21: 6 | BE21: 6 | BF21: 6 | BG21: 6 | BH21: 6
C22: =+C21 -> 2025 | E22: 12 | F22: Diciembre | G22: =+DATE(C22,PeriodosElectricos!E22,1) -> 45992 | H22: =+G22+30 -> 46022 | I22: 6 | J22: 6 | K22: 6 | L22: 6 | M22: 6 | N22: 6 | O22: 6 | P22: 6 | Q22: 2 | R22: 1 | S22: 1 | T22: 1 | U22: 1 | V22: 2 | W22: 2 | X22: 2 | Y22: 2 | Z22: 2 | AA22: 1 | AB22: 1 | AC22: 1 | AD22: 1 | AE22: 2 | AF22: 2 | AJ22: Diciembre | AK22: 6 | AL22: 6 | AM22: 6 | AN22: 6 | AO22: 6 | AP22: 6 | AQ22: 6 | AR22: 6 | AS22: 6 | AT22: 6 | AU22: 6 | AV22: 6 | AW22: 6 | AX22: 6 | AY22: 6 | AZ22: 6 | BA22: 6 | BB22: 6 | BC22: 6 | BD22: 6 | BE22: 6 | BF22: 6 | BG22: 6 | BH22: 6
